File: data/class2/Specimen_RawData_9.csv
Time,Extension,Load
(s),(mm),(N)
"0.00000","0.00000","-0.01580"
"0.10000","0.12909","0.10535"
"0.20000","0.26871","0.27429"
"0.30000","0.40262","0.42197"
"0.40000","0.53607","0.55585"
"0.50000","0.66940","0.69155"
"0.60000","0.80274","0.81408"
"0.70000","0.93602","0.93448"
"0.80000","1.06930","1.04798"
"0.90000","1.20275","1.14712"
"1.00000","1.33603","1.26087"
"1.10000","1.46931","1.35468"
"1.20000","1.60265","1.44843"
"1.30000","1.73598","1.54362"
"1.40000","1.86943","1.62075"
"1.50000","2.00260","1.71086"
"1.60000","2.13611","1.79482"
"1.70000","2.26944","1.86612"
"1.80000","2.40272","1.93849"
"1.90000","2.53606","2.01969"
"2.00000","2.66934","2.08911"
"2.10000","2.80273","2.15727"
"2.20000","2.93607","2.22280"
"2.30000","3.06935","2.29191"
"2.40000","3.20263","2.36045"
"2.50000","3.33591","2.42353"
"2.60000","3.46942","2.48467"
"2.70000","3.60270","2.54023"
"2.80000","3.73603","2.59754"
"2.90000","3.86937","2.66044"
"3.00000","4.00271","2.70076"
"3.10000","4.13610","2.76648"
"3.20000","4.26938","2.82323"
"3.30000","4.40266","2.87377"
"3.40000","4.53611","2.92174"
"3.50000","4.66939","2.97279"
"3.60000","4.80273","3.01305"
"3.70000","4.93606","3.06051"
"3.80000","5.06940","3.10604"
"3.90000","5.20274","3.15972"
"4.00000","5.33607","3.19885"
"4.10000","5.46941","3.22863"
"4.20000","5.60258","3.27635"
"4.30000","5.73608","3.31699"
"4.40000","5.86942","3.35587"
"4.50000","6.00270","3.39556"
"4.60000","6.13598","3.44291"
"4.70000","6.26932","3.46686"
"4.80000","6.40271","3.50756"
"4.90000","6.53599","3.54355"
"5.00000","6.66938","3.57754"
"5.10000","6.80278","3.61504"
"5.20000","6.93606","3.64965"
"5.30000","7.06939","3.68897"
"5.40000","7.20267","3.72390"
"5.50000","7.33601","3.75500"
"5.60000","7.46935","3.77413"
"5.70000","7.60268","3.81884"
"5.80000","7.73602","3.84461"
"5.90000","7.86930","3.87590"
"6.00000","8.00269","3.90462"
"6.10000","8.13597","3.93717"
"6.20000","8.26937","3.95874"
"6.30000","8.40265","3.98715"
"6.40000","8.53598","4.01862"
"6.50000","8.66938","4.04778"
"6.60000","8.80271","4.06478"
"6.70000","8.93605","4.10221"
"6.80000","9.06944","4.13162"
"6.90000","9.20272","4.15495"
"7.00000","9.33612","4.17947"
"7.10000","9.46940","4.20135"
"7.20000","9.60268","4.22393"
"7.30000","9.73601","4.25572"
"7.40000","9.86941","4.28106"
"7.50000","10.00268","4.30758"
"7.60000","10.13591","4.31943"
"7.70000","10.26942","4.34953"
"7.80000","10.40275","4.37913"
"7.90000","10.53609","4.39330"
"8.00000","10.66931","4.42359"
"8.10000","10.80265","4.43212"
"8.20000","10.93604","4.46040"
"8.30000","11.06927","4.47307"
"8.40000","11.20266","4.49965"
"8.50000","11.33605","4.52543"
"8.60000","11.46933","4.54468"
"8.70000","11.60267","4.56562"
"8.80000","11.73601","4.57603"
"8.90000","11.86940","4.60080"
"9.00000","12.00268","4.61824"
"9.10000","12.13602","4.63987"
"9.20000","12.26941","4.65586"
"9.30000","12.40263","4.67530"
"9.40000","12.53608","4.68935"
"9.50000","12.66931","4.71092"
"9.60000","12.80270","4.72327"
"9.70000","12.93598","4.75324"
"9.80000","13.06932","4.76579"
"9.90000","13.20277","4.78240"
"10.00000","13.33599","4.79074"
"10.10000","13.46938","4.80974"
"10.20000","13.60272","4.82962"
"10.30000","13.73606","4.85433"
"10.40000","13.86939","4.86041"
"10.50000","14.00267","4.87640"
"10.60000","14.13601","4.89948"
"10.70000","14.26935","4.91854"
"10.80000","14.40274","4.92757"
"10.90000","14.53608","4.94300"
"11.00000","14.66930","4.96031"
"11.10000","14.80275","4.98683"
"11.20000","14.93603","4.99072"
"11.30000","15.06942","5.00941"
"11.40000","15.20259","5.02333"
"11.50000","15.33593","5.04045"
"11.60000","15.46943","5.05524"
"11.70000","15.60271","5.06929"
"11.80000","15.73605","5.08346"
"11.90000","15.86944","5.10359"
"12.00000","16.00272","5.11864"
"12.10000","16.13606","5.13106"
"12.20000","16.26934","5.15181"
"12.30000","16.40268","5.16342"
"12.40000","16.53601","5.17119"
"12.50000","16.66940","5.19427"
"12.60000","16.80268","5.20750"
"12.70000","16.93596","5.22443"
"12.80000","17.06936","5.23195"
"12.90000","17.20275","5.25108"
"13.00000","17.33609","5.26274"
"13.10000","17.46937","5.28112"
"13.20000","17.60271","5.29034"
"13.30000","17.73610","5.30677"
"13.40000","17.86932","5.30702"
"13.50000","18.00271","5.32564"
"13.60000","18.13594","5.32959"
"13.70000","18.26933","5.34232"
"13.80000","18.40267","5.34746"
"13.90000","18.53601","5.36903"
"14.00000","18.66934","5.38239"
"14.10000","18.80268","5.39606"
"14.20000","18.93602","5.41030"
"14.30000","19.06935","5.42553"
"14.40000","19.20258","5.44328"
"14.50000","19.33608","5.45149"
"14.60000","19.46936","5.45990"
"14.70000","19.60270","5.48147"
"14.80000","19.73603","5.49012"
"14.90000","19.86932","5.49752"
"15.00000","20.00276","5.52831"
"15.10000","20.13599","5.53082"
"15.20000","20.26938","5.54951"
"15.30000","20.40272","5.56123"
"15.40000","20.53606","5.57760"
"15.50000","20.66939","5.58425"
"15.60000","20.80267","5.60224"
"15.70000","20.93601","5.60601"
"15.80000","21.06935","5.61943"
"15.90000","21.20268","5.63310"
"16.00000","21.33602","5.64645"
"16.10000","21.46924","5.66012"
"16.20000","21.60275","5.67041"
"16.30000","21.73608","5.68019"
"16.40000","21.86937","5.69568"
"16.50000","22.00265","5.70546"
"16.60000","22.13598","5.72854"
"16.70000","22.26943","5.73775"
"16.80000","22.40265","5.74409"
"16.90000","22.53605","5.76196"
"17.00000","22.66939","5.77262"
"17.10000","22.80272","5.78849"
"17.20000","22.93606","5.79946"
"17.30000","23.06934","5.81137"
"17.40000","23.20262","5.82323"
"17.50000","23.33601","5.83752"
"17.60000","23.46935","5.84730"
"17.70000","23.60268","5.86204"
"17.80000","23.73597","5.87063"
"17.90000","23.86936","5.87872"
"18.00000","24.00264","5.88411"
"18.10000","24.13609","5.90399"
"18.20000","24.26937","5.91139"
"18.30000","24.40270","5.93215"
"18.40000","24.53616","5.93165"
"18.50000","24.66938","5.94563"
"18.60000","24.80272","5.95911"
"18.70000","24.93605","5.96877"
"18.80000","25.06933","5.98206"
"18.90000","25.20272","6.00420"
"19.00000","25.33606","6.00853"
"19.10000","25.46934","6.00733"
"19.20000","25.60274","6.02320"
"19.30000","25.73607","6.02383"
"19.40000","25.86935","6.02978"
"19.50000","26.00263","6.04584"
"19.60000","26.13608","6.05443"
"19.70000","26.26936","6.06151"
"19.80000","26.40275","6.07550"
"19.90000","26.53603","6.07957"
"20.00000","26.66932","6.09425"
"20.10000","26.80276","6.10315"
"20.20000","26.93605","6.10842"
"20.30000","27.06938","6.12259"
"20.40000","27.20272","6.13977"
"20.50000","27.33605","6.14341"
"20.60000","27.46939","6.15407"
"20.70000","27.60262","6.16065"
"20.80000","27.73601","6.18028"
"20.90000","27.86929","6.18636"
"21.00000","28.00268","6.19552"
"21.10000","28.13602","6.20361"
"21.20000","28.26924","6.21747"
"21.30000","28.40269","6.23434"
"21.40000","28.53609","6.24199"
"21.50000","28.66942","6.26676"
"21.60000","28.80264","6.26857"
"21.70000","28.93598","6.28043"
"21.80000","29.06938","6.29372"
"21.90000","29.20271","6.30946"
"22.00000","29.33605","6.32526"
"22.10000","29.46938","6.33235"
"22.20000","29.60272","6.34458"
"22.30000","29.73611","6.37355"
"22.40000","29.86934","6.38026"
"22.50000","30.00268","6.40246"
"22.60000","30.13607","6.41863"
"22.70000","30.26935","6.43726"
"22.80000","30.40269","6.45500"
"22.90000","30.53596","6.46792"
"23.00000","30.66936","6.47846"
"23.10000","30.80264","6.49445"
"23.20000","30.93603","6.50931"
"23.30000","31.06931","6.52467"
"23.40000","31.20259","6.53496"
"23.50000","31.33610","6.54913"
"23.60000","31.46932","6.56042"
"23.70000","31.60271","6.58644"
"23.80000","31.73605","6.59509"
"23.90000","31.86927","6.59886"
"24.00000","32.00272","6.61729"
"24.10000","32.13606","6.64100"
"24.20000","32.26934","6.64595"
"24.30000","32.40268","6.66752"
"24.40000","32.53601","6.67410"
"24.50000","32.66941","6.69191"
"24.60000","32.80263","6.70257"
"24.70000","32.93602","6.72471"
"24.80000","33.06936","6.74252"
"24.90000","33.20270","6.76215"
"25.00000","33.33603","6.77669"
"25.10000","33.46926","6.79331"
"25.20000","33.60276","6.80918"
"25.30000","33.73604","6.82122"
"25.40000","33.86932","6.84360"
"25.50000","34.00272","6.86361"
"25.60000","34.13605","6.88254"
"25.70000","34.26945","6.89766"
"25.80000","34.40273","6.91691"
"25.90000","34.53601","6.93585"
"26.00000","34.66940","6.95052"
"26.10000","34.80268","6.97943"
"26.20000","34.93602","6.99504"
"26.30000","35.06930","7.01423"
"26.40000","35.20269","7.03461"
"26.50000","35.33609","7.05267"
"26.60000","35.46936","7.06421"
"26.70000","35.60270","7.08898"
"26.80000","35.73598","7.10177"
"26.90000","35.86937","7.12228"
"27.00000","36.00271","7.13112"
"27.10000","36.13605","7.14736"
"27.20000","36.26939","7.15708"
"27.30000","36.40266","7.18210"
"27.40000","36.53606","7.19470"
"27.50000","36.66940","7.20630"
"27.60000","36.80268","7.21709"
"27.70000","36.93601","7.23741"
"27.80000","37.06940","7.25377"
"27.90000","37.20268","7.26293"
"28.00000","37.33602","7.28312"
"28.10000","37.46936","7.30181"
"28.20000","37.60269","7.31165"
"28.30000","37.73609","7.32024"
"28.40000","37.86926","7.33711"
"28.50000","38.00265","7.35185"
"28.60000","38.13604","7.36307"
"28.70000","38.26932","7.38038"
"28.80000","38.40271","7.39781"
"28.90000","38.53605","7.41556"
"29.00000","38.66927","7.42722"
"29.10000","38.80267","7.43876"
"29.20000","38.93600","7.46303"
"29.30000","39.06934","7.47494"
"29.40000","39.20268","7.48673"
"29.50000","39.33607","7.51138"
"29.60000","39.46935","7.53470"
"29.70000","39.60263","7.54317"
"29.80000","39.73608","7.56462"
"29.90000","39.86936","7.58876"
"30.00000","40.00264","7.59942"
"30.10000","40.13604","7.62525"
"30.20000","40.26926","7.65579"
"30.30000","40.40276","7.65962"
"30.40000","40.53599","7.68420"
"30.50000","40.66938","7.69988"
"30.60000","40.80272","7.71957"
"30.70000","40.93599","7.73725"
"30.80000","41.06939","7.75399"
"30.90000","41.20267","7.77682"
"31.00000","41.33595","7.79387"
"31.10000","41.46934","7.80516"
"31.20000","41.60274","7.82466"
"31.30000","41.73607","7.83815"
"31.40000","41.86930","7.84918"
"31.50000","42.00269","7.87909"
"31.60000","42.13609","7.88756"
"31.70000","42.26942","7.91340"
"31.80000","42.40276","7.92863"
"31.90000","42.53592","7.95566"
"32.00000","42.66937","7.97780"
"32.10000","42.80265","7.99372"
"32.20000","42.93599","8.01900"
"32.30000","43.06933","8.04295"
"32.40000","43.20266","8.07004"
"32.50000","43.33600","8.08659"
"32.60000","43.46939","8.11293"
"32.70000","43.60273","8.13319"
"32.80000","43.73606","8.16021"
"32.90000","43.86935","8.17432"
"33.00000","44.00269","8.19395"
"33.10000","44.13602","8.22204"
"33.20000","44.26936","8.24593"
"33.30000","44.40269","8.25622"
"33.40000","44.53603","8.27616"
"33.50000","44.66931","8.29823"
"33.60000","44.80265","8.32557"
"33.70000","44.93610","8.35066"
"33.80000","45.06938","8.36552"
"33.90000","45.20266","8.39142"
"34.00000","45.33605","8.41418"
"34.10000","45.46933","8.43042"
"34.20000","45.60278","8.45638"
"34.30000","45.73600","8.47939"
"34.40000","45.86928","8.49539"
"34.50000","46.00268","8.51551"
"34.60000","46.13607","8.54242"
"34.70000","46.26935","8.56863"
"34.80000","46.40269","8.57923"
"34.90000","46.53603","8.60713"
"35.00000","46.66930","8.61246"
"35.10000","46.80276","8.63560"
"35.20000","46.93603","8.65692"
"35.30000","47.06926","8.67849"
"35.40000","47.20282","8.69348"
"35.50000","47.33599","8.72546"
"35.60000","47.46933","8.73211"
"35.70000","47.60266","8.76076"
"35.80000","47.73600","8.77826"
"35.90000","47.86939","8.79218"
"36.00000","48.00267","8.81682"
"36.10000","48.13600","8.83702"
"36.20000","48.26935","8.86085"
"36.30000","48.40273","8.88925"
"36.40000","48.53602","8.89653"
"36.50000","48.66935","8.92913"
"36.60000","48.80269","8.94707"
"36.70000","48.93597","8.95961"
"36.80000","49.06942","8.98532"
"36.90000","49.20270","8.99811"
"37.00000","49.33592","9.02777"
"37.10000","49.46943","9.04784"
"37.20000","49.60276","9.06458"
"37.30000","49.73599","9.08390"
"37.40000","49.86932","9.10378"
"37.50000","50.00261","9.11657"
"37.60000","50.13605","9.14485"
"37.70000","50.26934","9.15770"
"37.80000","50.40273","9.18034"
"37.90000","50.53607","9.21013"
"38.00000","50.66941","9.21803"
"38.10000","50.80274","9.24675"
"38.20000","50.93602","9.26173"
"38.30000","51.06936","9.28487"
"38.40000","51.20264","9.29823"
"38.50000","51.33603","9.32432"
"38.60000","51.46931","9.33749"
"38.70000","51.60259","9.36878"
"38.80000","51.73604","9.39436"
"38.90000","51.86938","9.41763"
"39.00000","52.00271","9.44578"
"39.10000","52.13605","9.46710"
"39.20000","52.26933","9.49375"
"39.30000","52.40278","9.51137"
"39.40000","52.53606","9.54580"
"39.50000","52.66934","9.55891"
"39.60000","52.80273","9.58462"
"39.70000","52.93601","9.60976"
"39.80000","53.06940","9.63384"
"39.90000","53.20269","9.65962"
"40.00000","53.33608","9.67291"
"40.10000","53.46930","9.69473"
"40.20000","53.60276","9.73204"
"40.30000","53.73597","9.75154"
"40.40000","53.86926","9.76239"
"40.50000","54.00276","9.79876"
"40.60000","54.13604","9.81049"
"40.70000","54.26938","9.83676"
"40.80000","54.40272","9.85664"
"40.90000","54.53600","9.88417"
"41.00000","54.66945","9.90530"
"41.10000","54.80273","9.92017"
"41.20000","54.93601","9.94406"
"41.30000","55.06935","9.96575"
"41.40000","55.20273","9.98676"
"41.50000","55.33608","10.00777"
"41.60000","55.46935","10.03799"
"41.70000","55.60269","10.05035"
"41.80000","55.73597","10.07555"
"41.90000","55.86937","10.09493"
"42.00000","56.00270","10.11713"
"42.10000","56.13592","10.13983"
"42.20000","56.26943","10.15174"
"42.30000","56.40271","10.16968"
"42.40000","56.53605","10.20229"
"42.50000","56.66932","10.22091"
"42.60000","56.80261","10.24255"
"42.70000","56.93605","10.25778"
"42.80000","57.06939","10.28299"
"42.90000","57.20279","10.30237"
"43.00000","57.33601","10.31641"
"43.10000","57.46946","10.34269"
"43.20000","57.60268","10.35398"
"43.30000","57.73602","10.37542"
"43.40000","57.86936","10.40189"
"43.50000","58.00270","10.42277"
"43.60000","58.13609","10.43882"
"43.70000","58.26937","10.46133"
"43.80000","58.40259","10.48861"
"43.90000","58.53610","10.50397"
"44.00000","58.66938","10.52580"
"44.10000","58.80272","10.54229"
"44.20000","58.93599","10.56994"
"44.30000","59.06933","10.58825"
"44.40000","59.20278","10.61026"
"44.50000","59.33595","10.62262"
"44.60000","59.46934","10.64325"
"44.70000","59.60274","10.67736"
"44.80000","59.73596","10.68457"
"44.90000","59.86935","10.70940"
"45.00000","60.00269","10.73424"
"45.10000","60.13602","10.74527"
"45.20000","60.26931","10.77186"
"45.30000","60.40275","10.78910"
"45.40000","60.53598","10.81663"
"45.50000","60.66920","10.83846"
"45.60000","60.80276","10.85451"
"45.70000","60.93599","10.87690"
"45.80000","61.06939","10.89282"
"45.90000","61.20272","10.91791"
"46.00000","61.33594","10.94355"
"46.10000","61.46939","10.96594"
"46.20000","61.60273","10.98300"
"46.30000","61.73601","11.01027"
"46.40000","61.86940","11.02545"
"46.50000","62.00268","11.05317"
"46.60000","62.13607","11.07355"
"46.70000","62.26941","11.09988"
"46.80000","62.40269","11.11807"
"46.90000","62.53591","11.13895"
"47.00000","62.66942","11.15663"
"47.10000","62.80275","11.17946"
"47.20000","62.93592","11.20254"
"47.30000","63.06942","11.23364"
"47.40000","63.20271","11.25715"
"47.50000","63.33604","11.27540"
"47.60000","63.46932","11.30086"
"47.70000","63.60260","11.32983"
"47.80000","63.73605","11.34551"
"47.90000","63.86934","11.38188"
"48.00000","64.00267","11.40069"
"48.10000","64.13606","11.43675"
"48.20000","64.26940","11.45274"
"48.30000","64.40274","11.48271"
"48.40000","64.53607","11.50962"
"48.50000","64.66936","11.53213"
"48.60000","64.80264","11.55646"
"48.70000","64.93609","11.58292"
"48.80000","65.06936","11.61685"
"48.90000","65.20258","11.63390"
"49.00000","65.33615","11.66269"
"49.10000","65.46938","11.68589"
"49.20000","65.60277","11.71730"
"49.30000","65.73598","11.74747"
"49.40000","65.86927","11.76841"
"49.50000","66.00278","11.79701"
"49.60000","66.13605","11.82121"
"49.70000","66.26934","11.84748"
"49.80000","66.40267","11.86880"
"49.90000","66.53601","11.90022"
"50.00000","66.66934","11.93051"
"50.10000","66.80269","11.95371"
"50.20000","66.93602","11.98438"
"50.30000","67.06930","12.01366"
"50.40000","67.20275","12.03322"
"50.50000","67.33597","12.07041"
"50.60000","67.46931","12.09273"
"50.70000","67.60276","12.12597"
"50.80000","67.73598","12.15701"
"50.90000","67.86938","12.18535"
"51.00000","68.00266","12.21483"
"51.10000","68.13599","12.24085"
"51.20000","68.26939","12.27120"
"51.30000","68.40267","12.29829"
"51.40000","68.53600","12.33303"
"51.50000","68.66946","12.35316"
"51.60000","68.80273","12.39511"
"51.70000","68.93601","12.41674"
"51.80000","69.06935","12.44095"
"51.90000","69.20269","12.46848"
"52.00000","69.33597","12.49450"
"52.10000","69.46941","12.52548"
"52.20000","69.60270","12.55539"
"52.30000","69.73592","12.59095"
"52.40000","69.86948","12.62230"
"52.50000","70.00271","12.64262"
"52.60000","70.13605","12.68200"
"52.70000","70.26939","12.69448"
"52.80000","70.40261","12.72426"
"52.90000","70.53606","12.74696"
"53.00000","70.66933","12.78866"
"53.10000","70.80267","12.81180"
"53.20000","70.93606","12.83770"
"53.30000","71.06940","12.85683"
"53.40000","71.20274","12.89558"
"53.50000","71.33601","12.92831"
"53.60000","71.46935","12.94644"
"53.70000","71.60264","12.97064"
"53.80000","71.73608","13.00695"
"53.90000","71.86937","13.03529"
"54.00000","72.00264","13.06176"
"54.10000","72.13609","13.08119"
"54.20000","72.26932","13.11769"
"54.30000","72.40277","13.13838"
"54.40000","72.53605","13.16591"
"54.50000","72.66927","13.20134"
"54.60000","72.80272","13.22015"
"54.70000","72.93606","13.25145"
"54.80000","73.06940","13.27722"
"54.90000","73.20267","13.30788"
"55.00000","73.33601","13.33416"
"55.10000","73.46935","13.35266"
"55.20000","73.60263","13.38677"
"55.30000","73.73597","13.40985"
"55.40000","73.86930","13.43349"
"55.50000","74.00275","13.46020"
"55.60000","74.13603","13.48585"
"55.70000","74.26937","13.52178"
"55.80000","74.40282","13.54266"
"55.90000","74.53599","13.56235"
"56.00000","74.66937","13.58599"
"56.10000","74.80260","13.61866"
"56.20000","74.93594","13.64776"
"56.30000","75.06939","13.67943"
"56.40000","75.20273","13.69335"
"56.50000","75.33600","13.72984"
"56.60000","75.46940","13.75298"
"56.70000","75.60268","13.78183"
"56.80000","75.73602","13.80177"
"56.90000","75.86935","13.84008"
"57.00000","76.00269","13.86366"
"57.10000","76.13597","13.88805"
"57.20000","76.26942","13.91934"
"57.30000","76.40258","13.95321"
"57.40000","76.53593","13.97534"
"57.50000","76.66937","14.01265"
"57.60000","76.80265","14.03360"
"57.70000","76.93604","14.07643"
"57.80000","77.06933","14.10402"
"57.90000","77.20261","14.14258"
"58.00000","77.33611","14.16478"
"58.10000","77.46934","14.20473"
"58.20000","77.60267","14.23602"
"58.30000","77.73595","14.26675"
"58.40000","77.86935","14.28537"
"58.50000","78.00269","14.33723"
"58.60000","78.13607","14.36438"
"58.70000","78.26929","14.39736"
"58.80000","78.40264","14.42126"
"58.90000","78.53609","14.46233"
"59.00000","78.66936","14.49619"
"59.10000","78.80264","14.53407"
"59.20000","78.93604","14.56893"
"59.30000","79.06931","14.60511"
"59.40000","79.20265","14.63522"
"59.50000","79.33599","14.67472"
"59.60000","79.46932","14.70852"
"59.70000","79.60272","14.73856"
"59.80000","79.73605","14.77261"
"59.90000","79.86940","14.80427"
"60.00000","80.00273","14.84002"
"60.10000","80.13600","14.87789"
"60.20000","80.26935","14.91251"
"60.30000","80.40273","14.94223"
"60.40000","80.53602","14.99045"
"60.50000","80.66930","15.01880"
"60.60000","80.80275","15.05705"
"60.70000","80.93603","15.08934"
"60.80000","81.06937","15.12735"
"60.90000","81.20276","15.16271"
"61.00000","81.33598","15.18416"
"61.10000","81.46938","15.21777"
"61.20000","81.60265","15.25126"
"61.30000","81.73588","15.28474"
"61.40000","81.86938","15.31998"
"61.50000","82.00273","15.34776"
"61.60000","82.13600","15.39116"
"61.70000","82.26939","15.42245"
"61.80000","82.40268","15.45317"
"61.90000","82.53601","15.48653"
"62.00000","82.66941","15.51952"
"62.10000","82.80263","15.55764"
"62.20000","82.93591","15.58831"
"62.30000","83.06942","15.61766"
"62.40000","83.20264","15.65678"
"62.50000","83.33598","15.69209"
"62.60000","83.46938","15.72344"
"62.70000","83.60265","15.75097"
"62.80000","83.73604","15.78722"
"62.90000","83.86932","15.81625"
"63.00000","84.00261","15.85770"
"63.10000","84.13612","15.88874"
"63.20000","84.26939","15.91570"
"63.30000","84.40273","15.95045"
"63.40000","84.53601","15.98820"
"63.50000","84.66933","16.02607"
"63.60000","84.80267","16.05460"
"63.70000","84.93607","16.08157"
"63.80000","85.06936","16.12389"
"63.90000","85.20264","16.16378"
"64.00000","85.33609","16.20316"
"64.10000","85.46937","16.24624"
"64.20000","85.60264","16.28844"
"64.30000","85.73598","16.31954"
"64.40000","85.86932","16.36908"
"64.50000","86.00272","16.40896"
"64.60000","86.13605","16.45355"
"64.70000","86.26927","16.48578"
"64.80000","86.40278","16.54159"
"64.90000","86.53605","16.57940"
"65.00000","86.66940","16.61446"
"65.10000","86.80267","16.66117"
"65.20000","86.93595","16.71065"
"65.30000","87.06940","16.73699"
"65.40000","87.20268","16.77486"
"65.50000","87.33602","16.81663"
"65.60000","87.46930","16.86177"
"65.70000","87.60263","16.89639"
"65.80000","87.73597","16.93207"
"65.90000","87.86936","16.96568"
"66.00000","88.00276","17.01202"
"66.10000","88.13598","17.04971"
"66.20000","88.26939","17.08508"
"66.30000","88.40266","17.13512"
"66.40000","88.53588","17.16829"
"66.50000","88.66939","17.19839"
"66.60000","88.80267","17.22561"
"66.70000","88.93606","17.27740"
"66.80000","89.06939","17.30273"
"66.90000","89.20261","17.34111"
"67.00000","89.33607","17.37027"
"67.10000","89.46941","17.40815"
"67.20000","89.60263","17.43285"
"67.30000","89.73603","17.47687"
"67.40000","89.86942","17.49964"
"67.50000","90.00270","17.53325"
"67.60000","90.13604","17.56724"
"67.70000","90.26937","17.59407"
"67.80000","90.40266","17.62706"
"67.90000","90.53603","17.64807"
"68.00000","90.66933","17.67760"
"68.10000","90.80254","17.70544"
"68.20000","90.93611","17.74269"
"68.30000","91.06938","17.77386"
"68.40000","91.20261","17.80684"
"68.50000","91.33595","17.83387"
"68.60000","91.46935","17.87156"
"68.70000","91.60262","17.90680"
"68.80000","91.73602","17.93370"
"68.90000","91.86935","17.98092"
"69.00000","92.00269","18.00280"
"69.10000","92.13615","18.04037"
"69.20000","92.26937","18.08859"
"69.30000","92.40270","18.11699"
"69.40000","92.53603","18.16584"
"69.50000","92.66927","18.19764"
"69.60000","92.80265","18.24510"
"69.70000","92.93600","18.28373"
"69.80000","93.06927","18.33070"
"69.90000","93.20277","18.36764"
"70.00000","93.33600","18.41279"
"70.10000","93.46946","18.45699"
"70.20000","93.60262","18.49192"
"70.30000","93.73602","18.52804"
"70.40000","93.86935","18.57890"
"70.50000","94.00275","18.60774"
"70.60000","94.13608","18.65189"
"70.70000","94.26936","18.69165"
"70.80000","94.40275","18.72770"
"70.90000","94.53598","18.77223"
"71.00000","94.66937","18.81085"
"71.10000","94.80264","18.84886"
"71.20000","94.93597","18.89551"
"71.30000","95.06937","18.92366"
"71.40000","95.20266","18.96812"
"71.50000","95.33593","18.99854"
"71.60000","95.46944","19.03811"
"71.70000","95.60266","19.06921"
"71.80000","95.73601","19.10583"
"71.90000","95.86939","19.14634"
"72.00000","96.00268","19.18528"
"72.10000","96.13607","19.22065"
"72.20000","96.26936","19.25878"
"72.30000","96.40269","19.30681"
"72.40000","96.53602","19.34318"
"72.50000","96.66936","19.37158"
"72.60000","96.80264","19.40796"
"72.70000","96.93604","19.44558"
"72.80000","97.06943","19.47599"
"72.90000","97.20265","19.51368"
"73.00000","97.33610","19.54146"
"73.10000","97.46938","19.57670"
"73.20000","97.60249","19.61332"
"73.30000","97.73611","19.64323"
"73.40000","97.86945","19.67553"
"73.50000","98.00273","19.70926"
"73.60000","98.13607","19.73918"
"73.70000","98.26934","19.76683"
"73.80000","98.40269","19.80239"
"73.90000","98.53607","19.82860"
"74.00000","98.66935","19.85914"
"74.10000","98.80264","19.88610"
"74.20000","98.93608","19.90328"
"74.30000","99.06942","19.94103"
"74.40000","99.20264","19.97502"
"74.50000","99.33610","19.99233"
"74.60000","99.46931","20.02575"
"74.70000","99.60271","20.05529"
"74.80000","99.73605","20.06971"
"74.90000","99.86926","20.10708"
"75.00000","100.00277","20.13323"
"75.10000","100.13606","20.16615"
"75.20000","100.26939","20.18992"
"75.30000","100.40267","20.21275"
"75.40000","100.53596","20.23507"
"75.50000","100.66935","20.26172"
"75.60000","100.80274","20.28781"
"75.70000","100.93603","20.31502"
"75.80000","101.06936","20.33208"
"75.90000","101.20269","20.35917"
"76.00000","101.33602","20.36525"
"76.10000","101.46931","20.38996"
"76.20000","101.60265","20.40614"
"76.30000","101.73592","20.41611"
"76.40000","101.86938","20.43091"
"76.50000","102.00271","20.44577"
"76.60000","102.13594","20.45505"
"76.70000","102.26944","20.46634"
"76.80000","102.40260","20.47794"
"76.90000","102.53601","20.47768"
"77.00000","102.66928","20.48157"
"77.10000","102.80263","20.46997"
"77.20000","102.93601","20.47593"
"77.30000","103.06940","20.45586"
"77.40000","103.20268","20.43097"
"77.50000","103.33602","20.40137"
"77.60000","103.46936","20.35653"
"77.70000","103.60270","20.32763"
"77.80000","103.73598","20.25739"
"77.90000","103.86936","20.20359"
"78.00000","104.00259","20.11360"
"78.10000","104.13609","20.02638"
"78.20000","104.26932","19.92009"
"78.30000","104.40260","19.80652"
"78.40000","104.53612","19.69497"
"78.50000","104.66933","19.58686"
"78.60000","104.80267","19.45009"
"78.70000","104.93607","19.33014"
"78.80000","105.06929","19.18252"
"78.90000","105.20268","19.03911"
"79.00000","105.33607","18.87268"
"79.10000","105.46930","18.69804"
"79.20000","105.60263","18.50917"
"79.30000","105.73608","18.31741"
"79.40000","105.86943","18.11988"
"79.50000","106.00276","17.91997"
"79.60000","106.13609","17.73667"
"79.70000","106.26932","17.53563"
"79.80000","106.40271","17.32757"
"79.90000","106.53600","17.11894"
"80.00000","106.66915","16.89808"
"80.10000","106.80278","16.64600"
"80.20000","106.93606","16.37096"
"80.30000","107.06939","16.06971"
"80.40000","107.20272","15.74577"
"80.50000","107.33601","15.37347"
"80.60000","107.46935","14.95158"
"80.70000","107.60268","14.44910"
"80.80000","107.73602","13.84240"
"80.90000","107.86935","12.98105"
"81.00000","108.00269","11.73518"
"81.01400","108.02134","8.94155"
"81.01800","108.02672","7.54756"