File: data/class4/Specimen_RawData_16.csv
Time,Extension,Load
(s),(mm),(N)
"0.00000","0.00006","-0.01859"
"0.20000","0.26871","0.01471"
"0.40000","0.53601","0.06187"
"0.60000","0.80263","0.10651"
"0.80000","1.06936","0.14696"
"1.00000","1.33603","0.18427"
"1.20000","1.60265","0.23287"
"1.40000","1.86932","0.27325"
"1.60000","2.13605","0.31489"
"1.80000","2.40267","0.34468"
"2.00000","2.66923","0.38926"
"2.20000","2.93601","0.43121"
"2.40000","3.20274","0.46263"
"2.60000","3.46936","0.49148"
"2.80000","3.73603","0.54171"
"3.00000","4.00265","0.57494"
"3.20000","4.26921","0.59946"
"3.40000","4.53605","0.64367"
"3.60000","4.80267","0.66662"
"3.80000","5.06946","0.70311"
"4.00000","5.33596","0.73817"
"4.20000","5.60269","0.76777"
"4.40000","5.86931","0.80257"
"4.60000","6.13604","0.82634"
"4.80000","6.40265","0.86383"
"5.00000","6.66933","0.88641"
"5.20000","6.93594","0.91864"
"5.40000","7.20262","0.94548"
"5.60000","7.46935","0.98185"
"5.80000","7.73608","1.00580"
"6.00000","8.00269","1.03572"
"6.20000","8.26931","1.05522"
"6.40000","8.53604","1.08914"
"6.60000","8.80260","1.11868"
"6.80000","9.06933","1.13561"
"7.00000","9.33600","1.15969"
"7.20000","9.60268","1.18853"
"7.40000","9.86929","1.21412"
"7.60000","10.13602","1.24140"
"7.80000","10.40270","1.27382"
"8.00000","10.66931","1.29514"
"8.20000","10.93604","1.30285"
"8.40000","11.20272","1.33395"
"8.60000","11.46933","1.34932"
"8.80000","11.73595","1.37258"
"9.00000","12.00268","1.39835"
"9.20000","12.26935","1.41855"
"9.40000","12.53603","1.43159"
"9.60000","12.80264","1.46307"
"9.80000","13.06937","1.47204"
"10.00000","13.33593","1.49267"
"10.20000","13.60272","1.52590"
"10.40000","13.86928","1.54346"
"10.60000","14.13607","1.55707"
"10.80000","14.40268","1.57707"
"11.00000","14.66936","1.59902"
"11.20000","14.93597","1.61250"
"11.40000","15.20270","1.63464"
"11.60000","15.46932","1.65370"
"11.80000","15.73605","1.67602"
"12.00000","16.00272","1.69013"
"12.20000","16.26928","1.70663"
"12.40000","16.53601","1.72274"
"12.60000","16.80274","1.73723"
"12.80000","17.06936","1.75654"
"13.00000","17.33603","1.77673"
"13.20000","17.60265","1.79492"
"13.40000","17.86927","1.81185"
"13.60000","18.13605","1.82596"
"13.80000","18.40267","1.83731"
"14.00000","18.66934","1.85493"
"14.20000","18.93596","1.86534"
"14.40000","19.20269","1.89851"
"14.60000","19.46931","1.89951"
"14.80000","19.73598","1.91751"
"15.00000","20.00271","1.92961"
"15.20000","20.26938","1.94636"
"15.40000","20.53600","1.95670"
"15.60000","20.80256","1.97583"
"15.80000","21.06935","1.98743"
"16.00000","21.33607","2.00386"
"16.20000","21.60269","2.01446"
"16.40000","21.86942","2.03032"
"16.60000","22.13604","2.05014"
"16.80000","22.40260","2.06023"
"17.00000","22.66933","2.07817"
"17.20000","22.93606","2.08619"
"17.40000","23.20279","2.09943"
"17.60000","23.46935","2.11184"
"17.80000","23.73597","2.12545"
"18.00000","24.00258","2.14131"
"18.20000","24.26943","2.14991"
"18.40000","24.53604","2.16464"
"18.60000","24.80272","2.17054"
"18.80000","25.06933","2.18565"
"19.00000","25.33595","2.19669"
"19.20000","25.60262","2.21801"
"19.40000","25.86935","2.22578"
"19.60000","26.13602","2.23525"
"19.80000","26.40270","2.24754"
"20.00000","26.66932","2.25927"
"20.20000","26.93599","2.26410"
"20.40000","27.20272","2.28749"
"20.60000","27.46928","2.29645"
"20.80000","27.73601","2.30592"
"21.00000","28.00274","2.31677"
"21.20000","28.26930","2.32950"
"21.40000","28.53591","2.34098"
"21.60000","28.80264","2.34455"
"21.80000","29.06938","2.36079"
"22.00000","29.33605","2.37277"
"22.20000","29.60266","2.37960"
"22.40000","29.86928","2.38638"
"22.60000","30.13601","2.40168"
"22.80000","30.40269","2.41528"
"23.00000","30.66930","2.42256"
"23.20000","30.93603","2.43366"
"23.40000","31.20271","2.44269"
"23.60000","31.46921","2.45291"
"23.80000","31.73599","2.46037"
"24.00000","32.00267","2.46639"
"24.20000","32.26940","2.48771"
"24.40000","32.53601","2.49373"
"24.60000","32.80268","2.49963"
"24.80000","33.06936","2.51022"
"25.00000","33.33598","2.52396"
"25.20000","33.60265","2.53292"
"25.40000","33.86932","2.54177"
"25.60000","34.13605","2.55519"
"25.80000","34.40267","2.56152"
"26.00000","34.66929","2.56415"
"26.20000","34.93596","2.57914"
"26.40000","35.20269","2.58284"
"26.60000","35.46936","2.59977"
"26.80000","35.73598","2.60128"
"27.00000","36.00260","2.60811"
"27.20000","36.26933","2.62021"
"27.40000","36.53600","2.63326"
"27.60000","36.80268","2.64479"
"27.80000","37.06935","2.66078"
"28.00000","37.33602","2.66191"
"28.20000","37.60264","2.66781"
"28.40000","37.86937","2.68305"
"28.60000","38.13604","2.69114"
"28.80000","38.40271","2.70255"
"29.00000","38.66927","2.71377"
"29.20000","38.93589","2.71898"
"29.40000","39.20268","2.73785"
"29.60000","39.46930","2.73566"
"29.80000","39.73603","2.74738"
"30.00000","40.00269","2.75409"
"30.20000","40.26931","2.75999"
"30.40000","40.53593","2.76814"
"30.60000","40.80272","2.77999"
"30.80000","41.06939","2.79329"
"31.00000","41.33601","2.80100"
"31.20000","41.60262","2.80250"
"31.40000","41.86935","2.81906"
"31.60000","42.13597","2.82339"
"31.80000","42.40270","2.83605"
"32.00000","42.66937","2.84251"
"32.20000","42.93605","2.84784"
"32.40000","43.20266","2.86233"
"32.60000","43.46922","2.86258"
"32.80000","43.73601","2.88101"
"33.00000","44.00269","2.88810"
"33.20000","44.26936","2.89224"
"33.40000","44.53592","2.90296"
"33.60000","44.80265","2.90754"
"33.80000","45.06938","2.92773"
"34.00000","45.33593","2.93526"
"34.20000","45.60266","2.93457"
"34.40000","45.86934","2.94209"
"34.60000","46.13607","2.94817"
"34.80000","46.40269","2.97194"
"35.00000","46.66930","2.96793"
"35.20000","46.93603","2.98348"
"35.40000","47.20265","2.98279"
"35.60000","47.46933","2.99577"
"35.80000","47.73600","3.00336"
"36.00000","48.00262","3.01678"
"36.20000","48.26935","3.02631"
"36.40000","48.53596","3.03045"
"36.60000","48.80275","3.03578"
"36.80000","49.06936","3.05158"
"37.00000","49.33604","3.04882"
"37.20000","49.60259","3.05716"
"37.40000","49.86932","3.07861"
"37.60000","50.13600","3.07698"
"37.80000","50.40268","3.08036"
"38.00000","50.66935","3.09253"
"38.20000","50.93602","3.09968"
"38.40000","51.20264","3.11291"
"38.60000","51.46936","3.11774"
"38.80000","51.73598","3.12883"
"39.00000","52.00271","3.13868"
"39.20000","52.26933","3.14457"
"39.40000","52.53589","3.14583"
"39.60000","52.80273","3.15900"
"39.80000","53.06935","3.16245"
"40.00000","53.33597","3.17530"
"40.20000","53.60264","3.19788"
"40.40000","53.86937","3.19361"
"40.60000","54.13593","3.19813"
"40.80000","54.40266","3.20534"
"41.00000","54.66933","3.21663"
"41.20000","54.93607","3.21982"
"41.40000","55.20273","3.23744"
"41.60000","55.46930","3.24114"
"41.80000","55.73597","3.24271"
"42.00000","56.00270","3.25688"
"42.20000","56.26943","3.26535"
"42.40000","56.53594","3.27400"
"42.60000","56.80267","3.28253"
"42.80000","57.06928","3.29313"
"43.00000","57.33601","3.29952"
"43.20000","57.60263","3.30598"
"43.40000","57.86941","3.31357"
"43.60000","58.13603","3.32480"
"43.80000","58.40259","3.33176"
"44.00000","58.66926","3.33646"
"44.20000","58.93599","3.34511"
"44.40000","59.20267","3.36292"
"44.60000","59.46934","3.36694"
"44.80000","59.73602","3.37170"
"45.00000","60.00263","3.37452"
"45.20000","60.26936","3.38826"
"45.40000","60.53598","3.39804"
"45.60000","60.80270","3.40381"
"45.80000","61.06939","3.41002"
"46.00000","61.33599","3.41879"
"46.20000","61.60255","3.42902"
"46.40000","61.86934","3.43491"
"46.60000","62.13602","3.44331"
"46.80000","62.40269","3.45535"
"47.00000","62.66931","3.45642"
"47.20000","62.93603","3.47153"
"47.40000","63.20271","3.47805"
"47.60000","63.46932","3.48683"
"47.80000","63.73600","3.49737"
"48.00000","64.00267","3.49655"
"48.20000","64.26940","3.51248"
"48.40000","64.53596","3.51725"
"48.60000","64.80264","3.51543"
"48.80000","65.06942","3.53079"
"49.00000","65.33609","3.52960"
"49.20000","65.60260","3.54559"
"49.40000","65.86932","3.54515"
"49.60000","66.13594","3.56716"
"49.80000","66.40257","3.57124"
"50.00000","66.66930","3.58572"
"50.20000","66.93602","3.59369"
"50.40000","67.20270","3.59224"
"50.60000","67.46937","3.60435"
"50.80000","67.73598","3.61338"
"51.00000","68.00266","3.60917"
"51.20000","68.26945","3.63677"
"51.40000","68.53606","3.63783"
"51.60000","68.80273","3.63984"
"51.80000","69.06924","3.64022"
"52.00000","69.33603","3.65972"
"52.20000","69.60270","3.66317"
"52.40000","69.86937","3.66981"
"52.60000","70.13605","3.68411"
"52.80000","70.40266","3.68850"
"53.00000","70.66928","3.69897"
"53.20000","70.93601","3.70330"
"53.40000","71.20268","3.71866"
"53.60000","71.46935","3.72155"
"53.80000","71.73603","3.72468"
"54.00000","72.00264","3.73553"
"54.20000","72.26932","3.75127"
"54.40000","72.53605","3.76262"
"54.60000","72.80267","3.76488"
"54.80000","73.06934","3.77679"
"55.00000","73.33595","3.77466"
"55.20000","73.60257","3.79611"
"55.40000","73.86935","3.78827"
"55.60000","74.13603","3.81040"
"55.80000","74.40265","3.81354"
"56.00000","74.66933","3.82200"
"56.20000","74.93600","3.82784"
"56.40000","75.20267","3.83649"
"56.60000","75.46928","3.83812"
"56.80000","75.73602","3.84884"
"57.00000","76.00275","3.86201"
"57.20000","76.26936","3.86189"
"57.40000","76.53598","3.87756"
"57.60000","76.80265","3.87800"
"57.80000","77.06933","3.89638"
"58.00000","77.33600","3.90610"
"58.20000","77.60262","3.90359"
"58.40000","77.86935","3.91951"
"58.60000","78.13596","3.93024"
"58.80000","78.40269","3.94109"
"59.00000","78.66931","3.93538"
"59.20000","78.93604","3.94874"
"59.40000","79.20265","3.95977"
"59.60000","79.46938","3.96642"
"59.80000","79.73600","3.97062"
"60.00000","80.00266","3.99320"
"60.20000","80.26929","3.98925"
"60.40000","80.53602","4.00172"
"60.60000","80.80275","4.00304"
"60.80000","81.06937","4.01665"
"61.00000","81.33593","4.01345"
"61.20000","81.60265","4.03101"
"61.40000","81.86933","4.03878"
"61.60000","82.13606","4.04945"
"61.80000","82.40268","4.06061"
"62.00000","82.66923","4.06286"
"62.20000","82.93603","4.06895"
"62.40000","83.20264","4.08036"
"62.60000","83.46938","4.08801"
"62.80000","83.73598","4.09729"
"63.00000","84.00272","4.10256"
"63.20000","84.26928","4.11673"
"63.40000","84.53594","4.12074"
"63.60000","84.80267","4.14150"
"63.80000","85.06947","4.14006"
"64.00000","85.33603","4.14965"
"64.20000","85.60264","4.15718"
"64.40000","85.86932","4.16558"
"64.60000","86.13605","4.17135"
"64.80000","86.40267","4.17944"
"65.00000","86.66933","4.19047"
"65.20000","86.93607","4.19825"
"65.40000","87.20257","4.20690"
"65.60000","87.46930","4.20954"
"65.80000","87.73597","4.22565"
"66.00000","88.00276","4.23218"
"66.20000","88.26926","4.24378"
"66.40000","88.53600","4.25569"
"66.60000","88.80261","4.25118"
"66.80000","89.06934","4.26829"
"67.00000","89.33596","4.27036"
"67.20000","89.60268","4.28366"
"67.40000","89.86935","4.29206"
"67.60000","90.13598","4.29770"
"67.80000","90.40260","4.30642"
"68.00000","90.66939","4.31877"
"68.20000","90.93606","4.32028"
"68.40000","91.20267","4.32881"
"68.60000","91.46935","4.33953"
"68.80000","91.73591","4.34818"
"69.00000","92.00264","4.36135"
"69.20000","92.26926","4.37013"
"69.40000","92.53598","4.37515"
"69.60000","92.80271","4.37866"
"69.80000","93.06938","4.39189"
"70.00000","93.33600","4.38988"
"70.20000","93.60262","4.40707"
"70.40000","93.86929","4.41522"
"70.60000","94.13608","4.43234"
"70.80000","94.40269","4.42450"
"71.00000","94.66931","4.43685"
"71.20000","94.93597","4.44983"
"71.40000","95.20271","4.46532"
"71.60000","95.46932","4.45679"
"71.80000","95.73601","4.47304"
"72.00000","96.00268","4.48802"
"72.20000","96.26924","4.48852"
"72.40000","96.53597","4.49555"
"72.60000","96.80264","4.50815"
"72.80000","97.06943","4.50884"
"73.00000","97.33594","4.52477"
"73.20000","97.60267","4.53386"
"73.40000","97.86934","4.54415"
"73.60000","98.13600","4.55186"
"73.80000","98.40262","4.55970"
"74.00000","98.66935","4.57080"
"74.20000","98.93603","4.57694"
"74.40000","99.20264","4.59162"
"74.60000","99.46931","4.59481"
"74.80000","99.73605","4.60096"
"75.00000","100.00266","4.61394"
"75.20000","100.26933","4.61933"
"75.40000","100.53606","4.63545"
"75.60000","100.80257","4.63564"
"75.80000","101.06929","4.65370"
"76.00000","101.33598","4.64686"
"76.20000","101.60271","4.66385"
"76.40000","101.86932","4.67897"
"76.60000","102.13599","4.69370"
"76.80000","102.40267","4.68649"
"77.00000","102.66928","4.71396"
"77.20000","102.93601","4.70574"
"77.40000","103.20274","4.71697"
"77.60000","103.46931","4.72844"
"77.80000","103.73598","4.73961"
"78.00000","104.00266","4.74280"
"78.20000","104.26939","4.75666"
"78.40000","104.53600","4.76343"
"78.60000","104.80267","4.76732"
"78.80000","105.06934","4.77635"
"79.00000","105.33590","4.78570"
"79.20000","105.60270","4.79930"
"79.40000","105.86931","4.80357"
"79.60000","106.13604","4.81391"
"79.80000","106.40260","4.82156"
"80.00000","106.66933","4.83116"
"80.20000","106.93606","4.84163"
"80.40000","107.20261","4.85386"
"80.60000","107.46930","4.85963"
"80.80000","107.73608","4.86709"
"81.00000","108.00275","4.87681"
"81.20000","108.26926","4.88296"
"81.40000","108.53599","4.89443"
"81.60000","108.80265","4.91067"
"81.80000","109.06934","4.91312"
"82.00000","109.33595","4.91055"
"82.20000","109.60268","4.92415"
"82.40000","109.86935","4.93143"
"82.60000","110.13597","4.93575"
"82.80000","110.40263","4.94391"
"83.00000","110.66936","4.95250"
"83.20000","110.93604","4.96046"
"83.40000","111.20267","4.97300"
"83.60000","111.46940","4.98724"
"83.80000","111.73595","4.99345"
"84.00000","112.00268","4.99991"
"84.20000","112.26936","5.00756"
"84.40000","112.53609","5.02091"
"84.60000","112.80260","5.02530"
"84.80000","113.06931","5.03891"
"85.00000","113.33600","5.04600"
"85.20000","113.60266","5.05402"
"85.40000","113.86928","5.06882"
"85.60000","114.13601","5.06819"
"85.80000","114.40262","5.07340"
"86.00000","114.66931","5.08851"
"86.20000","114.93603","5.10017"
"86.40000","115.20271","5.10952"
"86.60000","115.46932","5.11366"
"86.80000","115.73599","5.12237"
"87.00000","116.00267","5.12570"
"87.20000","116.26929","5.14006"
"87.40000","116.53602","5.15743"
"87.60000","116.80275","5.15498"
"87.80000","117.06937","5.17160"
"88.00000","117.33587","5.16991"
"88.20000","117.60260","5.18809"
"88.40000","117.86938","5.20320"
"88.60000","118.13599","5.21192"
"88.80000","118.40262","5.21010"
"89.00000","118.66935","5.22245"
"89.20000","118.93597","5.23337"
"89.40000","119.20263","5.23669"
"89.60000","119.46931","5.24835"
"89.80000","119.73605","5.25556"
"90.00000","120.00271","5.26528"
"90.20000","120.26928","5.27438"
"90.40000","120.53605","5.28002"
"90.60000","120.80261","5.28604"
"90.80000","121.06934","5.29877"
"91.00000","121.33602","5.31150"
"91.20000","121.60270","5.32285"
"91.40000","121.86919","5.33458"
"91.60000","122.13593","5.34593"
"91.80000","122.40272","5.34699"
"92.00000","122.66934","5.35276"
"92.20000","122.93600","5.37220"
"92.40000","123.20268","5.36894"
"92.60000","123.46930","5.38142"
"92.80000","123.73590","5.39904"
"93.00000","124.00269","5.40286"
"93.20000","124.26936","5.41685"
"93.40000","124.53600","5.41766"
"93.60000","124.80267","5.42933"
"93.80000","125.06938","5.44156"
"94.00000","125.33595","5.44663"
"94.20000","125.60268","5.45322"
"94.40000","125.86941","5.47410"
"94.60000","126.13596","5.47642"
"94.80000","126.40259","5.49040"
"95.00000","126.66936","5.49749"
"95.20000","126.93599","5.50796"
"95.40000","127.20266","5.51329"
"95.60000","127.46927","5.52289"
"95.80000","127.73594","5.53593"
"96.00000","128.00267","5.53800"
"96.20000","128.26930","5.54891"
"96.40000","128.53590","5.56584"
"96.60000","128.80270","5.57343"
"96.80000","129.06937","5.57581"
"97.00000","129.33592","5.58992"
"97.20000","129.60266","5.59456"
"97.40000","129.86934","5.61425"
"97.60000","130.13589","5.61726"
"97.80000","130.40274","5.62372"
"98.00000","130.66942","5.63770"
"98.20000","130.93593","5.64322"
"98.40000","131.20264","5.64742"
"98.60000","131.46933","5.66153"
"98.80000","131.73599","5.67364"
"99.00000","132.00273","5.68041"
"99.20000","132.26939","5.69195"
"99.40000","132.53601","5.69872"
"99.60000","132.80264","5.70806"
"99.80000","133.06935","5.71302"
"100.00000","133.33607","5.72631"
"100.20000","133.60271","5.74487"
"100.40000","133.86932","5.73866"
"100.60000","134.13593","5.75735"
"100.80000","134.40266","5.76582"
"101.00000","134.66939","5.77491"
"101.20000","134.93608","5.78732"
"101.40000","135.20270","5.79140"
"101.60000","135.46919","5.79786"
"101.80000","135.73598","5.81448"
"102.00000","136.00259","5.82363"
"102.20000","136.26933","5.83768"
"102.40000","136.53600","5.84602"
"102.60000","136.80273","5.85988"
"102.80000","137.06935","5.86765"
"103.00000","137.33591","5.87794"
"103.20000","137.60269","5.87838"
"103.40000","137.86948","5.89111"
"103.60000","138.13599","5.90879"
"103.80000","138.40260","5.91882"
"104.00000","138.66939","5.92691"
"104.20000","138.93594","5.92509"
"104.40000","139.20262","5.95030"
"104.60000","139.46936","5.95620"
"104.80000","139.73602","5.96240"
"105.00000","140.00258","5.96548"
"105.20000","140.26926","5.98021"
"105.40000","140.53604","5.99238"
"105.60000","140.80267","6.00128"
"105.80000","141.06927","6.01107"
"106.00000","141.33601","6.01834"
"106.20000","141.60268","6.02850"
"106.40000","141.86929","6.03822"
"106.60000","142.13596","6.05841"
"106.80000","142.40269","6.06042"
"107.00000","142.66937","6.06587"
"107.20000","142.93599","6.07873"
"107.40000","143.20273","6.09729"
"107.60000","143.46927","6.09616"
"107.80000","143.73601","6.11046"
"108.00000","144.00262","6.12181"
"108.20000","144.26936","6.13397"
"108.40000","144.53586","6.13610"
"108.60000","144.80270","6.14363"
"108.80000","145.06932","6.15510"
"109.00000","145.33604","6.17204"
"109.20000","145.60262","6.17812"
"109.40000","145.86938","6.18038"
"109.60000","146.13596","6.19279"
"109.80000","146.40257","6.20402"
"110.00000","146.66930","6.21913"
"110.20000","146.93610","6.21907"
"110.40000","147.20265","6.23004"
"110.60000","147.46927","6.24189"
"110.80000","147.73599","6.25838"
"111.00000","148.00261","6.26340"
"111.20000","148.26929","6.27594"
"111.40000","148.53601","6.28660"
"111.60000","148.80269","6.29243"
"111.80000","149.06918","6.30021"
"112.00000","149.33592","6.31745"
"112.20000","149.60271","6.33476"
"112.40000","149.86945","6.33294"
"112.60000","150.13599","6.34204"
"112.80000","150.40273","6.35326"
"113.00000","150.66936","6.36524"
"113.20000","150.93590","6.36850"
"113.40000","151.20264","6.38255"
"113.60000","151.46942","6.38631"
"113.80000","151.73604","6.40380"
"114.00000","152.00255","6.41283"
"114.20000","152.26939","6.42312"
"114.40000","152.53601","6.42249"
"114.60000","152.80267","6.44206"
"114.80000","153.06929","6.44826"
"115.00000","153.33597","6.45660"
"115.20000","153.60258","6.47065"
"115.40000","153.86931","6.48902"
"115.60000","154.13599","6.48564"
"115.80000","154.40273","6.49993"
"116.00000","154.66933","6.51066"
"116.20000","154.93607","6.52075"
"116.40000","155.20268","6.53060"
"116.60000","155.46930","6.54885"
"116.80000","155.73602","6.55355"
"117.00000","156.00270","6.55844"
"117.20000","156.26938","6.56597"
"117.40000","156.53593","6.58785"
"117.60000","156.80267","6.59293"
"117.80000","157.06927","6.60315"
"118.00000","157.33588","6.61770"
"118.20000","157.60266","6.62021"
"118.40000","157.86940","6.63670"
"118.60000","158.13591","6.64548"
"118.80000","158.40263","6.65952"
"119.00000","158.66933","6.67069"
"119.20000","158.93610","6.67558"
"119.40000","159.20261","6.68241"
"119.60000","159.46939","6.69364"
"119.80000","159.73599","6.70693"
"120.00000","160.00264","6.71954"
"120.20000","160.26936","6.73352"
"120.40000","160.53604","6.74311"
"120.60000","160.80269","6.76092"
"120.80000","161.06927","6.76569"
"121.00000","161.33600","6.77886"
"121.20000","161.60266","6.77955"
"121.40000","161.86935","6.80150"
"121.60000","162.13596","6.80193"
"121.80000","162.40276","6.80908"
"122.00000","162.66925","6.81880"
"122.20000","162.93599","6.82758"
"122.40000","163.20265","6.83323"
"122.60000","163.46939","6.85699"
"122.80000","163.73593","6.85975"
"123.00000","164.00266","6.87637"
"123.20000","164.26935","6.88540"
"123.40000","164.53595","6.90860"
"123.60000","164.80269","6.91061"
"123.80000","165.06937","6.92233"
"124.00000","165.33604","6.92741"
"124.20000","165.60255","6.94597"
"124.40000","165.86931","6.94660"
"124.60000","166.13596","6.96780"
"124.80000","166.40268","6.97513"
"125.00000","166.66936","6.98128"
"125.20000","166.93600","7.00611"
"125.40000","167.20259","7.00529"
"125.60000","167.46931","7.01533"
"125.80000","167.73604","7.02404"
"126.00000","168.00276","7.03978"
"126.20000","168.26939","7.04750"
"126.40000","168.53595","7.07126"
"126.60000","168.80267","7.07603"
"126.80000","169.06931","7.08550"
"127.00000","169.33601","7.10074"
"127.20000","169.60265","7.10444"
"127.40000","169.86931","7.11516"
"127.60000","170.13588","7.13704"
"127.80000","170.40266","7.14620"
"128.00000","170.66939","7.16288"
"128.20000","170.93600","7.17367"
"128.40000","171.20264","7.17435"
"128.60000","171.46936","7.18727"
"128.80000","171.73598","7.19191"
"129.00000","172.00259","7.20790"
"129.20000","172.26936","7.22245"
"129.40000","172.53604","7.23700"
"129.60000","172.80260","7.23951"
"129.80000","173.06927","7.25011"
"130.00000","173.33600","7.26892"
"130.20000","173.60263","7.28804"
"130.40000","173.86929","7.28992"
"130.60000","174.13603","7.29632"
"130.80000","174.40265","7.31413"
"131.00000","174.66927","7.31701"
"131.20000","174.93599","7.33106"
"131.40000","175.20265","7.33777"
"131.60000","175.46930","7.34931"
"131.80000","175.73607","7.36386"
"132.00000","176.00276","7.37753"
"132.20000","176.26935","7.38443"
"132.40000","176.53598","7.39885"
"132.60000","176.80264","7.41509"
"132.80000","177.06938","7.41816"
"133.00000","177.33601","7.43892"
"133.20000","177.60262","7.45409"
"133.40000","177.86929","7.45340"
"133.60000","178.13594","7.46958"
"133.80000","178.40263","7.47899"
"134.00000","178.66931","7.49097"
"134.20000","178.93605","7.50081"
"134.40000","179.20255","7.50620"
"134.60000","179.46931","7.53166"
"134.80000","179.73601","7.54571"
"135.00000","180.00267","7.55022"
"135.20000","180.26935","7.55305"
"135.40000","180.53607","7.57430"
"135.60000","180.80264","7.58522"
"135.80000","181.06924","7.59142"
"136.00000","181.33604","7.59914"
"136.20000","181.60278","7.61751"
"136.40000","181.86934","7.62917"
"136.60000","182.13602","7.64924"
"136.80000","182.40266","7.65940"
"137.00000","182.66930","7.66918"
"137.20000","182.93604","7.68448"
"137.40000","183.20270","7.69025"
"137.60000","183.46933","7.71283"
"137.80000","183.73587","7.71220"
"138.00000","184.00267","7.73277"
"138.20000","184.26939","7.74775"
"138.40000","184.53600","7.75045"
"138.60000","184.80269","7.75547"
"138.80000","185.06935","7.78463"
"139.00000","185.33597","7.78751"
"139.20000","185.60263","7.79924"
"139.40000","185.86926","7.81303"
"139.60000","186.13605","7.82495"
"139.80000","186.40266","7.83843"
"140.00000","186.66934","7.85404"
"140.20000","186.93602","7.86828"
"140.40000","187.20264","7.87724"
"140.60000","187.46928","7.89054"
"140.80000","187.73598","7.90308"
"141.00000","188.00270","7.91518"
"141.20000","188.26926","7.93186"
"141.40000","188.53600","7.94534"
"141.60000","188.80266","7.95444"
"141.80000","189.06935","7.96773"
"142.00000","189.33601","7.97607"
"142.20000","189.60275","7.99633"
"142.40000","189.86931","8.00761"
"142.60000","190.13591","8.02555"
"142.80000","190.40265","8.03564"
"143.00000","190.66931","8.04643"
"143.20000","190.93594","8.05822"
"143.40000","191.20261","8.07001"
"143.60000","191.46935","8.07458"
"143.80000","191.73590","8.09760"
"144.00000","192.00264","8.10876"
"144.20000","192.26932","8.12419"
"144.40000","192.53610","8.13654"
"144.60000","192.80261","8.14325"
"144.80000","193.06934","8.16238"
"145.00000","193.33601","8.17774"
"145.20000","193.60266","8.19655"
"145.40000","193.86923","8.20132"
"145.60000","194.13606","8.21775"
"145.80000","194.40269","8.23023"
"146.00000","194.66925","8.24835"
"146.20000","194.93604","8.26133"
"146.40000","195.20267","8.27594"
"146.60000","195.46925","8.28503"
"146.80000","195.73596","8.29381"
"147.00000","196.00272","8.31143"
"147.20000","196.26930","8.32297"
"147.40000","196.53596","8.33927"
"147.60000","196.80263","8.35044"
"147.80000","197.06932","8.36868"
"148.00000","197.33592","8.37784"
"148.20000","197.60266","8.39747"
"148.40000","197.86928","8.40662"
"148.60000","198.13600","8.42732"
"148.80000","198.40269","8.44268"
"149.00000","198.66936","8.46011"
"149.20000","198.93596","8.46864"
"149.40000","199.20259","8.48394"
"149.60000","199.46939","8.49234"
"149.80000","199.73598","8.51128"
"150.00000","200.00266","8.51987"
"150.20000","200.26929","8.54019"
"150.40000","200.53601","8.55129"
"150.60000","200.80257","8.56251"
"150.80000","201.06935","8.58252"
"151.00000","201.33603","8.59813"
"151.20000","201.60271","8.60622"
"151.40000","201.86922","8.61995"
"151.60000","202.13605","8.63438"
"151.80000","202.40271","8.66147"
"152.00000","202.66936","8.66391"
"152.20000","202.93590","8.67526"
"152.40000","203.20268","8.68925"
"152.60000","203.46930","8.70511"
"152.80000","203.73586","8.73295"
"153.00000","204.00270","8.74474"
"153.20000","204.26938","8.76355"
"153.40000","204.53601","8.76951"
"153.60000","204.80260","8.78889"
"153.80000","205.06934","8.79591"
"154.00000","205.33597","8.81378"
"154.20000","205.60268","8.83103"
"154.40000","205.86931","8.83993"
"154.60000","206.13611","8.86376"
"154.80000","206.40266","8.87774"
"155.00000","206.66933","8.89907"
"155.20000","206.93600","8.90973"
"155.40000","207.20273","8.92352"
"155.60000","207.46930","8.93744"
"155.80000","207.73602","8.94911"
"156.00000","208.00270","8.96309"
"156.20000","208.26927","8.98033"
"156.40000","208.53596","9.00209"
"156.60000","208.80260","9.01652"
"156.80000","209.06940","9.02787"
"157.00000","209.33595","9.03853"
"157.20000","209.60268","9.06831"
"157.40000","209.86929","9.07759"
"157.60000","210.13597","9.09051"
"157.80000","210.40263","9.10061"
"158.00000","210.66937","9.11842"
"158.20000","210.93605","9.12889"
"158.40000","211.20265","9.15090"
"158.60000","211.46933","9.17059"
"158.80000","211.73599","9.18733"
"159.00000","212.00270","9.19837"
"159.20000","212.26935","9.21850"
"159.40000","212.53598","9.23311"
"159.60000","212.80258","9.24628"
"159.80000","213.06932","9.25920"
"160.00000","213.33600","9.27832"
"160.20000","213.60262","9.28823"
"160.40000","213.86929","9.30748"
"160.60000","214.13608","9.32385"
"160.80000","214.40262","9.34241"
"161.00000","214.66934","9.36172"
"161.20000","214.93602","9.37746"
"161.40000","215.20265","9.39214"
"161.60000","215.46931","9.40637"
"161.80000","215.73595","9.42405"
"162.00000","216.00267","9.43271"
"162.20000","216.26941","9.45265"
"162.40000","216.53607","9.47660"
"162.60000","216.80269","9.48877"
"162.80000","217.06937","9.50087"
"163.00000","217.33591","9.51906"
"163.20000","217.60271","9.54163"
"163.40000","217.86928","9.55731"
"163.60000","218.13602","9.57725"
"163.80000","218.40260","9.59242"
"164.00000","218.66934","9.60221"
"164.20000","218.93597","9.62447"
"164.40000","219.20264","9.63983"
"164.60000","219.46938","9.65645"
"164.80000","219.73602","9.67338"
"165.00000","220.00267","9.69125"
"165.20000","220.26933","9.70317"
"165.40000","220.53593","9.72486"
"165.60000","220.80266","9.74656"
"165.80000","221.06934","9.75553"
"166.00000","221.33603","9.78243"
"166.20000","221.60258","9.80174"
"166.40000","221.86926","9.82018"
"166.60000","222.13605","9.83266"
"166.80000","222.40266","9.84808"
"167.00000","222.66928","9.86401"
"167.20000","222.93600","9.88621"
"167.40000","223.20273","9.89411"
"167.60000","223.46922","9.91436"
"167.80000","223.73590","9.92622"
"168.00000","224.00269","9.94823"
"168.20000","224.26936","9.96002"
"168.40000","224.53598","9.98504"
"168.60000","224.80266","9.99476"
"168.80000","225.06938","10.01890"
"169.00000","225.33607","10.02379"
"169.20000","225.60262","10.04555"
"169.40000","225.86929","10.06129"
"169.60000","226.13599","10.08154"
"169.80000","226.40259","10.10268"
"170.00000","226.66931","10.11566"
"170.20000","226.93599","10.13196"
"170.40000","227.20265","10.15535"
"170.60000","227.46928","10.16714"
"170.80000","227.73601","10.17755"
"171.00000","228.00269","10.20106"
"171.20000","228.26930","10.21630"
"171.40000","228.53598","10.23079"
"171.60000","228.80270","10.24026"
"171.80000","229.06932","10.26220"
"172.00000","229.33601","10.27882"
"172.20000","229.60254","10.29287"
"172.40000","229.86942","10.31369"
"172.60000","230.13600","10.32823"
"172.80000","230.40268","10.33852"
"173.00000","230.66931","10.35551"
"173.20000","230.93593","10.37941"
"173.40000","231.20261","10.39326"
"173.60000","231.46939","10.40919"
"173.80000","231.73601","10.42393"
"174.00000","232.00266","10.44117"
"174.20000","232.26933","10.45083"
"174.40000","232.53598","10.46588"
"174.60000","232.80270","10.47754"
"174.80000","233.06943","10.48312"
"175.00000","233.33597","10.35169"
"175.20000","233.60260","10.26810"
"175.40000","233.86932","10.23969"
"175.60000","234.13606","10.22847"
"175.80000","234.40273","10.22082"
"176.00000","234.66936","10.21448"
"176.20000","234.93596","10.22376"
"176.40000","235.20268","10.23580"
"176.60000","235.46919","10.23825"
"176.80000","235.73599","10.24634"
"177.00000","236.00273","10.25524"
"177.20000","236.26932","10.27167"
"177.40000","236.53600","10.28954"
"177.60000","236.80263","10.29795"
"177.80000","237.06929","10.31638"
"178.00000","237.33603","10.33099"
"178.20000","237.60265","10.34159"
"178.40000","237.86938","10.35539"
"178.60000","238.13605","10.37257"
"178.80000","238.40262","10.39251"
"179.00000","238.66930","10.40079"
"179.20000","238.93602","10.42154"
"179.40000","239.20262","10.43578"
"179.60000","239.46935","10.45327"
"179.80000","239.73602","10.47748"
"180.00000","240.00264","10.48607"
"180.20000","240.26938","10.49974"
"180.40000","240.53601","10.51153"
"180.60000","240.80267","10.53517"
"180.80000","241.06935","10.54639"
"181.00000","241.33594","10.56947"
"181.20000","241.60265","10.58527"
"181.40000","241.86940","10.60653"
"181.60000","242.13597","10.62453"
"181.80000","242.40277","10.63243"
"182.00000","242.66931","10.64961"
"182.20000","242.93594","10.66867"
"182.40000","243.20267","10.68899"
"182.60000","243.46930","10.70586"
"182.80000","243.73602","10.72260"
"183.00000","244.00270","10.74737"
"183.20000","244.26930","10.76380"
"183.40000","244.53593","10.78845"
"183.60000","244.80270","10.79867"
"183.80000","245.06938","10.81391"
"184.00000","245.33607","10.83742"
"184.20000","245.60260","10.86614"
"184.40000","245.86934","10.87505"
"184.60000","246.13603","10.90063"
"184.80000","246.40263","10.91035"
"185.00000","246.66937","10.94108"
"185.20000","246.93599","10.95412"
"185.40000","247.20267","10.96566"
"185.60000","247.46924","10.98598"
"185.80000","247.73595","11.00090"
"186.00000","248.00272","11.02247"
"186.20000","248.26936","11.04436"
"186.40000","248.53596","11.04335"
"186.60000","248.80263","10.97061"
"186.80000","249.06926","10.94371"
"187.00000","249.33598","10.93418"
"187.20000","249.60262","10.92841"
"187.40000","249.86937","10.92759"
"187.60000","250.13599","10.92690"
"187.80000","250.40266","10.94271"
"188.00000","250.66927","10.93951"
"188.20000","250.93600","10.95481"
"188.40000","251.20267","10.94954"
"188.60000","251.46931","10.95751"
"188.80000","251.73599","10.95776"
"189.00000","252.00259","10.80619"
"189.20000","252.26933","10.66146"
"189.40000","252.53600","10.62854"
"189.60000","252.80261","10.59800"
"189.80000","253.06934","10.59148"
"190.00000","253.33601","10.59211"
"190.20000","253.60257","10.59681"
"190.40000","253.86929","10.59750"
"190.60000","254.13597","10.60553"
"190.80000","254.40269","10.61086"
"191.00000","254.66934","10.61782"
"191.20000","254.93607","10.63299"
"191.40000","255.20268","10.64378"
"191.60000","255.46935","10.65049"
"191.80000","255.73602","10.67488"
"192.00000","256.00269","10.67582"
"192.20000","256.26932","10.69156"
"192.40000","256.53586","10.71282"
"192.60000","256.80264","10.72593"
"192.80000","257.06931","10.74010"
"193.00000","257.33606","10.75941"
"193.20000","257.60263","10.78080"
"193.40000","257.86929","10.79560"
"193.60000","258.13599","10.81767"
"193.80000","258.40259","10.83993"
"194.00000","258.66925","10.85448"
"194.20000","258.93604","10.87498"
"194.40000","259.20267","10.89160"
"194.60000","259.46921","10.91455"
"194.80000","259.73599","10.93292"
"195.00000","260.00269","10.95951"
"195.20000","260.26935","10.97550"
"195.40000","260.53595","10.99952"
"195.60000","260.80267","11.00755"
"195.80000","261.06927","11.03965"
"196.00000","261.33606","11.06204"
"196.20000","261.60254","11.07960"
"196.40000","261.86935","11.09866"
"196.60000","262.13596","11.12519"
"196.80000","262.40262","11.13923"
"197.00000","262.66925","11.15817"
"197.20000","262.93610","11.18313"
"197.40000","263.20270","11.21404"
"197.60000","263.46930","11.22138"
"197.80000","263.73596","11.24759"
"198.00000","264.00262","11.27468"
"198.20000","264.26935","11.29004"
"198.40000","264.53595","11.31218"
"198.60000","264.80270","11.33526"
"198.80000","265.06931","11.35733"
"199.00000","265.33603","11.38398"
"199.20000","265.60254","11.40668"
"199.40000","265.86932","11.42267"
"199.60000","266.13593","11.45377"
"199.80000","266.40271","11.46155"
"200.00000","266.66928","11.48895"
"200.20000","266.93600","11.51924"
"200.40000","267.20264","11.52764"
"200.60000","267.46927","11.55850"
"200.80000","267.73599","11.58195"
"201.00000","268.00278","11.59863"
"201.20000","268.26926","11.63306"
"201.40000","268.53601","11.65325"
"201.60000","268.80267","11.67971"
"201.80000","269.06934","11.71050"
"202.00000","269.33603","11.72956"
"202.20000","269.60269","11.74518"
"202.40000","269.86935","11.77402"
"202.60000","270.13586","11.79992"
"202.80000","270.40268","11.81754"
"203.00000","270.66928","11.84426"
"203.20000","270.93607","11.86520"
"203.40000","271.20270","11.88959"
"203.60000","271.46936","11.91530"
"203.80000","271.73602","11.94151"
"204.00000","272.00262","11.96879"
"204.20000","272.26932","11.98779"
"204.40000","272.53598","12.01300"
"204.60000","272.80264","12.02974"
"204.80000","273.06934","12.06204"
"205.00000","273.33597","12.08800"
"205.20000","273.60263","12.10844"
"205.40000","273.86935","12.13459"
"205.60000","274.13605","12.15234"
"205.80000","274.40265","12.18237"
"206.00000","274.66919","12.20539"
"206.20000","274.93600","12.23223"
"206.40000","275.20267","12.26032"
"206.60000","275.46933","12.28891"
"206.80000","275.73599","12.31431"
"207.00000","276.00269","12.34203"
"207.20000","276.26929","12.34071"
"207.40000","276.53598","12.36893"
"207.60000","276.80267","12.39721"
"207.80000","277.06934","12.41841"
"208.00000","277.33594","12.44675"
"208.20000","277.60260","12.47227"
"208.40000","277.86935","12.49905"
"208.60000","278.13608","12.52300"
"208.80000","278.40262","12.55323"
"209.00000","278.66931","12.57323"
"209.20000","278.93591","12.60528"
"209.40000","279.20258","12.63531"
"209.60000","279.46930","12.65726"
"209.80000","279.73602","12.68491"
"210.00000","280.00275","12.72179"
"210.20000","280.26935","12.73671"
"210.40000","280.53592","12.75935"
"210.60000","280.80270","12.79252"
"210.80000","281.06937","12.81685"
"211.00000","281.33597","12.84469"
"211.20000","281.60266","12.87454"
"211.40000","281.86932","12.89850"
"211.60000","282.13593","12.91963"
"211.80000","282.40262","12.95305"
"212.00000","282.66934","12.97669"
"212.20000","282.93604","13.00309"
"212.40000","283.20264","13.03407"
"212.60000","283.46927","13.06699"
"212.80000","283.73593","13.09358"
"213.00000","284.00272","13.11728"
"213.20000","284.26935","13.14287"
"213.40000","284.53601","13.17447"
"213.60000","284.80261","13.20633"
"213.80000","285.06934","13.22514"
"214.00000","285.33591","13.24702"
"214.20000","285.60263","13.27944"
"214.40000","285.86932","13.29569"
"214.60000","286.13602","13.32340"
"214.80000","286.40268","13.35676"
"215.00000","286.66928","13.37401"
"215.20000","286.93594","13.40812"
"215.40000","287.20270","13.43364"
"215.60000","287.46936","13.44662"
"215.80000","287.73596","13.47547"
"216.00000","288.00266","13.50362"
"216.20000","288.26920","13.53711"
"216.40000","288.53592","13.55128"
"216.60000","288.80261","13.57580"
"216.80000","289.06940","13.58909"
"217.00000","289.33603","13.63537"
"217.20000","289.60263","13.64679"
"217.40000","289.86935","13.66980"
"217.60000","290.13599","13.68322"
"217.80000","290.40265","13.71708"
"218.00000","290.66931","13.74555"
"218.20000","290.93600","13.75677"
"218.40000","291.20261","13.78719"
"218.60000","291.46921","13.79954"
"218.80000","291.73599","13.82230"
"219.00000","292.00275","13.84074"
"219.20000","292.26932","13.85962"
"219.40000","292.53598","13.87918"
"219.60000","292.80267","13.90100"
"219.80000","293.06934","13.92540"
"220.00000","293.33588","13.94333"
"220.20000","293.60266","13.95581"
"220.40000","293.86935","13.98773"
"220.60000","294.13589","14.00735"
"220.80000","294.40262","14.03012"
"221.00000","294.66931","14.05169"
"221.20000","294.93597","14.07251"
"221.40000","295.20264","14.08587"
"221.60000","295.46930","14.11020"
"221.80000","295.73590","14.12945"
"222.00000","296.00269","14.14826"
"222.20000","296.26929","14.17127"
"222.40000","296.53598","14.19172"
"222.60000","296.80270","14.21134"
"222.80000","297.06931","14.25154"
"223.00000","297.33597","14.27305"
"223.20000","297.60272","14.29205"
"223.40000","297.86932","14.32622"
"223.60000","298.13599","14.34384"
"223.80000","298.40265","14.36792"
"224.00000","298.66931","14.40160"
"224.20000","298.93591","14.41583"
"224.40000","299.20264","14.44556"
"224.60000","299.46933","14.47214"
"224.80000","299.73611","14.49152"
"225.00000","300.00266","14.52037"
"225.20000","300.26929","14.55166"
"225.40000","300.53601","14.57699"
"225.60000","300.80255","14.59931"
"225.80000","301.06934","14.61888"
"226.00000","301.33594","14.65418"
"226.20000","301.60266","14.68309"
"226.40000","301.86932","14.70943"
"226.60000","302.13596","14.73188"
"226.80000","302.40262","14.75941"
"227.00000","302.66940","14.79195"
"227.20000","302.93600","14.80399"
"227.40000","303.20258","14.82393"
"227.60000","303.46924","14.86463"
"227.80000","303.73602","14.89448"
"228.00000","304.00259","14.92201"
"228.20000","304.26938","14.95217"
"228.40000","304.53598","14.99475"
"228.60000","304.80258","15.02247"
"228.80000","305.06931","15.04115"
"229.00000","305.33597","15.07815"
"229.20000","305.60269","15.11214"
"229.40000","305.86938","15.13289"
"229.60000","306.13599","15.16149"
"229.80000","306.40265","15.18601"
"230.00000","306.66925","15.22489"
"230.20000","306.93600","15.25649"
"230.40000","307.20267","15.29104"
"230.60000","307.46939","15.32327"
"230.80000","307.73596","15.35112"
"231.00000","308.00266","15.38053"
"231.20000","308.26932","15.40736"
"231.40000","308.53598","15.40429"
"231.60000","308.80267","15.43979"
"231.80000","309.06940","15.45841"
"232.00000","309.33588","15.46631"
"232.20000","309.60269","15.49327"
"232.40000","309.86929","15.53303"
"232.60000","310.13602","15.55448"
"232.80000","310.40262","15.58163"
"233.00000","310.66931","15.61555"
"233.20000","310.93597","15.64879"
"233.40000","311.20261","15.68949"
"233.60000","311.46930","15.71840"
"233.80000","311.73608","15.73997"
"234.00000","312.00269","15.77515"
"234.20000","312.26920","15.80111"
"234.40000","312.53595","15.82889"
"234.60000","312.80255","15.86883"
"234.80000","313.06937","15.90401"
"235.00000","313.33594","15.92815"
"235.20000","313.60266","15.95744"
"235.40000","313.86923","15.98697"
"235.60000","314.13596","16.02805"
"235.80000","314.40271","16.05764"
"236.00000","314.66934","16.08605"
"236.20000","314.93597","16.12418"
"236.40000","315.20261","16.14845"
"236.60000","315.46933","16.17233"
"236.80000","315.73596","16.21109"
"237.00000","316.00269","16.24307"
"237.20000","316.26935","16.25906"
"237.40000","316.53601","16.29079"
"237.60000","316.80258","16.31675"
"237.80000","317.06934","16.35005"
"238.00000","317.33600","16.39219"
"238.20000","317.60263","16.42718"
"238.40000","317.86932","16.45139"
"238.60000","318.13599","16.49415"
"238.80000","318.40250","16.52544"
"239.00000","318.66925","16.56658"
"239.20000","318.93597","16.60420"
"239.40000","319.20270","16.62346"
"239.60000","319.46933","16.65418"
"239.80000","319.73596","16.68804"
"240.00000","320.00262","16.73175"
"240.20000","320.26929","16.76354"
"240.40000","320.53595","16.79414"
"240.60000","320.80267","16.82612"
"240.80000","321.06940","16.86532"
"241.00000","321.33597","16.89799"
"241.20000","321.60263","16.93279"
"241.40000","321.86929","16.97098"
"241.60000","322.13599","17.00578"
"241.80000","322.40265","17.03758"
"242.00000","322.66937","17.06517"
"242.20000","322.93588","17.10649"
"242.40000","323.20261","17.13314"
"242.60000","323.46927","17.16669"
"242.80000","323.73602","17.20087"
"243.00000","324.00266","17.23184"
"243.20000","324.26929","17.26338"
"243.40000","324.53601","17.27762"
"243.60000","324.80258","17.29938"
"243.80000","325.06931","17.32572"
"244.00000","325.33603","17.35782"
"244.20000","325.60275","17.38893"
"244.40000","325.86929","17.42085"
"244.60000","326.13589","17.44750"
"244.80000","326.40265","17.48330"
"245.00000","326.66928","17.51189"
"245.20000","326.93597","17.52883"
"245.40000","327.20261","17.55548"
"245.60000","327.46915","17.58739"
"245.80000","327.73602","17.60370"
"246.00000","328.00259","17.63386"
"246.20000","328.26941","17.65054"
"246.40000","328.53592","17.66779"
"246.60000","328.80264","17.69243"
"246.80000","329.06937","17.72579"
"247.00000","329.33594","17.75639"
"247.20000","329.60266","17.78794"
"247.40000","329.86938","17.80875"
"247.60000","330.13599","17.84838"
"247.80000","330.40259","17.88632"
"248.00000","330.66931","17.91304"
"248.20000","330.93604","17.95154"
"248.40000","331.20264","17.98452"
"248.60000","331.46924","18.00867"
"248.80000","331.73605","18.03732"
"249.00000","332.00253","18.07614"
"249.20000","332.26926","18.10812"
"249.40000","332.53595","18.14712"
"249.60000","332.80267","18.18531"
"249.80000","333.06931","18.22482"
"250.00000","333.33600","18.26250"
"250.20000","333.60266","18.29718"
"250.40000","333.86929","18.32427"
"250.60000","334.13593","18.37181"
"250.80000","334.40265","18.39814"
"251.00000","334.66928","18.44204"
"251.20000","334.93591","18.46066"
"251.40000","335.20264","18.50757"
"251.60000","335.46927","18.53616"
"251.80000","335.73596","18.57372"
"252.00000","336.00266","18.62138"
"252.20000","336.26938","18.68001"
"252.40000","336.53592","18.70516"
"252.60000","336.80264","18.73250"
"252.80000","337.06921","18.78430"
"253.00000","337.33603","18.82524"
"253.20000","337.60257","18.87522"
"253.40000","337.86938","18.88814"
"253.60000","338.13602","18.93110"
"253.80000","338.40256","18.96364"
"254.00000","338.66928","19.00572"
"254.20000","338.93604","19.04999"
"254.40000","339.20273","19.10548"
"254.60000","339.46927","19.14135"
"254.80000","339.73599","19.18619"
"255.00000","340.00266","19.22845"
"255.20000","340.26932","19.27229"
"255.40000","340.53598","19.31411"
"255.60000","340.80267","19.35205"
"255.80000","341.06921","19.36742"
"256.00000","341.33600","19.40429"
"256.20000","341.60260","19.43620"
"256.40000","341.86948","19.46398"
"256.60000","342.13596","19.51108"
"256.80000","342.40262","19.55228"
"257.00000","342.66925","19.59812"
"257.20000","342.93597","19.65066"
"257.40000","343.20261","19.69193"
"257.60000","343.46927","19.73193"
"257.80000","343.73599","19.76837"
"258.00000","344.00256","19.79734"
"258.20000","344.26935","19.82913"
"258.40000","344.53604","19.87948"
"258.60000","344.80270","19.92300"
"258.80000","345.06924","19.97518"
"259.00000","345.33597","20.01857"
"259.20000","345.60266","20.06134"
"259.40000","345.86929","20.10323"
"259.60000","346.13605","20.13684"
"259.80000","346.40277","20.17672"
"260.00000","346.66928","20.21209"
"260.20000","346.93597","20.22877"
"260.40000","347.20267","20.26990"
"260.60000","347.46933","20.32277"
"260.80000","347.73599","20.37105"
"261.00000","348.00266","20.42561"
"261.20000","348.26929","20.46229"
"261.40000","348.53583","20.51026"
"261.60000","348.80261","20.56494"
"261.80000","349.06931","20.60181"
"262.00000","349.33600","20.64226"
"262.20000","349.60266","20.64828"
"262.40000","349.86942","20.65198"
"262.60000","350.13602","20.67023"
"262.80000","350.40262","20.71945"
"263.00000","350.66928","20.74698"
"263.20000","350.93610","20.78398"
"263.40000","351.20264","20.83226"
"263.60000","351.46924","20.88738"
"263.80000","351.73599","20.92921"
"264.00000","352.00266","20.98101"
"264.20000","352.26935","20.99988"
"264.40000","352.53607","21.01801"
"264.60000","352.80270","21.06629"
"264.80000","353.06918","21.11363"
"265.00000","353.33591","21.15609"
"265.20000","353.60260","21.20556"
"265.40000","353.86923","21.24770"
"265.60000","354.13596","21.29705"
"265.80000","354.40268","21.33167"
"266.00000","354.66934","21.35481"
"266.20000","354.93588","21.36666"
"266.40000","355.20261","21.39726"
"266.60000","355.46945","21.43721"
"266.80000","355.73605","21.49527"
"267.00000","356.00259","21.52493"
"267.20000","356.26923","21.57723"
"267.40000","356.53598","21.62088"
"267.60000","356.80267","21.66233"
"267.80000","357.06924","21.70233"
"268.00000","357.33606","21.71845"
"268.20000","357.60251","21.73826"
"268.40000","357.86923","21.77658"
"268.60000","358.13596","21.82493"
"268.80000","358.40268","21.85716"
"269.00000","358.66928","21.87509"
"269.20000","358.93591","21.91240"
"269.40000","359.20264","21.94896"
"269.60000","359.46930","21.98458"
"269.80000","359.73596","21.99047"
"270.00000","360.00275","22.03111"
"270.20000","360.26929","22.07450"
"270.40000","360.53592","22.11150"
"270.60000","360.80270","22.16029"
"270.80000","361.06934","22.19766"
"271.00000","361.33606","22.23742"
"271.20000","361.60263","22.26890"
"271.40000","361.86935","22.27228"
"271.60000","362.13583","22.27623"
"271.80000","362.40265","22.29511"
"272.00000","362.66925","22.33035"
"272.20000","362.93604","22.37418"
"272.40000","363.20258","22.41300"
"272.60000","363.46930","22.45294"
"272.80000","363.73599","22.48649"
"273.00000","364.00256","22.49671"
"273.20000","364.26929","22.53484"
"273.40000","364.53601","22.59146"
"273.60000","364.80267","22.61975"
"273.80000","365.06924","22.68277"
"274.00000","365.33606","22.71857"
"274.20000","365.60266","22.74102"
"274.40000","365.86942","22.72171"
"274.60000","366.13596","22.72716"
"274.80000","366.40274","22.74761"
"275.00000","366.66925","22.79251"
"275.20000","366.93597","22.81426"
"275.40000","367.20258","22.87628"
"275.60000","367.46936","22.93517"
"275.80000","367.73596","22.87290"
"276.00000","368.00269","22.88180"
"276.20000","368.26926","22.90820"
"276.40000","368.53589","22.95968"
"276.60000","368.80261","22.95856"
"276.80000","369.06943","22.95680"
"277.00000","369.33603","22.93767"
"277.20000","369.60263","22.94118"
"277.40000","369.86932","22.93761"
"277.60000","370.13596","22.92927"
"277.80000","370.40262","22.93191"
"278.00000","370.66934","22.95285"
"278.20000","370.93597","22.97524"
"278.40000","371.20255","22.99392"
"278.60000","371.46930","23.00772"
"278.80000","371.73602","23.01280"
"279.00000","372.00272","23.00289"
"279.20000","372.26932","22.99932"
"279.40000","372.53592","23.00126"
"279.60000","372.80264","23.02289"
"279.80000","373.06921","23.05738"
"280.00000","373.33597","23.07826"
"280.20000","373.60263","23.09664"
"280.40000","373.86935","23.08265"
"280.60000","374.13596","23.09062"
"280.80000","374.40271","23.13395"
"281.00000","374.66928","23.15245"
"281.20000","374.93588","23.17741"
"281.40000","375.20276","23.19823"
"281.60000","375.46939","23.18393"
"281.80000","375.73593","23.16229"
"282.00000","376.00256","23.18299"
"282.20000","376.26938","23.20619"
"282.40000","376.53595","23.23528"
"282.60000","376.80267","23.26419"
"282.80000","377.06931","23.28119"
"283.00000","377.33603","23.26538"
"283.20000","377.60257","23.27410"
"283.40000","377.86929","23.31292"
"283.60000","378.13605","23.32997"
"283.80000","378.40262","23.34465"
"284.00000","378.66922","23.33700"
"284.20000","378.93607","23.30702"
"284.40000","379.20267","23.30558"
"284.60000","379.46924","23.32188"
"284.80000","379.73596","23.33511"
"285.00000","380.00272","23.32019"
"285.20000","380.26929","23.28307"
"285.40000","380.53601","23.21302"
"285.59800","380.80005","20.10893"
"285.60800","380.81332","13.63757"