File: data/class4/Specimen_RawData_17.csv
Time,Extension,Load
(s),(mm),(N)
"0.00000","0.00000","-0.01558"
"0.10000","0.48920","0.02085"
"0.20000","1.00810","0.11516"
"0.30000","1.50994","0.19593"
"0.40000","2.00997","0.27099"
"0.50000","2.50977","0.33044"
"0.60000","3.00985","0.39208"
"0.70000","3.50999","0.46037"
"0.80000","4.01007","0.51969"
"0.90000","4.51004","0.57475"
"1.00000","5.00996","0.63118"
"1.10000","5.50998","0.69640"
"1.20000","6.01007","0.74531"
"1.30000","6.51004","0.80388"
"1.40000","7.00984","0.84934"
"1.50000","7.50975","0.90095"
"1.60000","8.00995","0.95112"
"1.70000","8.50997","0.99827"
"1.80000","9.01011","1.04455"
"1.90000","9.50997","1.07484"
"2.00000","10.00988","1.11723"
"2.10000","10.50997","1.15868"
"2.20000","11.01011","1.20878"
"2.30000","11.50996","1.25243"
"2.40000","12.00982","1.29181"
"2.50000","12.50985","1.33044"
"2.60000","13.01004","1.36555"
"2.70000","13.51007","1.40029"
"2.80000","14.01004","1.43604"
"2.90000","14.50990","1.47755"
"3.00000","15.00981","1.51454"
"3.10000","15.51001","1.54339"
"3.20000","16.01003","1.57525"
"3.30000","16.50994","1.60466"
"3.40000","17.00986","1.62435"
"3.50000","17.50989","1.66680"
"3.60000","18.01003","1.69583"
"3.70000","18.51005","1.73321"
"3.80000","19.00996","1.75196"
"3.90000","19.50977","1.78318"
"4.00000","20.00985","1.81253"
"4.10000","20.51004","1.84702"
"4.20000","21.01013","1.86119"
"4.30000","21.50999","1.88546"
"4.40000","22.00990","1.91738"
"4.50000","22.50993","1.94002"
"4.60000","23.01007","1.95143"
"4.70000","23.51009","1.97883"
"4.80000","24.00983","2.01345"
"4.90000","24.50980","2.02536"
"5.00000","25.01000","2.06023"
"5.10000","25.51008","2.07390"
"5.20000","26.01011","2.09183"
"5.30000","26.50991","2.11723"
"5.40000","27.00983","2.13692"
"5.50000","27.50991","2.15586"
"5.60000","28.01005","2.18113"
"5.70000","28.50985","2.19843"
"5.80000","29.00993","2.21606"
"5.90000","29.50985","2.23850"
"6.00000","30.01004","2.25437"
"6.10000","30.51007","2.27544"
"6.20000","31.01010","2.27883"
"6.30000","31.50984","2.31131"
"6.40000","32.00975","2.33401"
"6.50000","32.51001","2.35727"
"6.60000","33.01003","2.36467"
"6.70000","33.51000","2.38029"
"6.80000","34.00991","2.40085"
"6.90000","34.50988","2.42343"
"7.00000","35.01003","2.43773"
"7.10000","35.51011","2.45967"
"7.20000","36.00991","2.47378"
"7.30000","36.50976","2.49441"
"7.40000","37.00990","2.51147"
"7.50000","37.51004","2.51937"
"7.60000","38.01013","2.54113"
"7.70000","38.50993","2.55969"
"7.80000","39.00990","2.56922"
"7.90000","39.50981","2.59086"
"8.00000","40.01012","2.61180"
"8.10000","40.51004","2.62127"
"8.20000","41.00989","2.62654"
"8.30000","41.50986","2.64974"
"8.40000","42.00988","2.66335"
"8.50000","42.51003","2.68110"
"8.60000","43.01017","2.69709"
"8.70000","43.50991","2.70499"
"8.80000","44.00977","2.72549"
"8.90000","44.50990","2.74211"
"9.00000","45.01004","2.75979"
"9.10000","45.51001","2.77591"
"9.20000","46.00993","2.79228"
"9.30000","46.50990","2.80557"
"9.40000","47.00998","2.82143"
"9.50000","47.51007","2.83391"
"9.60000","48.01009","2.84577"
"9.70000","48.50978","2.86571"
"9.80000","49.00981","2.87944"
"9.90000","49.51000","2.89587"
"10.00000","50.01009","2.91249"
"10.10000","50.51006","2.92327"
"10.20000","51.00997","2.93299"
"10.30000","51.50989","2.94302"
"10.40000","52.00997","2.96842"
"10.50000","52.51005","2.98335"
"10.60000","53.00991","2.99281"
"10.70000","53.50977","3.00648"
"10.80000","54.00985","3.03075"
"10.90000","54.51004","3.05947"
"11.00000","55.01019","3.05464"
"11.10000","55.50998","3.07891"
"11.20000","56.00985","3.08380"
"11.30000","56.50981","3.09967"
"11.40000","57.01001","3.10556"
"11.50000","57.50992","3.13441"
"11.60000","58.00994","3.14275"
"11.70000","58.50986","3.14595"
"11.80000","59.01000","3.16350"
"11.90000","59.51003","3.18821"
"12.00000","60.01011","3.19674"
"12.10000","60.50985","3.21373"
"12.20000","61.00982","3.22571"
"12.30000","61.50985","3.23355"
"12.40000","62.00999","3.25581"
"12.50000","62.51007","3.26522"
"12.60000","63.00998","3.27839"
"12.70000","63.50990","3.30290"
"12.80000","64.00998","3.31488"
"12.90000","64.51006","3.32291"
"13.00000","65.01003","3.34197"
"13.10000","65.50978","3.37213"
"13.20000","66.00992","3.36768"
"13.30000","66.50995","3.38674"
"13.40000","67.01009","3.39778"
"13.50000","67.51006","3.41553"
"13.60000","68.00991","3.43484"
"13.70000","68.50983","3.45221"
"13.80000","69.01002","3.45491"
"13.90000","69.51005","3.47585"
"14.00000","70.00996","3.49128"
"14.10000","70.50987","3.49999"
"14.20000","71.00996","3.51743"
"14.30000","71.51004","3.52765"
"14.40000","72.01007","3.53662"
"14.50000","72.51004","3.54978"
"14.60000","73.00984","3.56991"
"14.70000","73.50980","3.59268"
"14.80000","74.01001","3.60196"
"14.90000","74.51003","3.61632"
"15.00000","75.01006","3.63030"
"15.10000","75.50991","3.64585"
"15.20000","76.00999","3.66297"
"15.30000","76.51003","3.67815"
"15.40000","77.01005","3.68053"
"15.50000","77.50980","3.70956"
"15.60000","78.00982","3.71471"
"15.70000","78.50990","3.73552"
"15.80000","79.01005","3.74938"
"15.90000","79.51007","3.77240"
"16.00000","80.01004","3.77773"
"16.10000","80.50990","3.79779"
"16.20000","81.00999","3.80645"
"16.30000","81.51007","3.82645"
"16.40000","82.00997","3.83623"
"16.50000","82.50983","3.85210"
"16.60000","83.00986","3.86614"
"16.70000","83.50999","3.89361"
"16.80000","84.01008","3.89524"
"16.90000","84.51011","3.91725"
"17.00000","85.00990","3.92929"
"17.10000","85.50983","3.94233"
"17.20000","86.01003","3.96221"
"17.30000","86.51004","3.97870"
"17.40000","87.00996","3.98360"
"17.50000","87.50982","4.00429"
"17.60000","88.00996","4.02636"
"17.70000","88.51004","4.02793"
"17.80000","89.01007","4.04147"
"17.90000","89.50998","4.06969"
"18.00000","90.00979","4.07734"
"18.10000","90.50992","4.10130"
"18.20000","91.01006","4.10889"
"18.30000","91.51009","4.12889"
"18.40000","92.00995","4.14237"
"18.50000","92.50992","4.14758"
"18.60000","93.00993","4.16933"
"18.70000","93.51002","4.19342"
"18.80000","94.01005","4.20144"
"18.90000","94.50991","4.21386"
"19.00000","95.00988","4.23041"
"19.10000","95.51002","4.25173"
"19.20000","96.01010","4.26716"
"19.30000","96.51002","4.27581"
"19.40000","97.00987","4.29331"
"19.50000","97.50978","4.31369"
"19.60000","98.00993","4.33194"
"19.70000","98.51006","4.34761"
"19.80000","99.00992","4.36059"
"19.90000","99.50995","4.37445"
"20.00000","100.00992","4.39414"
"20.10000","100.51006","4.41051"
"20.20000","101.01009","4.42198"
"20.30000","101.51006","4.43917"
"20.40000","102.00980","4.45491"
"20.50000","102.50977","4.48174"
"20.60000","103.01002","4.48814"
"20.70000","103.51006","4.49736"
"20.80000","104.00996","4.51642"
"20.90000","104.50993","4.53009"
"21.00000","105.00990","4.54038"
"21.10000","105.51004","4.56320"
"21.20000","106.01012","4.58578"
"21.30000","106.50999","4.59054"
"21.40000","107.00978","4.61412"
"21.50000","107.50986","4.63331"
"21.60000","108.01001","4.64999"
"21.70000","108.51015","4.66447"
"21.80000","109.00995","4.67225"
"21.90000","109.50986","4.68536"
"22.00000","110.00988","4.70956"
"22.10000","110.51007","4.72129"
"22.20000","111.01000","4.73559"
"22.30000","111.50990","4.75383"
"22.40000","112.00983","4.77528"
"22.50000","112.51002","4.78726"
"22.60000","113.01004","4.80375"
"22.70000","113.51001","4.82093"
"22.80000","114.00986","4.83140"
"22.90000","114.50979","4.85028"
"23.00000","115.00999","4.87291"
"23.10000","115.51007","4.88928"
"23.20000","116.00997","4.90703"
"23.30000","116.50989","4.92202"
"23.40000","117.00986","4.93029"
"23.50000","117.51000","4.95462"
"23.60000","118.01003","4.97707"
"23.70000","118.50999","4.98792"
"23.80000","119.00975","4.99551"
"23.90000","119.50983","5.01827"
"24.00000","120.00996","5.03972"
"24.10000","120.51016","5.04988"
"24.20000","121.00996","5.06304"
"24.30000","121.50993","5.08117"
"24.40000","122.00978","5.09948"
"24.50000","122.50998","5.11033"
"24.60000","123.01006","5.14155"
"24.70000","123.50992","5.14576"
"24.80000","124.00978","5.16313"
"24.90000","124.50993","5.18689"
"25.00000","125.01006","5.19561"
"25.10000","125.51008","5.21492"
"25.20000","126.01000","5.22884"
"25.30000","126.50984","5.25386"
"25.40000","127.00983","5.27073"
"25.50000","127.51001","5.29017"
"25.60000","128.00999","5.30541"
"25.70000","128.50990","5.32861"
"25.80000","129.00981","5.33639"
"25.90000","129.51001","5.36210"
"26.00000","130.00998","5.37602"
"26.10000","130.51012","5.39170"
"26.20000","131.00986","5.41496"
"26.30000","131.50984","5.42512"
"26.40000","132.00992","5.44694"
"26.50000","132.51007","5.45503"
"26.60000","133.01003","5.47754"
"26.70000","133.50989","5.49592"
"26.80000","134.00980","5.51097"
"26.90000","134.50999","5.53473"
"27.00000","135.01009","5.54972"
"27.10000","135.50999","5.56596"
"27.20000","136.00974","5.57511"
"27.30000","136.50992","5.58841"
"27.40000","137.01003","5.61820"
"27.50000","137.50998","5.63469"
"27.60000","138.00990","5.65344"
"27.70000","138.50993","5.66704"
"27.80000","139.00980","5.68492"
"27.90000","139.51004","5.71257"
"28.00000","140.00999","5.71326"
"28.10000","140.50992","5.74054"
"28.20000","141.00984","5.75879"
"28.30000","141.50992","5.77622"
"28.40000","142.01001","5.79929"
"28.50000","142.51009","5.81786"
"28.60000","143.00995","5.82576"
"28.70000","143.50975","5.85040"
"28.80000","144.00987","5.87737"
"28.90000","144.51007","5.89229"
"29.00000","145.01004","5.89812"
"29.10000","145.50990","5.92578"
"29.20000","146.00987","5.94076"
"29.30000","146.50996","5.96346"
"29.40000","147.00998","5.97488"
"29.50000","147.51001","6.00203"
"29.60000","148.00970","6.01570"
"29.70000","148.50983","6.03276"
"29.80000","149.00992","6.05439"
"29.90000","149.51012","6.07345"
"30.00000","150.01004","6.08010"
"30.10000","150.50999","6.10330"
"30.20000","151.00986","6.12701"
"30.30000","151.50999","6.14613"
"30.40000","152.00996","6.16519"
"30.50000","152.50989","6.18194"
"30.60000","153.00984","6.19485"
"30.70000","153.50987","6.21944"
"30.80000","154.00995","6.23768"
"30.90000","154.51016","6.26063"
"31.00000","155.01001","6.27801"
"31.10000","155.50981","6.28973"
"31.20000","156.00984","6.31387"
"31.30000","156.51004","6.32949"
"31.40000","157.00995","6.35150"
"31.50000","157.50998","6.36504"
"31.60000","158.00983","6.39201"
"31.70000","158.50990","6.40499"
"31.80000","159.01001","6.42261"
"31.90000","159.51009","6.44337"
"32.00000","160.00993","6.46030"
"32.10000","160.50974","6.48663"
"32.20000","161.00987","6.50319"
"32.30000","161.51009","6.52827"
"32.40000","162.00998","6.54827"
"32.50000","162.50990","6.56728"
"32.60000","163.00986","6.59411"
"32.70000","163.50984","6.60327"
"32.80000","164.01004","6.63048"
"32.90000","164.51001","6.65525"
"33.00000","165.00981","6.67037"
"33.10000","165.50989","6.69256"
"33.20000","166.00998","6.71294"
"33.30000","166.51012","6.72455"
"33.40000","167.00998","6.75835"
"33.50000","167.50989","6.77521"
"33.60000","168.00978","6.79371"
"33.70000","168.50987","6.82344"
"33.80000","169.00995","6.83924"
"33.90000","169.50998","6.86633"
"34.00000","170.00990","6.87793"
"34.10000","170.50993","6.90985"
"34.20000","171.00996","6.93010"
"34.30000","171.51010","6.94816"
"34.40000","172.00995","6.97688"
"34.50000","172.50977","6.99513"
"34.60000","173.00984","7.01896"
"34.70000","173.50998","7.03765"
"34.80000","174.01007","7.06398"
"34.90000","174.51003","7.08562"
"35.00000","175.00995","7.10186"
"35.10000","175.50992","7.12236"
"35.20000","176.01006","7.15591"
"35.30000","176.51009","7.17259"
"35.40000","177.00978","7.19962"
"35.50000","177.50980","7.21805"
"35.60000","178.00989","7.24640"
"35.70000","178.51003","7.26252"
"35.80000","179.01006","7.27756"
"35.90000","179.50999","7.31230"
"36.00000","180.00981","7.33425"
"36.10000","180.50995","7.36736"
"36.20000","181.01004","7.37953"
"36.30000","181.50995","7.40436"
"36.40000","182.00987","7.42518"
"36.50000","182.50984","7.45434"
"36.60000","183.00992","7.47660"
"36.70000","183.51001","7.49811"
"36.80000","184.01009","7.52846"
"36.90000","184.50989","7.54232"
"37.00000","185.00981","7.56953"
"37.10000","185.51006","7.59135"
"37.20000","186.01003","7.61104"
"37.30000","186.51006","7.63864"
"37.40000","187.00986","7.66322"
"37.50000","187.50993","7.69614"
"37.60000","188.00996","7.71526"
"37.70000","188.51004","7.74129"
"37.80000","189.00983","7.76261"
"37.90000","189.50983","7.79032"
"38.00000","190.00990","7.80763"
"38.10000","190.51003","7.83560"
"38.20000","191.01007","7.86219"
"38.30000","191.50996","7.89110"
"38.40000","192.00989","7.91649"
"38.50000","192.50990","7.94321"
"38.60000","193.00999","7.96917"
"38.70000","193.51003","7.98685"
"38.80000","194.00983","8.01714"
"38.90000","194.50984","8.04047"
"39.00000","195.00993","8.06511"
"39.10000","195.51007","8.10223"
"39.20000","196.01010","8.12876"
"39.30000","196.50996","8.14293"
"39.40000","197.00974","8.17278"
"39.50000","197.50990","8.20953"
"39.60000","198.01004","8.22903"
"39.70000","198.50996","8.25957"
"39.80000","199.00992","8.27738"
"39.90000","199.50984","8.31362"
"40.00000","200.01001","8.34403"
"40.10000","200.51006","8.36147"
"40.20000","201.01004","8.39583"
"40.30000","201.50977","8.41778"
"40.40000","202.00980","8.44806"
"40.50000","202.50998","8.47465"
"40.60000","203.01007","8.49873"
"40.70000","203.50999","8.52626"
"40.80000","204.00989","8.55548"
"40.90000","204.50981","8.58772"
"41.00000","205.00995","8.60872"
"41.10000","205.51004","8.64152"
"41.20000","206.00989","8.66321"
"41.30000","206.50981","8.69081"
"41.40000","207.00984","8.71758"
"41.50000","207.51003","8.74379"
"41.60000","208.01006","8.76524"
"41.70000","208.51003","8.79358"
"41.80000","209.00983","8.78368"
"41.90000","209.50986","8.74680"
"42.00000","210.01006","8.74361"
"42.10000","210.50996","8.76148"
"42.20000","211.00995","8.76254"
"42.30000","211.50984","8.78988"
"42.40000","212.00987","8.81491"
"42.50000","212.51001","8.82506"
"42.60000","213.01009","8.85190"
"42.70000","213.50980","8.87090"
"42.80000","214.00975","8.89893"
"42.90000","214.50996","8.91931"
"43.00000","215.00998","8.94948"
"43.10000","215.50999","8.98277"
"43.20000","216.00992","9.01149"
"43.30000","216.50987","9.03507"
"43.40000","217.00993","9.06523"
"43.50000","217.51004","9.09696"
"43.60000","218.01003","9.12186"
"43.70000","218.50972","9.15591"
"43.80000","219.00980","9.17817"
"43.90000","219.50999","9.21755"
"44.00000","220.01007","9.24727"
"44.10000","220.50999","9.27223"
"44.20000","221.00986","9.30126"
"44.30000","221.50981","9.33356"
"44.40000","222.00996","9.36855"
"44.50000","222.50998","9.39859"
"44.60000","223.00989","9.43659"
"44.70000","223.50981","9.46857"
"44.80000","224.00990","9.50575"
"44.90000","224.51004","9.54100"
"45.00000","225.01013","9.56771"
"45.10000","225.50993","9.59957"
"45.20000","226.00978","9.63650"
"45.30000","226.50987","9.66886"
"45.40000","227.01001","9.70429"
"45.50000","227.50996","9.74223"
"45.60000","228.00998","9.77057"
"45.70000","228.50978","9.81202"
"45.80000","229.00987","9.84996"
"45.90000","229.51001","9.88350"
"46.00000","230.01009","9.92690"
"46.10000","230.50978","9.95618"
"46.20000","231.00981","9.99945"
"46.30000","231.50984","10.02968"
"46.40000","232.01004","10.06674"
"46.50000","232.50999","10.10016"
"46.60000","233.00992","10.15045"
"46.70000","233.50978","10.18808"
"46.80000","234.00992","10.22696"
"46.90000","234.51007","10.26703"
"47.00000","235.00992","10.30948"
"47.10000","235.50984","10.34234"
"47.20000","236.00992","10.37469"
"47.30000","236.51001","10.42499"
"47.40000","237.01003","10.47007"
"47.50000","237.51006","10.51334"
"47.60000","238.00984","10.54839"
"47.70000","238.50970","10.59687"
"47.80000","239.00995","10.62734"
"47.90000","239.50999","10.67193"
"48.00000","240.01003","10.70968"
"48.10000","240.50981","10.75859"
"48.20000","241.00989","10.79076"
"48.30000","241.51006","10.83547"
"48.40000","242.01006","10.87567"
"48.50000","242.50992","10.90088"
"48.60000","243.00972","10.78543"
"48.70000","243.50980","10.66371"
"48.80000","244.01006","10.66353"
"48.90000","244.51009","10.68541"
"49.00000","245.00999","10.71375"
"49.10000","245.50980","10.74047"
"49.20000","246.00995","10.76467"
"49.30000","246.51003","10.80017"
"49.40000","247.00993","10.83578"
"49.50000","247.50975","10.87272"
"49.60000","248.00983","10.90727"
"49.70000","248.50986","10.94866"
"49.80000","249.01003","10.98860"
"49.90000","249.51003","11.02428"
"50.00000","250.00995","11.07614"
"50.10000","250.50983","11.11784"
"50.20000","251.00992","11.16092"
"50.30000","251.50999","11.20846"
"50.40000","252.00996","11.25480"
"50.50000","252.50980","11.29756"
"50.60000","253.00989","11.34008"
"50.70000","253.50987","11.39445"
"50.80000","254.01006","11.43571"
"50.90000","254.51004","11.48123"
"51.00000","255.00983","11.53272"
"51.10000","255.50980","11.58363"
"51.20000","256.01001","11.62998"
"51.30000","256.51001","11.68854"
"51.40000","257.00995","11.73727"
"51.50000","257.50980","11.78066"
"51.60000","258.00989","11.83321"
"51.70000","258.50992","11.88507"
"51.80000","259.01004","11.94151"
"51.90000","259.50986","11.98534"
"52.00000","260.00983","12.04667"
"52.10000","260.50986","12.09721"
"52.20000","261.01004","12.15634"
"52.30000","261.51001","12.21704"
"52.40000","262.00998","12.26546"
"52.50000","262.50980","12.32014"
"52.60000","263.00989","12.37852"
"52.70000","263.50989","12.44173"
"52.80000","264.00998","12.49258"
"52.90000","264.50989","12.54432"
"53.00000","265.00986","12.60533"
"53.10000","265.50992","12.66747"
"53.20000","266.01007","12.73225"
"53.30000","266.51001","12.78624"
"53.40000","267.00986","12.84155"
"53.50000","267.50970","12.90344"
"53.60000","268.00995","12.96113"
"53.70000","268.50992","13.02792"
"53.80000","269.01001","13.08228"
"53.90000","269.50989","13.14606"
"54.00000","270.00992","13.20939"
"54.10000","270.50998","13.27919"
"54.20000","271.01007","13.34196"
"54.30000","271.50998","13.40529"
"54.40000","272.00974","13.46750"
"54.50000","272.50983","13.53052"
"54.60000","273.00995","13.59097"
"54.70000","273.50998","13.66057"
"54.80000","274.00995","13.72334"
"54.90000","274.50986","13.79960"
"55.00000","275.00983","13.86312"
"55.10000","275.50995","13.93266"
"55.20000","276.01007","13.99637"
"55.30000","276.50986","14.06341"
"55.40000","277.00989","14.14305"
"55.50000","277.50983","14.21754"
"55.60000","278.00998","14.28677"
"55.70000","278.51001","14.35726"
"55.80000","279.00995","14.42097"
"55.90000","279.50980","14.49854"
"56.00000","280.00992","14.56858"
"56.10000","280.50995","14.64477"
"56.20000","281.01004","14.70503"
"56.30000","281.50992","14.78730"
"56.40000","282.00980","14.85967"
"56.50000","282.50995","14.93768"
"56.60000","283.01010","15.01895"
"56.70000","283.51001","15.08404"
"56.80000","284.00980","15.16336"
"56.90000","284.50977","15.24432"
"57.00000","285.00998","15.31587"
"57.10000","285.51007","15.39218"
"57.20000","286.01004","15.47145"
"57.30000","286.50992","15.54902"
"57.40000","287.00983","15.62627"
"57.50000","287.50992","15.70879"
"57.60000","288.01001","15.79332"
"57.70000","288.50989","15.86362"
"57.80000","289.00983","15.95273"
"57.90000","289.50986","16.02478"
"58.00000","290.01001","16.11646"
"58.10000","290.51010","16.18612"
"58.20000","291.00998","16.28439"
"58.30000","291.50986","16.35625"
"58.40000","292.00977","16.45188"
"58.50000","292.50998","16.53409"
"58.60000","293.01001","16.61078"
"58.70000","293.50989","16.69594"
"58.80000","294.00983","16.78379"
"58.90000","294.50998","16.86920"
"59.00000","295.01007","16.95548"
"59.10000","295.51007","17.05431"
"59.20000","296.00986","17.12461"
"59.30000","296.50974","17.21748"
"59.40000","297.00983","17.30890"
"59.50000","297.51001","17.40127"
"59.60000","298.01004","17.49696"
"59.70000","298.50983","17.57616"
"59.80000","299.00986","17.67951"
"59.90000","299.50995","17.76115"
"60.00000","300.00998","17.86211"
"60.10000","300.50992","17.94746"
"60.20000","301.00980","18.02697"
"60.30000","301.50983","18.13871"
"60.40000","302.00992","18.22325"
"60.50000","302.51004","18.31818"
"60.60000","303.00995","18.41130"
"60.70000","303.50989","18.49671"
"60.80000","304.00986","18.60557"
"60.90000","304.50995","18.69882"
"61.00000","305.01001","18.79652"
"61.10000","305.50992","18.88851"
"61.20000","306.00983","18.98414"
"61.30000","306.50989","19.07914"
"61.40000","307.00998","19.17239"
"61.50000","307.51007","19.26620"
"61.60000","308.01001","19.36377"
"61.70000","308.50974","19.47897"
"61.80000","309.00977","19.57221"
"61.90000","309.51001","19.67430"
"62.00000","310.00998","19.77839"
"62.10000","310.50998","19.88588"
"62.20000","311.00989","19.97630"
"62.30000","311.50998","20.08867"
"62.40000","312.00998","20.18624"
"62.50000","312.51001","20.28263"
"62.60000","313.00980","20.39117"
"62.70000","313.50967","20.48931"
"62.80000","314.00986","20.59710"
"62.90000","314.51004","20.69988"
"63.00000","315.00998","20.79827"
"63.10000","315.50992","20.89854"
"63.20000","316.00986","21.01743"
"63.30000","316.50986","21.11444"
"63.40000","317.00998","21.22192"
"63.50000","317.50995","21.32664"
"63.60000","318.00980","21.41952"
"63.70000","318.50977","21.52932"
"63.80000","319.00995","21.63466"
"63.90000","319.51010","21.73801"
"64.00000","320.01004","21.84712"
"64.10000","320.50986","21.94996"
"64.20000","321.00980","22.05757"
"64.30000","321.50989","22.15558"
"64.40000","322.00989","22.25974"
"64.50000","322.50989","22.35969"
"64.60000","323.00980","22.46999"
"64.70000","323.50986","22.58074"
"64.80000","324.00995","22.67900"
"64.90000","324.51007","22.78924"
"65.00000","325.00986","22.88800"
"65.10000","325.50977","22.99003"
"65.20000","326.00983","23.09130"
"65.30000","326.50995","23.19941"
"65.40000","327.01001","23.29748"
"65.50000","327.50998","23.41192"
"65.60000","328.00980","23.49959"
"65.70000","328.50980","23.60437"
"65.80000","329.00995","23.71518"
"65.90000","329.51004","23.79896"
"66.00000","330.00980","23.90330"
"66.10000","330.50980","24.00012"
"66.20000","331.00986","24.09707"
"66.30000","331.51001","24.17921"
"66.40000","332.00998","24.26061"
"66.49600","332.48996","20.76121"
"66.50000","332.50995","18.17596"
"66.50400","332.52997","15.38353"
"66.50600","332.53992","13.98772"