File: data/class3/Specimen_RawData_15.csv
Time,Extension,Load
(s),(mm),(N)
"0.00000","-0.00006","-0.00389"
"0.20000","0.26866","0.01242"
"0.40000","0.53595","0.02809"
"0.60000","0.80268","0.05531"
"0.80000","1.06936","0.06879"
"1.00000","1.33592","0.09939"
"1.20000","1.60265","0.11733"
"1.40000","1.86932","0.13990"
"1.60000","2.13599","0.16361"
"1.80000","2.40272","0.17565"
"2.00000","2.66940","0.20813"
"2.20000","2.93596","0.23252"
"2.40000","3.20263","0.25027"
"2.60000","3.46936","0.27949"
"2.80000","3.73603","0.30213"
"3.00000","4.00271","0.31906"
"3.20000","4.26932","0.33699"
"3.40000","4.53605","0.36383"
"3.60000","4.80256","0.38340"
"3.80000","5.06934","0.41469"
"4.00000","5.33596","0.43444"
"4.20000","5.60269","0.45495"
"4.40000","5.86919","0.47533"
"4.60000","6.13604","0.49483"
"4.80000","6.40265","0.51333"
"5.00000","6.66938","0.52530"
"5.20000","6.93594","0.55001"
"5.40000","7.20273","0.56424"
"5.60000","7.46929","0.58795"
"5.80000","7.73591","0.61309"
"6.00000","8.00264","0.62576"
"6.20000","8.26942","0.64257"
"6.40000","8.53604","0.66313"
"6.60000","8.80260","0.67731"
"6.80000","9.06933","0.70208"
"7.00000","9.33595","0.72045"
"7.20000","9.60268","0.73807"
"7.40000","9.86935","0.74628"
"7.60000","10.13602","0.76930"
"7.80000","10.40252","0.78190"
"8.00000","10.66926","0.79764"
"8.20000","10.93599","0.82022"
"8.40000","11.20272","0.83157"
"8.60000","11.46933","0.84931"
"8.80000","11.73601","0.86750"
"9.00000","12.00268","0.87929"
"9.20000","12.26930","0.89126"
"9.40000","12.53603","0.91096"
"9.60000","12.80270","0.93014"
"9.80000","13.06932","0.93836"
"10.00000","13.33593","0.96319"
"10.20000","13.60266","0.97598"
"10.40000","13.86934","0.99053"
"10.60000","14.13601","1.00721"
"10.80000","14.40268","1.01781"
"11.00000","14.66936","1.03204"
"11.20000","14.93586","1.05311"
"11.40000","15.20276","1.05625"
"11.60000","15.46932","1.07468"
"11.80000","15.73594","1.08597"
"12.00000","16.00261","1.10021"
"12.20000","16.26940","1.10892"
"12.40000","16.53601","1.12441"
"12.60000","16.80257","1.13582"
"12.80000","17.06930","1.14893"
"13.00000","17.33609","1.16868"
"13.20000","17.60271","1.17539"
"13.40000","17.86921","1.18574"
"13.60000","18.13605","1.19847"
"13.80000","18.40267","1.21390"
"14.00000","18.66923","1.22004"
"14.20000","18.93602","1.24255"
"14.40000","19.20269","1.25171"
"14.60000","19.46931","1.26149"
"14.80000","19.73592","1.27278"
"15.00000","20.00259","1.29473"
"15.20000","20.26938","1.29429"
"15.40000","20.53600","1.31348"
"15.60000","20.80267","1.32044"
"15.80000","21.06929","1.33254"
"16.00000","21.33590","1.34514"
"16.20000","21.60263","1.35806"
"16.40000","21.86937","1.36916"
"16.60000","22.13604","1.37700"
"16.80000","22.40260","1.39192"
"17.00000","22.66939","1.40183"
"17.20000","22.93594","1.40735"
"17.40000","23.20267","1.41343"
"17.60000","23.46935","1.42491"
"17.80000","23.73602","1.43607"
"18.00000","24.00264","1.44761"
"18.20000","24.26931","1.46360"
"18.40000","24.53593","1.47758"
"18.60000","24.80272","1.48078"
"18.80000","25.06933","1.49163"
"19.00000","25.33601","1.49639"
"19.20000","25.60268","1.50680"
"19.40000","25.86924","1.51627"
"19.60000","26.13602","1.52499"
"19.80000","26.40275","1.54110"
"20.00000","26.66926","1.54179"
"20.20000","26.93593","1.55898"
"20.40000","27.20272","1.55879"
"20.60000","27.46928","1.57352"
"20.80000","27.73595","1.57666"
"21.00000","28.00268","1.58845"
"21.20000","28.26936","1.59503"
"21.40000","28.53597","1.60325"
"21.60000","28.80264","1.61529"
"21.80000","29.06932","1.62394"
"22.00000","29.33605","1.62451"
"22.20000","29.60261","1.63698"
"22.40000","29.86928","1.64727"
"22.60000","30.13601","1.65467"
"22.80000","30.40263","1.66589"
"23.00000","30.66930","1.67354"
"23.20000","30.93603","1.68107"
"23.40000","31.20265","1.68941"
"23.60000","31.46932","1.70264"
"23.80000","31.73599","1.70540"
"24.00000","32.00272","1.70954"
"24.20000","32.26928","1.71405"
"24.40000","32.53601","1.73318"
"24.60000","32.80268","1.73268"
"24.80000","33.06931","1.73857"
"25.00000","33.33598","1.75650"
"25.20000","33.60260","1.75820"
"25.40000","33.86938","1.76265"
"25.60000","34.13600","1.77093"
"25.80000","34.40273","1.77607"
"26.00000","34.66934","1.77927"
"26.20000","34.93590","1.79225"
"26.40000","35.20263","1.79639"
"26.60000","35.46936","1.80893"
"26.80000","35.73603","1.80861"
"27.00000","36.00260","1.82197"
"27.20000","36.26933","1.81896"
"27.40000","36.53595","1.83251"
"27.60000","36.80262","1.84304"
"27.80000","37.06935","1.84574"
"28.00000","37.33608","1.85866"
"28.20000","37.60264","1.85953"
"28.40000","37.86926","1.86994"
"28.60000","38.13598","1.86825"
"28.80000","38.40271","1.88217"
"29.00000","38.66939","1.89628"
"29.20000","38.93595","1.89509"
"29.40000","39.20261","1.89973"
"29.60000","39.46930","1.91070"
"29.80000","39.73603","1.91528"
"30.00000","40.00275","1.91854"
"30.20000","40.26937","1.92845"
"30.40000","40.53587","1.93572"
"30.60000","40.80266","1.93597"
"30.80000","41.06934","1.95623"
"31.00000","41.33601","1.95259"
"31.20000","41.60262","1.95736"
"31.40000","41.86941","1.96350"
"31.60000","42.13603","1.97222"
"31.80000","42.40259","1.98313"
"32.00000","42.66937","1.98332"
"32.20000","42.93599","1.98326"
"32.40000","43.20266","1.99511"
"32.60000","43.46939","2.00677"
"32.80000","43.73595","2.00276"
"33.00000","44.00257","2.01342"
"33.20000","44.26936","2.02063"
"33.40000","44.53598","2.02025"
"33.60000","44.80265","2.03405"
"33.80000","45.06932","2.03668"
"34.00000","45.33605","2.04389"
"34.20000","45.60261","2.05857"
"34.40000","45.86934","2.06014"
"34.60000","46.13601","2.05374"
"34.80000","46.40274","2.07330"
"35.00000","46.66936","2.07067"
"35.20000","46.93592","2.08020"
"35.40000","47.20265","2.09042"
"35.60000","47.46938","2.08478"
"35.80000","47.73594","2.09199"
"36.00000","48.00267","2.09908"
"36.20000","48.26940","2.10096"
"36.40000","48.53596","2.10980"
"36.60000","48.80264","2.11764"
"36.80000","49.06936","2.12153"
"37.00000","49.33604","2.12403"
"37.20000","49.60254","2.13156"
"37.40000","49.86932","2.13689"
"37.60000","50.13600","2.14128"
"37.80000","50.40262","2.15664"
"38.00000","50.66929","2.15984"
"38.20000","50.93608","2.16392"
"38.40000","51.20269","2.16241"
"38.60000","51.46925","2.16849"
"38.80000","51.73598","2.17771"
"39.00000","52.00271","2.18166"
"39.20000","52.26933","2.18267"
"39.40000","52.53600","2.19333"
"39.60000","52.80267","2.19891"
"39.80000","53.06929","2.20618"
"40.00000","53.33597","2.20273"
"40.20000","53.60264","2.21496"
"40.40000","53.86937","2.21697"
"40.60000","54.13599","2.22424"
"40.80000","54.40266","2.22756"
"41.00000","54.66922","2.23691"
"41.20000","54.93601","2.24374"
"41.40000","55.20268","2.24061"
"41.60000","55.46930","2.25133"
"41.80000","55.73597","2.25528"
"42.00000","56.00259","2.25152"
"42.20000","56.26937","2.26318"
"42.40000","56.53605","2.26419"
"42.60000","56.80267","2.28275"
"42.80000","57.06928","2.27974"
"43.00000","57.33601","2.29648"
"43.20000","57.60257","2.28732"
"43.40000","57.86936","2.28507"
"43.60000","58.13603","2.29347"
"43.80000","58.40270","2.30720"
"44.00000","58.66926","2.31147"
"44.20000","58.93599","2.31617"
"44.40000","59.20267","2.32413"
"44.60000","59.46929","2.32495"
"44.80000","59.73602","2.31962"
"45.00000","60.00263","2.33611"
"45.20000","60.26931","2.34132"
"45.40000","60.53586","2.34244"
"45.60000","60.80265","2.35116"
"45.80000","61.06932","2.34966"
"46.00000","61.33599","2.35630"
"46.20000","61.60261","2.36082"
"46.40000","61.86934","2.37229"
"46.60000","62.13602","2.37041"
"46.80000","62.40269","2.38433"
"47.00000","62.66931","2.37925"
"47.20000","62.93603","2.38088"
"47.40000","63.20265","2.39763"
"47.60000","63.46927","2.39543"
"47.80000","63.73600","2.40685"
"48.00000","64.00261","2.39713"
"48.20000","64.26929","2.41500"
"48.40000","64.53607","2.41437"
"48.60000","64.80264","2.42190"
"48.80000","65.06925","2.42447"
"49.00000","65.33604","2.43707"
"49.20000","65.60265","2.43958"
"49.40000","65.86932","2.43387"
"49.60000","66.13600","2.43939"
"49.80000","66.40273","2.44974"
"50.00000","66.66924","2.45783"
"50.20000","66.93602","2.46899"
"50.40000","67.20270","2.46730"
"50.60000","67.46937","2.47300"
"50.80000","67.73598","2.47952"
"51.00000","68.00266","2.47733"
"51.20000","68.26933","2.48880"
"51.40000","68.53600","2.48416"
"51.60000","68.80267","2.49056"
"51.80000","69.06935","2.49457"
"52.00000","69.33603","2.49796"
"52.20000","69.60252","2.50906"
"52.40000","69.86937","2.50699"
"52.60000","70.13605","2.51389"
"52.80000","70.40266","2.51677"
"53.00000","70.66922","2.52499"
"53.20000","70.93606","2.52693"
"53.40000","71.20263","2.52737"
"53.60000","71.46930","2.54123"
"53.80000","71.73597","2.54405"
"54.00000","72.00276","2.54499"
"54.20000","72.26937","2.54568"
"54.40000","72.53593","2.55421"
"54.60000","72.80267","2.56205"
"54.80000","73.06940","2.56299"
"55.00000","73.33607","2.56594"
"55.20000","73.60263","2.57722"
"55.40000","73.86930","2.58180"
"55.60000","74.13593","2.58744"
"55.80000","74.40276","2.58368"
"56.00000","74.66933","2.59334"
"56.20000","74.93600","2.59892"
"56.40000","75.20267","2.60356"
"56.60000","75.46935","2.62024"
"56.80000","75.73595","2.60864"
"57.00000","76.00269","2.61917"
"57.20000","76.26936","2.62024"
"57.40000","76.53603","2.62983"
"57.60000","76.80265","2.63284"
"57.80000","77.06933","2.63504"
"58.00000","77.33600","2.63905"
"58.20000","77.60267","2.64018"
"58.40000","77.86935","2.65210"
"58.60000","78.13602","2.65523"
"58.80000","78.40264","2.66018"
"59.00000","78.66920","2.66514"
"59.20000","78.93604","2.66514"
"59.40000","79.20259","2.66990"
"59.60000","79.46927","2.67191"
"59.80000","79.73593","2.67624"
"60.00000","80.00273","2.67693"
"60.20000","80.26929","2.68163"
"60.40000","80.53590","2.68633"
"60.60000","80.80264","2.70471"
"60.80000","81.06937","2.70784"
"61.00000","81.33598","2.70170"
"61.20000","81.60260","2.70546"
"61.40000","81.86933","2.71330"
"61.60000","82.13606","2.71599"
"61.80000","82.40268","2.71844"
"62.00000","82.66935","2.72383"
"62.20000","82.93603","2.73468"
"62.40000","83.20258","2.73274"
"62.60000","83.46931","2.73675"
"62.80000","83.73598","2.74239"
"63.00000","84.00272","2.74703"
"63.20000","84.26928","2.74603"
"63.40000","84.53601","2.75243"
"63.60000","84.80263","2.75870"
"63.80000","85.06930","2.76434"
"64.00000","85.33597","2.76973"
"64.20000","85.60270","2.77375"
"64.40000","85.86932","2.77068"
"64.60000","86.13599","2.78478"
"64.80000","86.40267","2.78892"
"65.00000","86.66940","2.78779"
"65.20000","86.93601","2.79664"
"65.40000","87.20263","2.80322"
"65.60000","87.46930","2.80272"
"65.80000","87.73592","2.80485"
"66.00000","88.00269","2.80742"
"66.20000","88.26933","2.81275"
"66.40000","88.53600","2.80855"
"66.60000","88.80261","2.82523"
"66.80000","89.06939","2.82824"
"67.00000","89.33590","2.83031"
"67.20000","89.60268","2.83878"
"67.40000","89.86931","2.83664"
"67.60000","90.13604","2.84147"
"67.80000","90.40266","2.84718"
"68.00000","90.66926","2.85157"
"68.20000","90.93599","2.85590"
"68.40000","91.20272","2.86304"
"68.60000","91.46923","2.86555"
"68.80000","91.73602","2.87038"
"69.00000","92.00269","2.87320"
"69.20000","92.26926","2.87929"
"69.40000","92.53598","2.87797"
"69.60000","92.80265","2.88474"
"69.80000","93.06938","2.88900"
"70.00000","93.33589","2.89684"
"70.20000","93.60268","2.89985"
"70.40000","93.86929","2.90531"
"70.60000","94.13602","2.90675"
"70.80000","94.40264","2.91271"
"71.00000","94.66937","2.91798"
"71.20000","94.93597","2.92287"
"71.40000","95.20266","2.92475"
"71.60000","95.46928","2.92839"
"71.80000","95.73605","2.92707"
"72.00000","96.00268","2.93629"
"72.20000","96.26929","2.94206"
"72.40000","96.53590","2.94500"
"72.60000","96.80257","2.95303"
"72.80000","97.06937","2.95924"
"73.00000","97.33594","2.96118"
"73.20000","97.60267","2.96758"
"73.40000","97.86934","2.96494"
"73.60000","98.13600","2.97310"
"73.80000","98.40262","2.97272"
"74.00000","98.66924","2.98589"
"74.20000","98.93597","2.98733"
"74.40000","99.20270","2.99636"
"74.60000","99.46927","2.99329"
"74.80000","99.73593","3.00683"
"75.00000","100.00266","3.00489"
"75.20000","100.26933","3.00978"
"75.40000","100.53601","3.01486"
"75.60000","100.80269","3.01837"
"75.80000","101.06929","3.01781"
"76.00000","101.33586","3.02985"
"76.20000","101.60265","3.03737"
"76.40000","101.86932","3.03605"
"76.60000","102.13605","3.04502"
"76.80000","102.40267","3.04138"
"77.00000","102.66928","3.04678"
"77.20000","102.93595","3.05781"
"77.40000","103.20268","3.05844"
"77.60000","103.46941","3.06797"
"77.80000","103.73604","3.06904"
"78.00000","104.00266","3.07462"
"78.20000","104.26927","3.07826"
"78.40000","104.53600","3.08609"
"78.60000","104.80267","3.08810"
"78.80000","105.06940","3.08729"
"79.00000","105.33597","3.09644"
"79.20000","105.60270","3.10572"
"79.40000","105.86931","3.11074"
"79.60000","106.13598","3.11231"
"79.80000","106.40265","3.10974"
"80.00000","106.66927","3.12422"
"80.20000","106.93600","3.12635"
"80.40000","107.20261","3.12729"
"80.60000","107.46935","3.13363"
"80.80000","107.73602","3.13538"
"81.00000","108.00269","3.14429"
"81.20000","108.26937","3.14629"
"81.40000","108.53593","3.14567"
"81.60000","108.80265","3.15463"
"81.80000","109.06938","3.15601"
"82.00000","109.33595","3.16197"
"82.20000","109.60262","3.16730"
"82.40000","109.86930","3.16912"
"82.60000","110.13602","3.18172"
"82.80000","110.40259","3.18354"
"83.00000","110.66926","3.18737"
"83.20000","110.93594","3.19922"
"83.40000","111.20267","3.19715"
"83.60000","111.46933","3.19803"
"83.80000","111.73602","3.20825"
"84.00000","112.00268","3.20411"
"84.20000","112.26936","3.21671"
"84.40000","112.53596","3.22261"
"84.60000","112.80270","3.21847"
"84.80000","113.06931","3.21972"
"85.00000","113.33588","3.23371"
"85.20000","113.60261","3.23465"
"85.40000","113.86939","3.23565"
"85.60000","114.13596","3.25459"
"85.80000","114.40262","3.25892"
"86.00000","114.66935","3.25948"
"86.20000","114.93597","3.26149"
"86.40000","115.20259","3.26933"
"86.60000","115.46932","3.27673"
"86.80000","115.73599","3.27779"
"87.00000","116.00267","3.28406"
"87.20000","116.26929","3.28826"
"87.40000","116.53596","3.29077"
"87.60000","116.80269","3.29265"
"87.80000","117.06941","3.30256"
"88.00000","117.33598","3.30005"
"88.20000","117.60265","3.30770"
"88.40000","117.86922","3.31391"
"88.60000","118.13599","3.31711"
"88.80000","118.40262","3.31893"
"89.00000","118.66940","3.32996"
"89.20000","118.93590","3.33467"
"89.40000","119.20258","3.34088"
"89.60000","119.46925","3.34558"
"89.80000","119.73598","3.34495"
"90.00000","120.00271","3.35417"
"90.20000","120.26939","3.35436"
"90.40000","120.53594","3.35812"
"90.60000","120.80261","3.37399"
"90.80000","121.06929","3.37373"
"91.00000","121.33607","3.37373"
"91.20000","121.60264","3.37624"
"91.40000","121.86931","3.37994"
"91.60000","122.13593","3.37806"
"91.80000","122.40261","3.39543"
"92.00000","122.66938","3.39029"
"92.20000","122.93600","3.40258"
"92.40000","123.20262","3.40170"
"92.60000","123.46935","3.40841"
"92.80000","123.73603","3.41161"
"93.00000","124.00269","3.41625"
"93.20000","124.26932","3.41625"
"93.40000","124.53593","3.42578"
"93.60000","124.80267","3.42465"
"93.80000","125.06938","3.43255"
"94.00000","125.33595","3.44077"
"94.20000","125.60262","3.43337"
"94.40000","125.86935","3.44873"
"94.60000","126.13602","3.45293"
"94.80000","126.40263","3.46265"
"95.00000","126.66936","3.45983"
"95.20000","126.93593","3.46021"
"95.40000","127.20260","3.46930"
"95.60000","127.46933","3.48103"
"95.80000","127.73600","3.47394"
"96.00000","128.00262","3.47219"
"96.20000","128.26935","3.47952"
"96.40000","128.53596","3.48040"
"96.60000","128.80264","3.49796"
"96.80000","129.06932","3.49012"
"97.00000","129.33598","3.50141"
"97.20000","129.60272","3.49664"
"97.40000","129.86928","3.51100"
"97.60000","130.13602","3.51257"
"97.80000","130.40268","3.51069"
"98.00000","130.66930","3.51113"
"98.20000","130.93602","3.52041"
"98.40000","131.20264","3.52317"
"98.60000","131.46927","3.52900"
"98.80000","131.73599","3.52743"
"99.00000","132.00267","3.53019"
"99.20000","132.26933","3.54599"
"99.40000","132.53595","3.54787"
"99.60000","132.80264","3.55113"
"99.80000","133.06931","3.55678"
"100.00000","133.33604","3.55402"
"100.20000","133.60271","3.55822"
"100.40000","133.86938","3.56386"
"100.60000","134.13599","3.56738"
"100.80000","134.40256","3.57095"
"101.00000","134.66930","3.58424"
"101.20000","134.93602","3.57948"
"101.40000","135.20270","3.59146"
"101.60000","135.46930","3.59045"
"101.80000","135.73593","3.59409"
"102.00000","136.00259","3.60368"
"102.20000","136.26938","3.59848"
"102.40000","136.53595","3.60556"
"102.60000","136.80273","3.61359"
"102.80000","137.06929","3.61535"
"103.00000","137.33601","3.62187"
"103.20000","137.60265","3.62569"
"103.40000","137.86937","3.62670"
"103.60000","138.13605","3.64256"
"103.80000","138.40271","3.63385"
"104.00000","138.66933","3.63585"
"104.20000","138.93594","3.63541"
"104.40000","139.20262","3.64281"
"104.60000","139.46936","3.65341"
"104.80000","139.73596","3.65247"
"105.00000","140.00264","3.65554"
"105.20000","140.26930","3.66194"
"105.40000","140.53593","3.66294"
"105.60000","140.80267","3.66802"
"105.80000","141.06927","3.66909"
"106.00000","141.33601","3.67630"
"106.20000","141.60268","3.67128"
"106.40000","141.86935","3.67950"
"106.60000","142.13602","3.67975"
"106.80000","142.40265","3.69511"
"107.00000","142.66933","3.68922"
"107.20000","142.93605","3.69229"
"107.40000","143.20267","3.69793"
"107.60000","143.46927","3.70314"
"107.80000","143.73601","3.70910"
"108.00000","144.00267","3.70991"
"108.20000","144.26930","3.71047"
"108.40000","144.53598","3.71831"
"108.60000","144.80270","3.72095"
"108.80000","145.06926","3.72045"
"109.00000","145.33594","3.73098"
"109.20000","145.60262","3.73073"
"109.40000","145.86938","3.75167"
"109.60000","146.13596","3.74973"
"109.80000","146.40263","3.74528"
"110.00000","146.66930","3.75324"
"110.20000","146.93604","3.75123"
"110.40000","147.20265","3.76591"
"110.60000","147.46933","3.76534"
"110.80000","147.73605","3.77086"
"111.00000","148.00255","3.77488"
"111.20000","148.26929","3.77720"
"111.40000","148.53601","3.77287"
"111.60000","148.80269","3.78704"
"111.80000","149.06931","3.79143"
"112.00000","149.33598","3.78466"
"112.20000","149.60258","3.79193"
"112.40000","149.86922","3.79350"
"112.60000","150.13599","3.80165"
"112.80000","150.40279","3.80316"
"113.00000","150.66917","3.80861"
"113.20000","150.93602","3.81037"
"113.40000","151.20264","3.81143"
"113.60000","151.46930","3.81288"
"113.80000","151.73604","3.82241"
"114.00000","152.00266","3.82485"
"114.20000","152.26939","3.82987"
"114.40000","152.53589","3.83539"
"114.60000","152.80261","3.83639"
"114.80000","153.06929","3.83269"
"115.00000","153.33601","3.83589"
"115.20000","153.60265","3.85144"
"115.40000","153.86926","3.84574"
"115.60000","154.13593","3.84310"
"115.80000","154.40266","3.85270"
"116.00000","154.66933","3.85746"
"116.20000","154.93607","3.86285"
"116.40000","155.20268","3.86586"
"116.60000","155.46936","3.87458"
"116.80000","155.73602","3.87514"
"117.00000","156.00264","3.87151"
"117.20000","156.26938","3.87859"
"117.40000","156.53598","3.88675"
"117.60000","156.80267","3.88618"
"117.80000","157.06921","3.89421"
"118.00000","157.33601","3.89458"
"118.20000","157.60266","3.89647"
"118.40000","157.86934","3.89866"
"118.60000","158.13591","3.90211"
"118.80000","158.40263","3.90913"
"119.00000","158.66943","3.91446"
"119.20000","158.93593","3.91948"
"119.40000","159.20261","3.91810"
"119.60000","159.46939","3.91308"
"119.80000","159.73596","3.92186"
"120.00000","160.00264","3.92500"
"120.20000","160.26930","3.92857"
"120.40000","160.53596","3.93296"
"120.60000","160.80258","3.93340"
"120.80000","161.06932","3.93647"
"121.00000","161.33600","3.93603"
"121.20000","161.60255","3.94381"
"121.40000","161.86929","3.94237"
"121.60000","162.13596","3.94751"
"121.80000","162.40263","3.95347"
"122.00000","162.66925","3.95503"
"122.20000","162.93602","3.96043"
"122.40000","163.20265","3.96275"
"122.60000","163.46925","3.96670"
"122.80000","163.73599","3.96344"
"123.00000","164.00272","3.97460"
"123.20000","164.26930","3.97084"
"123.40000","164.53595","3.96877"
"123.60000","164.80269","3.97560"
"123.80000","165.06931","3.97799"
"124.00000","165.33598","3.98532"
"124.20000","165.60266","3.98106"
"124.40000","165.86938","3.99153"
"124.60000","166.13582","3.98764"
"124.80000","166.40262","3.98532"
"125.00000","166.66922","3.98444"
"125.20000","166.93600","3.99548"
"125.40000","167.20264","3.99548"
"125.60000","167.46931","4.00338"
"125.80000","167.73604","4.00206"
"126.00000","168.00261","4.00514"
"126.20000","168.26933","4.00257"
"126.40000","168.53613","4.01015"
"126.60000","168.80267","4.01548"
"126.80000","169.06924","4.01248"
"127.00000","169.33598","4.01730"
"127.20000","169.60271","4.02157"
"127.40000","169.86931","4.02458"
"127.60000","170.13597","4.02144"
"127.80000","170.40266","4.03104"
"128.00000","170.66917","4.03499"
"128.20000","170.93590","4.02445"
"128.40000","171.20264","4.04333"
"128.60000","171.46942","4.04439"
"128.80000","171.73604","4.03749"
"129.00000","172.00259","4.04753"
"129.20000","172.26932","4.05154"
"129.40000","172.53600","4.05769"
"129.60000","172.80267","4.04609"
"129.80000","173.06940","4.05618"
"130.00000","173.33606","4.05932"
"130.20000","173.60263","4.05179"
"130.40000","173.86929","4.06302"
"130.60000","174.13599","4.06421"
"130.80000","174.40265","4.06440"
"131.00000","174.66927","4.06772"
"131.20000","174.93599","4.07079"
"131.40000","175.20256","4.08070"
"131.60000","175.46930","4.07054"
"131.80000","175.73596","4.07788"
"132.00000","176.00262","4.07462"
"132.20000","176.26924","4.07612"
"132.40000","176.53598","4.08578"
"132.60000","176.80270","4.08616"
"132.80000","177.06927","4.08333"
"133.00000","177.33601","4.08728"
"133.20000","177.60274","4.09205"
"133.40000","177.86935","4.09130"
"133.60000","178.13594","4.09500"
"133.80000","178.40263","4.09970"
"134.00000","178.66936","4.10070"
"134.20000","178.93591","4.10904"
"134.40000","179.20265","4.10384"
"134.60000","179.46931","4.11249"
"134.80000","179.73589","4.10572"
"135.00000","180.00261","4.11939"
"135.20000","180.26930","4.11162"
"135.40000","180.53596","4.11757"
"135.60000","180.80264","4.11268"
"135.80000","181.06924","4.11864"
"136.00000","181.33597","4.12453"
"136.20000","181.60262","4.12572"
"136.40000","181.86928","4.12761"
"136.60000","182.13606","4.13927"
"136.80000","182.40274","4.14391"
"137.00000","182.66924","4.13262"
"137.20000","182.93604","4.14178"
"137.40000","183.20270","4.14667"
"137.60000","183.46938","4.14128"
"137.80000","183.73599","4.13864"
"138.00000","184.00267","4.15156"
"138.20000","184.26918","4.14529"
"138.40000","184.53595","4.15156"
"138.60000","184.80269","4.15244"
"138.80000","185.06935","4.15915"
"139.00000","185.33597","4.15783"
"139.20000","185.60258","4.15626"
"139.40000","185.86932","4.15783"
"139.60000","186.13599","4.15727"
"139.80000","186.40273","4.15720"
"140.00000","186.66939","4.16272"
"140.20000","186.93596","4.17357"
"140.40000","187.20264","4.16717"
"140.60000","187.46928","4.16598"
"140.80000","187.73602","4.17846"
"141.00000","188.00264","4.17746"
"141.20000","188.26932","4.17620"
"141.40000","188.53600","4.17890"
"141.60000","188.80261","4.17671"
"141.80000","189.06929","4.17439"
"142.00000","189.33601","4.17664"
"142.20000","189.60275","4.17934"
"142.40000","189.86937","4.17138"
"142.60000","190.13591","4.18285"
"142.80000","190.40265","4.19044"
"143.00000","190.66927","4.18141"
"143.20000","190.93594","4.18762"
"143.40000","191.20273","4.18781"
"143.60000","191.46935","4.19677"
"143.80000","191.73586","4.19383"
"144.00000","192.00269","4.19583"
"144.20000","192.26932","4.19583"
"144.40000","192.53596","4.19364"
"144.60000","192.80267","4.19916"
"144.80000","193.06934","4.19558"
"145.00000","193.33594","4.19589"
"145.20000","193.60257","4.19458"
"145.40000","193.86934","4.20129"
"145.60000","194.13606","4.20079"
"145.80000","194.40269","4.19477"
"146.00000","194.66937","4.20373"
"146.20000","194.93597","4.19464"
"146.40000","195.20261","4.20398"
"146.60000","195.46925","4.20342"
"146.80000","195.73599","4.21013"
"147.00000","196.00264","4.20819"
"147.20000","196.26923","4.22173"
"147.40000","196.53596","4.21025"
"147.60000","196.80263","4.21257"
"147.80000","197.06932","4.21025"
"148.00000","197.33598","4.21590"
"148.20000","197.60266","4.22612"
"148.40000","197.86928","4.21295"
"148.60000","198.13596","4.21784"
"148.80000","198.40263","4.22148"
"149.00000","198.66942","4.21170"
"149.20000","198.93596","4.21508"
"149.40000","199.20265","4.21051"
"149.60000","199.46939","4.21038"
"149.80000","199.73593","4.22305"
"150.00000","200.00266","4.21928"
"150.20000","200.26938","4.21082"
"150.40000","200.53601","4.20681"
"150.60000","200.80238","4.21145"
"150.80000","201.06929","4.22173"
"151.00000","201.33598","4.22198"
"151.20000","201.60271","4.21057"
"151.40000","201.86931","4.20956"
"151.60000","202.13605","4.20066"
"151.80000","202.40262","4.20223"
"152.00000","202.66936","4.20085"
"152.20000","202.93594","4.20160"
"152.40000","203.20282","4.19790"
"152.60000","203.46936","4.19539"
"152.80000","203.73598","4.20223"
"153.00000","204.00266","4.19426"
"153.20000","204.26927","4.20423"
"153.40000","204.53606","4.19314"
"153.60000","204.80254","4.19100"
"153.80000","205.06934","4.19119"
"154.00000","205.33585","4.19583"
"154.20000","205.60265","4.19006"
"154.40000","205.86931","4.18799"
"154.60000","206.13597","4.19188"
"154.80000","206.40266","4.18624"
"155.00000","206.66939","4.19100"
"155.20000","206.93600","4.18254"
"155.40000","207.20258","4.18172"
"155.60000","207.46935","4.17809"
"155.80000","207.73602","4.16743"
"156.00000","208.00262","4.16586"
"156.20000","208.26930","4.15908"
"156.40000","208.53609","4.15789"
"156.60000","208.80270","4.15570"
"156.80000","209.06932","4.15225"
"157.00000","209.33600","4.15796"
"157.20000","209.60268","4.14360"
"157.40000","209.86913","4.14435"
"157.60000","210.13597","4.15074"
"157.80000","210.40263","4.13977"
"158.00000","210.66933","4.12880"
"158.20000","210.93587","4.12930"
"158.40000","211.20273","4.12265"
"158.60000","211.46933","4.12259"
"158.80000","211.73596","4.11801"
"159.00000","212.00262","4.11312"
"159.20000","212.26942","4.10491"
"159.40000","212.53609","4.10102"
"159.60000","212.80258","4.09462"
"159.80000","213.06938","4.09751"
"160.00000","213.33600","4.08321"
"160.20000","213.60266","4.07506"
"160.40000","213.86935","4.07688"
"160.60000","214.13608","4.06973"
"160.80000","214.40253","4.03543"
"160.93600","214.58403","0.02540"
"161.13600","214.85063","0.00928"
"161.33600","215.11726","0.01342"
"161.53600","215.38405","0.00571"
"161.73600","215.65073","0.01662"
"161.93600","215.91731","0.00107"
"162.13600","216.18399","0.01298"
"162.33600","216.45068","0.00828"
"162.53600","216.71724","0.00696"
"162.73600","216.98398","0.00891"
"162.93600","217.25070","0.00690"
"163.13600","217.51738","0.00922"
"163.22800","217.63998","0.00947"