File: data/class3/Specimen_RawData_11.csv
Time,Extension,Load
(s),(mm),(N)
"0.00000","0.00000","-0.01442"
"0.10000","0.12982","-0.00332"
"0.20000","0.26877","0.00295"
"0.30000","0.40267","0.00144"
"0.40000","0.53601","0.00483"
"0.50000","0.66940","0.00753"
"0.60000","0.80274","0.01424"
"0.70000","0.93608","0.01743"
"0.80000","1.06930","0.01988"
"0.90000","1.20264","0.03016"
"1.00000","1.33609","0.04352"
"1.10000","1.46937","0.04904"
"1.20000","1.60270","0.05167"
"1.30000","1.73610","0.06177"
"1.40000","1.86932","0.06553"
"1.50000","2.00277","0.07306"
"1.60000","2.13605","0.09087"
"1.70000","2.26933","0.08409"
"1.80000","2.40272","0.09695"
"1.90000","2.53600","0.10284"
"2.00000","2.66934","0.11056"
"2.10000","2.80273","0.13000"
"2.20000","2.93601","0.13520"
"2.30000","3.06941","0.13815"
"2.40000","3.20274","0.15414"
"2.50000","3.33608","0.15244"
"2.60000","3.46930","0.16887"
"2.70000","3.60275","0.17308"
"2.80000","3.73603","0.17991"
"2.90000","3.86937","0.19045"
"3.00000","4.00271","0.20499"
"3.10000","4.13593","0.21402"
"3.20000","4.26938","0.21691"
"3.30000","4.40272","0.22537"
"3.40000","4.53600","0.23622"
"3.50000","4.66939","0.23647"
"3.60000","4.80273","0.24663"
"3.70000","4.93601","0.26494"
"3.80000","5.06934","0.27077"
"3.90000","5.20262","0.27454"
"4.00000","5.33607","0.28683"
"4.10000","5.46941","0.30050"
"4.20000","5.60275","0.30501"
"4.30000","5.73597","0.31178"
"4.40000","5.86942","0.31492"
"4.50000","6.00270","0.32934"
"4.60000","6.13604","0.33637"
"4.70000","6.26937","0.34747"
"4.80000","6.40265","0.35681"
"4.90000","6.53610","0.35900"
"5.00000","6.66938","0.36621"
"5.10000","6.80266","0.38177"
"5.20000","6.93600","0.38126"
"5.30000","7.06939","0.39788"
"5.40000","7.20273","0.39907"
"5.50000","7.33601","0.40660"
"5.60000","7.46935","0.41205"
"5.70000","7.60274","0.42146"
"5.80000","7.73608","0.43099"
"5.90000","7.86941","0.43432"
"6.00000","8.00264","0.45219"
"6.10000","8.13603","0.45582"
"6.20000","8.26931","0.46235"
"6.30000","8.40270","0.46924"
"6.40000","8.53604","0.47087"
"6.50000","8.66926","0.47451"
"6.60000","8.80283","0.48737"
"6.70000","8.93599","0.49934"
"6.80000","9.06927","0.50154"
"6.90000","9.20272","0.51721"
"7.00000","9.33600","0.51326"
"7.10000","9.46940","0.52085"
"7.20000","9.60273","0.53954"
"7.30000","9.73601","0.53841"
"7.40000","9.86941","0.54192"
"7.50000","10.00274","0.55145"
"7.60000","10.13602","0.56312"
"7.70000","10.26936","0.56048"
"7.80000","10.40275","0.57434"
"7.90000","10.53603","0.57566"
"8.00000","10.66937","0.58669"
"8.10000","10.80276","0.59679"
"8.20000","10.93593","0.60940"
"8.30000","11.06944","0.60557"
"8.40000","11.20272","0.61429"
"8.50000","11.33599","0.61366"
"8.60000","11.46939","0.63078"
"8.70000","11.60273","0.63793"
"8.80000","11.73612","0.64200"
"8.90000","11.86934","0.65147"
"9.00000","12.00262","0.65668"
"9.10000","12.13607","0.66351"
"9.20000","12.26941","0.65900"
"9.30000","12.40263","0.66345"
"9.40000","12.53597","0.67956"
"9.50000","12.66942","0.68910"
"9.60000","12.80276","0.69806"
"9.70000","12.93604","0.69311"
"9.80000","13.06943","0.70728"
"9.90000","13.20260","0.70973"
"10.00000","13.33605","0.71913"
"10.10000","13.46944","0.71895"
"10.20000","13.60266","0.72804"
"10.30000","13.73606","0.73769"
"10.40000","13.86934","0.74365"
"10.50000","14.00273","0.74578"
"10.60000","14.13601","0.75005"
"10.70000","14.26929","0.75619"
"10.80000","14.40280","0.76259"
"10.90000","14.53602","0.76560"
"11.00000","14.66936","0.77513"
"11.10000","14.80269","0.78479"
"11.20000","14.93597","0.79131"
"11.30000","15.06937","0.79369"
"11.40000","15.20276","0.78598"
"11.50000","15.33610","0.80253"
"11.60000","15.46932","0.81276"
"11.70000","15.60283","0.81545"
"11.80000","15.73610","0.82285"
"11.90000","15.86944","0.81696"
"12.00000","16.00272","0.83050"
"12.10000","16.13600","0.84191"
"12.20000","16.26940","0.84373"
"12.30000","16.40273","0.85452"
"12.40000","16.53596","0.85690"
"12.50000","16.66946","0.86016"
"12.60000","16.80280","0.86574"
"12.70000","16.93602","0.86236"
"12.80000","17.06936","0.87603"
"12.90000","17.20275","0.88644"
"13.00000","17.33609","0.88763"
"13.10000","17.46937","0.89484"
"13.20000","17.60271","0.89635"
"13.30000","17.73593","0.89653"
"13.40000","17.86943","0.91083"
"13.50000","18.00277","0.91334"
"13.60000","18.13599","0.91685"
"13.70000","18.26939","0.91961"
"13.80000","18.40273","0.93290"
"13.90000","18.53606","0.92864"
"14.00000","18.66940","0.93635"
"14.10000","18.80268","0.94858"
"14.20000","18.93602","0.95542"
"14.30000","19.06941","0.95278"
"14.40000","19.20263","0.96012"
"14.50000","19.33597","0.96965"
"14.60000","19.46936","0.97047"
"14.70000","19.60270","0.97166"
"14.80000","19.73603","0.97736"
"14.90000","19.86937","0.98928"
"15.00000","20.00265","0.99367"
"15.10000","20.13610","0.99524"
"15.20000","20.26933","0.99831"
"15.30000","20.40266","1.00928"
"15.40000","20.53600","1.00113"
"15.50000","20.66939","1.01580"
"15.60000","20.80273","1.01593"
"15.70000","20.93601","1.02301"
"15.80000","21.06929","1.03035"
"15.90000","21.20280","1.03574"
"16.00000","21.33602","1.04960"
"16.10000","21.46935","1.04528"
"16.20000","21.60269","1.04597"
"16.30000","21.73603","1.04967"
"16.40000","21.86937","1.06070"
"16.50000","22.00265","1.05713"
"16.60000","22.13604","1.07023"
"16.70000","22.26926","1.06885"
"16.80000","22.40277","1.07738"
"16.90000","22.53599","1.07851"
"17.00000","22.66939","1.08372"
"17.10000","22.80272","1.09488"
"17.20000","22.93600","1.08522"
"17.30000","23.06940","1.10322"
"17.40000","23.20279","1.10272"
"17.50000","23.33601","1.10823"
"17.60000","23.46940","1.10993"
"17.70000","23.60274","1.12347"
"17.80000","23.73602","1.11846"
"17.90000","23.86936","1.12078"
"18.00000","24.00264","1.12586"
"18.10000","24.13603","1.13382"
"18.20000","24.26937","1.13369"
"18.30000","24.40270","1.14222"
"18.40000","24.53598","1.14210"
"18.50000","24.66944","1.14398"
"18.60000","24.80272","1.15094"
"18.70000","24.93600","1.15871"
"18.80000","25.06939","1.16354"
"18.90000","25.20272","1.17684"
"19.00000","25.33612","1.17132"
"19.10000","25.46940","1.17753"
"19.20000","25.60262","1.17702"
"19.30000","25.73607","1.17257"
"19.40000","25.86941","1.19452"
"19.50000","26.00269","1.18079"
"19.60000","26.13602","1.19207"
"19.70000","26.26930","1.20487"
"19.80000","26.40275","1.20675"
"19.90000","26.53609","1.21064"
"20.00000","26.66943","1.20951"
"20.10000","26.80265","1.21691"
"20.20000","26.93605","1.21835"
"20.30000","27.06938","1.22750"
"20.40000","27.20272","1.23208"
"20.50000","27.33600","1.22945"
"20.60000","27.46928","1.23860"
"20.70000","27.60273","1.24055"
"20.80000","27.73606","1.24005"
"20.90000","27.86934","1.24550"
"21.00000","28.00274","1.24556"
"21.10000","28.13607","1.25378"
"21.20000","28.26941","1.25064"
"21.30000","28.40269","1.26387"
"21.40000","28.53609","1.26551"
"21.50000","28.66937","1.26914"
"21.60000","28.80264","1.27924"
"21.70000","28.93604","1.27196"
"21.80000","29.06926","1.28037"
"21.90000","29.20277","1.28099"
"22.00000","29.33605","1.28256"
"22.10000","29.46938","1.29874"
"22.20000","29.60272","1.29517"
"22.30000","29.73600","1.29830"
"22.40000","29.86940","1.29805"
"22.50000","30.00273","1.29918"
"22.60000","30.13596","1.30959"
"22.70000","30.26935","1.31254"
"22.80000","30.40274","1.31429"
"22.90000","30.53602","1.32282"
"23.00000","30.66936","1.32658"
"23.10000","30.80269","1.32520"
"23.20000","30.93609","1.33643"
"23.30000","31.06937","1.33241"
"23.40000","31.20271","1.33875"
"23.50000","31.33593","1.33593"
"23.60000","31.46943","1.34044"
"23.70000","31.60271","1.34696"
"23.80000","31.73605","1.35098"
"23.90000","31.86938","1.35775"
"24.00000","32.00261","1.36195"
"24.10000","32.13601","1.36709"
"24.20000","32.26940","1.36088"
"24.30000","32.40268","1.37041"
"24.40000","32.53607","1.37041"
"24.50000","32.66941","1.36621"
"24.60000","32.80268","1.36653"
"24.70000","32.93597","1.38277"
"24.80000","33.06931","1.37336"
"24.90000","33.20275","1.39644"
"25.00000","33.33603","1.38001"
"25.10000","33.46943","1.39769"
"25.20000","33.60265","1.39587"
"25.30000","33.73610","1.40315"
"25.40000","33.86944","1.39945"
"25.50000","34.00266","1.40904"
"25.60000","34.13600","1.40258"
"25.70000","34.26933","1.41212"
"25.80000","34.40267","1.41130"
"25.90000","34.53601","1.41870"
"26.00000","34.66934","1.41719"
"26.10000","34.80274","1.42447"
"26.20000","34.93602","1.42604"
"26.30000","35.06941","1.42999"
"26.40000","35.20275","1.43620"
"26.50000","35.33603","1.43450"
"26.60000","35.46942","1.43783"
"26.70000","35.60270","1.44015"
"26.80000","35.73615","1.44736"
"26.90000","35.86932","1.44334"
"27.00000","36.00271","1.45695"
"27.10000","36.13593","1.45125"
"27.20000","36.26933","1.46040"
"27.30000","36.40272","1.45125"
"27.40000","36.53600","1.46680"
"27.50000","36.66940","1.46805"
"27.60000","36.80268","1.46805"
"27.70000","36.93596","1.46410"
"27.80000","37.06935","1.46724"
"27.90000","37.20274","1.47965"
"28.00000","37.33602","1.47971"
"28.10000","37.46936","1.47921"
"28.20000","37.60269","1.48072"
"28.30000","37.73603","1.49000"
"28.40000","37.86937","1.48968"
"28.50000","38.00276","1.49815"
"28.60000","38.13598","1.49721"
"28.70000","38.26938","1.50825"
"28.80000","38.40271","1.49608"
"28.90000","38.53605","1.51063"
"29.00000","38.66939","1.50887"
"29.10000","38.80255","1.51094"
"29.20000","38.93612","1.50662"
"29.30000","39.06940","1.51828"
"29.40000","39.20274","1.51558"
"29.50000","39.33607","1.51922"
"29.60000","39.46935","1.52380"
"29.70000","39.60275","1.52367"
"29.80000","39.73603","1.53364"
"29.90000","39.86936","1.53835"
"30.00000","40.00269","1.53584"
"30.10000","40.13604","1.53327"
"30.20000","40.26942","1.53991"
"30.30000","40.40265","1.54706"
"30.40000","40.53604","1.55578"
"30.50000","40.66944","1.54901"
"30.60000","40.80266","1.55597"
"30.70000","40.93605","1.55967"
"30.80000","41.06927","1.55521"
"30.90000","41.20272","1.56613"
"31.00000","41.33612","1.56243"
"31.10000","41.46934","1.56983"
"31.20000","41.60274","1.56807"
"31.30000","41.73602","1.57685"
"31.40000","41.86941","1.57102"
"31.50000","42.00263","1.57666"
"31.60000","42.13603","1.57967"
"31.70000","42.26947","1.58745"
"31.80000","42.40264","1.58487"
"31.90000","42.53604","1.58908"
"32.00000","42.66932","1.59046"
"32.10000","42.80271","1.58889"
"32.20000","42.93605","1.59654"
"32.30000","43.06939","1.59008"
"32.40000","43.20272","1.59967"
"32.50000","43.33600","1.60525"
"32.60000","43.46945","1.60613"
"32.70000","43.60273","1.61002"
"32.80000","43.73601","1.61171"
"32.90000","43.86935","1.61372"
"33.00000","44.00263","1.61936"
"33.10000","44.13602","1.61773"
"33.20000","44.26936","1.62294"
"33.30000","44.40269","1.62495"
"33.40000","44.53609","1.62808"
"33.50000","44.66942","1.62194"
"33.60000","44.80270","1.62940"
"33.70000","44.93604","1.63228"
"33.80000","45.06938","1.63548"
"33.90000","45.20271","1.63799"
"34.00000","45.33605","1.64470"
"34.10000","45.46939","1.64332"
"34.20000","45.60266","1.64928"
"34.30000","45.73606","1.65247"
"34.40000","45.86940","1.65504"
"34.50000","46.00274","1.65323"
"34.60000","46.13601","1.65448"
"34.70000","46.26935","1.65272"
"34.80000","46.40274","1.65486"
"34.90000","46.53608","1.66646"
"35.00000","46.66941","1.67078"
"35.10000","46.80270","1.68126"
"35.20000","46.93603","1.67285"
"35.30000","47.06942","1.66514"
"35.40000","47.20271","1.67473"
"35.50000","47.33604","1.67147"
"35.60000","47.46933","1.68163"
"35.70000","47.60266","1.67699"
"35.80000","47.73606","1.68458"
"35.90000","47.86928","1.68759"
"36.00000","48.00273","1.68690"
"36.10000","48.13606","1.68602"
"36.20000","48.26940","1.69436"
"36.30000","48.40268","1.69675"
"36.40000","48.53607","1.70157"
"36.50000","48.66941","1.69480"
"36.60000","48.80269","1.70251"
"36.70000","48.93603","1.70703"
"36.80000","49.06936","1.70810"
"36.90000","49.20276","1.71242"
"37.00000","49.33604","1.70860"
"37.10000","49.46932","1.71042"
"37.20000","49.60271","1.71537"
"37.30000","49.73605","1.71832"
"37.40000","49.86938","1.71763"
"37.50000","50.00272","1.73017"
"37.60000","50.13594","1.72459"
"37.70000","50.26945","1.71919"
"37.80000","50.40273","1.72772"
"37.90000","50.53601","1.72515"
"38.00000","50.66935","1.73105"
"38.10000","50.80268","1.74033"
"38.20000","50.93608","1.73976"
"38.30000","51.06936","1.73399"
"38.40000","51.20269","1.74171"
"38.50000","51.33603","1.73845"
"38.60000","51.46936","1.74898"
"38.70000","51.60270","1.75381"
"38.80000","51.73598","1.74879"
"38.90000","51.86938","1.75600"
"39.00000","52.00271","1.75864"
"39.10000","52.13600","1.76472"
"39.20000","52.26938","1.76221"
"39.30000","52.40256","1.76604"
"39.40000","52.53611","1.76215"
"39.50000","52.66934","1.76409"
"39.60000","52.80267","1.78046"
"39.70000","52.93607","1.77413"
"39.80000","53.06940","1.78090"
"39.90000","53.20274","1.77337"
"40.00000","53.33603","1.78209"
"40.10000","53.46936","1.78272"
"40.20000","53.60270","1.77745"
"40.30000","53.73603","1.78817"
"40.40000","53.86932","1.78905"
"40.50000","54.00265","1.79037"
"40.60000","54.13604","1.79607"
"40.70000","54.26932","1.79463"
"40.80000","54.40266","1.79821"
"40.90000","54.53611","1.79952"
"41.00000","54.66928","1.80059"
"41.10000","54.80273","1.80209"
"41.20000","54.93607","1.80554"
"41.30000","55.06935","1.81326"
"41.40000","55.20273","1.81225"
"41.50000","55.33608","1.80623"
"41.60000","55.46946","1.82040"
"41.70000","55.60269","1.81865"
"41.80000","55.73602","1.80912"
"41.90000","55.86942","1.82128"
"42.00000","56.00275","1.81507"
"42.10000","56.13609","1.82210"
"42.20000","56.26932","1.82624"
"42.30000","56.40271","1.82693"
"42.40000","56.53605","1.83790"
"42.50000","56.66932","1.82912"
"42.60000","56.80267","1.83709"
"42.70000","56.93594","1.82799"
"42.80000","57.06945","1.84028"
"42.90000","57.20273","1.84480"
"43.00000","57.33601","1.84229"
"43.10000","57.46935","1.83846"
"43.20000","57.60263","1.85339"
"43.30000","57.73602","1.84643"
"43.40000","57.86936","1.84292"
"43.50000","58.00264","1.85640"
"43.60000","58.13609","1.85389"
"43.70000","58.26937","1.85213"
"43.80000","58.40270","1.86060"
"43.90000","58.53604","1.85671"
"44.00000","58.66938","1.86273"
"44.10000","58.80266","1.86486"
"44.20000","58.93605","1.86543"
"44.30000","59.06933","1.87101"
"44.40000","59.20261","1.87258"
"44.50000","59.33606","1.86769"
"44.60000","59.46940","1.87327"
"44.70000","59.60267","1.87139"
"44.80000","59.73602","1.87571"
"44.90000","59.86935","1.88217"
"45.00000","60.00274","1.89051"
"45.10000","60.13602","1.88154"
"45.20000","60.26931","1.88568"
"45.30000","60.40275","1.88963"
"45.40000","60.53609","1.89810"
"45.50000","60.66937","1.89164"
"45.60000","60.80259","1.89333"
"45.70000","60.93605","1.89396"
"45.80000","61.06939","1.89384"
"45.90000","61.20272","1.90180"
"46.00000","61.33605","1.89948"
"46.10000","61.46933","1.90387"
"46.20000","61.60273","1.90588"
"46.30000","61.73601","1.89960"
"46.40000","61.86934","1.90048"
"46.50000","62.00262","1.91183"
"46.60000","62.13602","1.91070"
"46.70000","62.26941","1.91710"
"46.80000","62.40264","1.91635"
"46.90000","62.53602","1.92042"
"47.00000","62.66936","1.91886"
"47.10000","62.80270","1.92738"
"47.20000","62.93603","1.93679"
"47.30000","63.06937","1.93340"
"47.40000","63.20271","1.92607"
"47.50000","63.33604","1.92669"
"47.60000","63.46938","1.93535"
"47.70000","63.60271","1.93253"
"47.80000","63.73594","1.93064"
"47.90000","63.86940","1.93453"
"48.00000","64.00273","1.93717"
"48.10000","64.13606","1.94268"
"48.20000","64.26929","1.93892"
"48.30000","64.40263","1.94820"
"48.40000","64.53607","1.94193"
"48.50000","64.66930","1.94758"
"48.60000","64.80269","1.96024"
"48.70000","64.93609","1.94965"
"48.80000","65.06942","1.95153"
"48.90000","65.20270","1.95203"
"49.00000","65.33604","1.96388"
"49.10000","65.46943","1.96369"
"49.20000","65.60271","1.95159"
"49.30000","65.73605","1.97253"
"49.40000","65.86938","1.97573"
"49.50000","66.00267","1.96927"
"49.60000","66.13605","1.97272"
"49.70000","66.26934","1.97097"
"49.80000","66.40267","1.97761"
"49.90000","66.53601","1.97893"
"50.00000","66.66930","1.98633"
"50.10000","66.80269","1.98464"
"50.20000","66.93607","1.98213"
"50.30000","67.06941","1.97962"
"50.40000","67.20275","1.98539"
"50.50000","67.33603","1.99266"
"50.60000","67.46937","2.00226"
"50.70000","67.60265","1.99586"
"50.80000","67.73605","1.99567"
"50.90000","67.86938","2.00420"
"51.00000","68.00260","1.99172"
"51.10000","68.13611","2.00821"
"51.20000","68.26933","1.99862"
"51.30000","68.40273","2.01166"
"51.40000","68.53606","1.99423"
"51.50000","68.66928","2.00483"
"51.60000","68.80267","2.00546"
"51.70000","68.93596","2.01254"
"51.80000","69.06940","2.01248"
"51.90000","69.20269","2.01285"
"52.00000","69.33603","2.02420"
"52.10000","69.46936","2.02822"
"52.20000","69.60270","2.01618"
"52.30000","69.73603","2.01875"
"52.40000","69.86937","2.02276"
"52.50000","70.00271","2.02283"
"52.60000","70.13610","2.02527"
"52.70000","70.26933","2.03461"
"52.80000","70.40272","2.03486"
"52.90000","70.53594","2.03367"
"53.00000","70.66939","2.03869"
"53.10000","70.80267","2.03932"
"53.20000","70.93606","2.03518"
"53.30000","71.06940","2.04747"
"53.40000","71.20268","2.04371"
"53.50000","71.33607","2.05142"
"53.60000","71.46941","2.04321"
"53.70000","71.60269","2.04810"
"53.80000","71.73603","2.05223"
"53.90000","71.86931","2.04697"
"54.00000","72.00270","2.05631"
"54.10000","72.13604","2.05807"
"54.20000","72.26937","2.04816"
"54.30000","72.40271","2.05970"
"54.40000","72.53605","2.05593"
"54.50000","72.66933","2.06089"
"54.60000","72.80267","2.06290"
"54.70000","72.93612","2.06553"
"54.80000","73.06940","2.06352"
"54.90000","73.20273","2.07293"
"55.00000","73.33601","2.06697"
"55.10000","73.46929","2.07318"
"55.20000","73.60280","2.07820"
"55.30000","73.73602","2.07048"
"55.40000","73.86935","2.07644"
"55.50000","74.00275","2.07631"
"55.60000","74.13609","2.08089"
"55.70000","74.26937","2.08246"
"55.80000","74.40265","2.08039"
"55.90000","74.53604","2.08290"
"56.00000","74.66937","2.09086"
"56.10000","74.80271","2.09074"
"56.20000","74.93606","2.09174"
"56.30000","75.06933","2.09538"
"56.40000","75.20278","2.09036"
"56.50000","75.33606","2.09488"
"56.60000","75.46940","2.10077"
"56.70000","75.60262","2.09638"
"56.80000","75.73602","2.10033"
"56.90000","75.86941","2.10522"
"57.00000","76.00269","2.09958"
"57.10000","76.13609","2.10246"
"57.20000","76.26936","2.10221"
"57.30000","76.40276","2.11256"
"57.40000","76.53609","2.11005"
"57.50000","76.66931","2.11595"
"57.60000","76.80271","2.11789"
"57.70000","76.93604","2.11689"
"57.80000","77.06938","2.11438"
"57.90000","77.20271","2.11544"
"58.00000","77.33594","2.12479"
"58.10000","77.46934","2.12429"
"58.20000","77.60273","2.12529"
"58.30000","77.73601","2.13074"
"58.40000","77.86935","2.12052"
"58.50000","78.00262","2.13407"
"58.60000","78.13607","2.12987"
"58.70000","78.26936","2.12466"
"58.80000","78.40275","2.13758"
"58.90000","78.53602","2.13852"
"59.00000","78.66925","2.14210"
"59.10000","78.80270","2.13269"
"59.20000","78.93598","2.13520"
"59.30000","79.06937","2.13971"
"59.40000","79.20277","2.14391"
"59.50000","79.33604","2.13858"
"59.60000","79.46932","2.15370"
"59.70000","79.60267","2.15407"
"59.80000","79.73605","2.15119"
"59.90000","79.86934","2.15915"
"60.00000","80.00273","2.15370"
"60.10000","80.13607","2.15909"
"60.20000","80.26929","2.16617"
"60.30000","80.40273","2.16561"
"60.40000","80.53602","2.16605"
"60.50000","80.66936","2.16674"
"60.60000","80.80275","2.17219"
"60.70000","80.93603","2.17821"
"60.80000","81.06943","2.16975"
"60.90000","81.20270","2.17270"
"61.00000","81.33604","2.16686"
"61.10000","81.46931","2.16912"
"61.20000","81.60265","2.16987"
"61.30000","81.73605","2.17577"
"61.40000","81.86938","2.18637"
"61.50000","82.00266","2.17495"
"61.60000","82.13611","2.17370"
"61.70000","82.26945","2.18750"
"61.80000","82.40268","2.18298"
"61.90000","82.53590","2.19101"
"62.00000","82.66935","2.18925"
"62.10000","82.80269","2.18524"
"62.20000","82.93603","2.19797"
"62.30000","83.06936","2.19201"
"62.40000","83.20269","2.19859"
"62.50000","83.33609","2.19784"
"62.60000","83.46938","2.19671"
"62.70000","83.60265","2.19671"
"62.80000","83.73604","2.20148"
"62.90000","83.86938","2.20725"
"63.00000","84.00272","2.20681"
"63.10000","84.13599","2.20938"
"63.20000","84.26934","2.20624"
"63.30000","84.40267","2.21314"
"63.40000","84.53594","2.21314"
"63.50000","84.66933","2.21082"
"63.60000","84.80263","2.21252"
"63.70000","84.93613","2.21371"
"63.80000","85.06936","2.21929"
"63.90000","85.20274","2.21571"
"64.00000","85.33603","2.22895"
"64.10000","85.46937","2.22311"
"64.20000","85.60276","2.22061"
"64.30000","85.73598","2.22437"
"64.40000","85.86937","2.23070"
"64.50000","86.00272","2.23835"
"64.60000","86.13599","2.23609"
"64.70000","86.26939","2.24149"
"64.80000","86.40272","2.23641"
"64.90000","86.53600","2.23402"
"65.00000","86.66933","2.23509"
"65.10000","86.80273","2.24023"
"65.20000","86.93607","2.24462"
"65.30000","87.06929","2.23634"
"65.40000","87.20280","2.24801"
"65.50000","87.33602","2.24205"
"65.60000","87.46941","2.25001"
"65.70000","87.60263","2.24964"
"65.80000","87.73597","2.24795"
"65.90000","87.86943","2.25535"
"66.00000","88.00269","2.24186"
"66.10000","88.13598","2.25898"
"66.20000","88.26942","2.25315"
"66.30000","88.40271","2.25861"
"66.40000","88.53600","2.25171"
"66.50000","88.66933","2.26224"
"66.60000","88.80273","2.26362"
"66.70000","88.93606","2.26538"
"66.80000","89.06939","2.26149"
"66.90000","89.20268","2.26688"
"67.00000","89.33590","2.26751"
"67.10000","89.46941","2.26525"
"67.20000","89.60274","2.27221"
"67.30000","89.73603","2.27729"
"67.40000","89.86931","2.27491"
"67.50000","90.00264","2.27993"
"67.60000","90.13609","2.27435"
"67.70000","90.26937","2.26663"
"67.80000","90.40271","2.28137"
"67.90000","90.53603","2.28294"
"68.00000","90.66939","2.27974"
"68.10000","90.80272","2.28450"
"68.20000","90.93599","2.28338"
"68.30000","91.06938","2.28958"
"68.40000","91.20267","2.28852"
"68.50000","91.33607","2.28965"
"68.60000","91.46935","2.29090"
"68.70000","91.60262","2.30175"
"68.80000","91.73608","2.29071"
"68.90000","91.86935","2.29774"
"69.00000","92.00275","2.29284"
"69.10000","92.13597","2.30413"
"69.20000","92.26930","2.30350"
"69.30000","92.40270","2.30413"
"69.40000","92.53592","2.30357"
"69.50000","92.66933","2.31103"
"69.60000","92.80271","2.30733"
"69.70000","92.93604","2.31272"
"69.80000","93.06938","2.30921"
"69.90000","93.20273","2.31561"
"70.00000","93.33611","2.31492"
"70.10000","93.46940","2.31617"
"70.20000","93.60273","2.31467"
"70.30000","93.73602","2.31887"
"70.40000","93.86929","2.31818"
"70.50000","94.00275","2.31975"
"70.60000","94.13602","2.31492"
"70.70000","94.26936","2.31874"
"70.80000","94.40264","2.32608"
"70.90000","94.53598","2.32539"
"71.00000","94.66937","2.32934"
"71.10000","94.80270","2.33110"
"71.20000","94.93604","2.33762"
"71.30000","95.06937","2.33335"
"71.40000","95.20266","2.32965"
"71.50000","95.33605","2.33881"
"71.60000","95.46932","2.34276"
"71.70000","95.60272","2.34270"
"71.80000","95.73601","2.34226"
"71.90000","95.86934","2.34351"
"72.00000","96.00274","2.35148"
"72.10000","96.13596","2.35041"
"72.20000","96.26946","2.34759"
"72.30000","96.40269","2.35342"
"72.40000","96.53602","2.35668"
"72.50000","96.66931","2.36483"
"72.60000","96.80270","2.35072"
"72.70000","96.93615","2.35768"
"72.80000","97.06937","2.35712"
"72.90000","97.20271","2.36490"
"73.00000","97.33610","2.36107"
"73.10000","97.46932","2.36834"
"73.20000","97.60271","2.36834"
"73.30000","97.73600","2.36891"
"73.40000","97.86940","2.36928"
"73.50000","98.00273","2.36345"
"73.60000","98.13600","2.36966"
"73.70000","98.26929","2.36772"
"73.80000","98.40269","2.37505"
"73.90000","98.53607","2.37857"
"74.00000","98.66935","2.37988"
"74.10000","98.80280","2.38176"
"74.20000","98.93603","2.38151"
"74.30000","99.06937","2.38603"
"74.40000","99.20276","2.38628"
"74.50000","99.33598","2.38709"
"74.60000","99.46938","2.38803"
"74.70000","99.60271","2.38791"
"74.80000","99.73599","2.39732"
"74.90000","99.86933","2.39086"
"75.00000","100.00272","2.39957"
"75.10000","100.13599","2.39230"
"75.20000","100.26939","2.39775"
"75.30000","100.40273","2.40446"
"75.40000","100.53601","2.40892"
"75.50000","100.66923","2.40101"
"75.60000","100.80280","2.40873"
"75.70000","100.93596","2.41374"
"75.80000","101.06942","2.40014"
"75.90000","101.20269","2.39938"
"76.00000","101.33602","2.41324"
"76.10000","101.46942","2.41136"
"76.20000","101.60265","2.40584"
"76.30000","101.73604","2.41807"
"76.40000","101.86943","2.41368"
"76.50000","102.00277","2.41694"
"76.60000","102.13599","2.41343"
"76.70000","102.26933","2.42183"
"76.80000","102.40267","2.42234"
"76.90000","102.53594","2.42535"
"77.00000","102.66933","2.41744"
"77.10000","102.80267","2.42277"
"77.20000","102.93595","2.41788"
"77.30000","103.06940","2.42234"
"77.40000","103.20274","2.42509"
"77.50000","103.33608","2.42698"
"77.60000","103.46936","2.42685"
"77.70000","103.60264","2.42547"
"77.80000","103.73604","2.42641"
"77.90000","103.86932","2.43124"
"78.00000","104.00277","2.43300"
"78.10000","104.13609","2.42923"
"78.20000","104.26939","2.43845"
"78.30000","104.40271","2.43996"
"78.40000","104.53600","2.44140"
"78.50000","104.66933","2.44391"
"78.60000","104.80267","2.44359"
"78.70000","104.93607","2.44679"
"78.80000","105.06940","2.44629"
"78.90000","105.20263","2.44961"
"79.00000","105.33613","2.44391"
"79.10000","105.46930","2.44836"
"79.20000","105.60270","2.45018"
"79.30000","105.73603","2.45356"
"79.40000","105.86931","2.45670"
"79.50000","106.00276","2.46046"
"79.60000","106.13598","2.46134"
"79.70000","106.26937","2.45262"
"79.80000","106.40271","2.46673"
"79.90000","106.53605","2.45751"
"80.00000","106.66933","2.46473"
"80.10000","106.80273","2.46504"
"80.20000","106.93606","2.47451"
"80.30000","107.06946","2.47144"
"80.40000","107.20272","2.47445"
"80.50000","107.33601","2.47658"
"80.60000","107.46923","2.46661"
"80.70000","107.60274","2.47332"
"80.80000","107.73602","2.47871"
"80.90000","107.86935","2.47162"
"81.00000","108.00269","2.48103"
"81.10000","108.13598","2.48366"
"81.20000","108.26942","2.48128"
"81.30000","108.40266","2.48435"
"81.40000","108.53603","2.48812"
"81.50000","108.66937","2.48906"
"81.60000","108.80272","2.48366"
"81.70000","108.93599","2.49570"
"81.80000","109.06938","2.48993"
"81.90000","109.20272","2.47946"
"82.00000","109.33601","2.49451"
"82.10000","109.46934","2.49878"
"82.20000","109.60262","2.50279"
"82.30000","109.73595","2.49388"
"82.40000","109.86941","2.50348"
"82.50000","110.00275","2.50373"
"82.60000","110.13614","2.50699"
"82.70000","110.26941","2.49878"
"82.80000","110.40263","2.50599"
"82.90000","110.53598","2.50091"
"83.00000","110.66936","2.51245"
"83.10000","110.80271","2.50768"
"83.20000","110.93610","2.50824"
"83.30000","111.06944","2.51364"
"83.40000","111.20271","2.52674"
"83.50000","111.33605","2.51063"
"83.60000","111.46940","2.50925"
"83.70000","111.60273","2.51646"
"83.80000","111.73602","2.52329"
"83.90000","111.86939","2.52367"
"84.00000","112.00262","2.53013"
"84.10000","112.13608","2.52173"
"84.20000","112.26936","2.52286"
"84.30000","112.40269","2.51489"
"84.40000","112.53592","2.52160"
"84.50000","112.66931","2.53283"
"84.60000","112.80276","2.53088"
"84.70000","112.93610","2.52649"
"84.80000","113.06937","2.53258"
"84.90000","113.20277","2.53163"
"85.00000","113.33604","2.54273"
"85.10000","113.46938","2.52737"
"85.20000","113.60273","2.53722"
"85.30000","113.73600","2.53584"
"85.40000","113.86939","2.54330"
"85.50000","114.00273","2.54217"
"85.60000","114.13607","2.54518"
"85.70000","114.26924","2.54330"
"85.80000","114.40274","2.54857"
"85.90000","114.53596","2.55020"
"86.00000","114.66942","2.55201"
"86.10000","114.80264","2.54581"
"86.20000","114.93597","2.55333"
"86.30000","115.06949","2.54926"
"86.40000","115.20265","2.54794"
"86.50000","115.33604","2.55684"
"86.60000","115.46938","2.55609"
"86.70000","115.60271","2.55427"
"86.80000","115.73605","2.56167"
"86.90000","115.86938","2.55590"
"87.00000","116.00267","2.56405"
"87.10000","116.13600","2.56104"
"87.20000","116.26940","2.57164"
"87.30000","116.40262","2.56456"
"87.40000","116.53596","2.56637"
"87.50000","116.66946","2.56888"
"87.60000","116.80275","2.56926"
"87.70000","116.93608","2.57735"
"87.80000","117.06937","2.58055"
"87.90000","117.20264","2.57208"
"88.00000","117.33610","2.58400"
"88.10000","117.46931","2.57729"
"88.20000","117.60265","2.59052"
"88.30000","117.73598","2.58243"
"88.40000","117.86938","2.58180"
"88.50000","118.00272","2.59089"
"88.60000","118.13605","2.59353"
"88.70000","118.26933","2.59002"
"88.80000","118.40262","2.59478"
"88.90000","118.53606","2.59346"
"89.00000","118.66935","2.61002"
"89.10000","118.80268","2.60387"
"89.20000","118.93597","2.59886"
"89.30000","119.06936","2.59698"
"89.40000","119.20275","2.59578"
"89.50000","119.33602","2.59641"
"89.60000","119.46931","2.59716"
"89.70000","119.60269","2.59372"
"89.80000","119.73605","2.60500"
"89.90000","119.86942","2.59616"
"90.00000","120.00277","2.60043"
"90.10000","120.13605","2.59792"
"90.20000","120.26939","2.60764"
"90.30000","120.40266","2.60450"
"90.40000","120.53594","2.61090"
"90.50000","120.66940","2.60381"
"90.60000","120.80273","2.61416"
"90.70000","120.93600","2.60933"
"90.80000","121.06940","2.61836"
"90.90000","121.20269","2.61823"
"91.00000","121.33597","2.62012"
"91.10000","121.46941","2.61711"
"91.20000","121.60264","2.62037"
"91.30000","121.73592","2.61058"
"91.40000","121.86943","2.62024"
"91.50000","122.00270","2.61779"
"91.60000","122.13604","2.62331"
"91.70000","122.26943","2.62382"
"91.80000","122.40266","2.62733"
"91.90000","122.53599","2.63723"
"92.00000","122.66938","2.62977"
"92.10000","122.80267","2.62877"
"92.20000","122.93607","2.64043"
"92.30000","123.06940","2.63667"
"92.40000","123.20274","2.63096"
"92.50000","123.33596","2.63422"
"92.60000","123.46935","2.64351"
"92.70000","123.60269","2.63786"
"92.80000","123.73608","2.63366"
"92.90000","123.86942","2.63774"
"93.00000","124.00263","2.64388"
"93.10000","124.13614","2.65116"
"93.20000","124.26936","2.64752"
"93.30000","124.40265","2.65279"
"93.40000","124.53600","2.64953"
"93.50000","124.66933","2.64940"
"93.60000","124.80273","2.66853"
"93.70000","124.93611","2.66796"
"93.80000","125.06938","2.65141"
"93.90000","125.20271","2.65153"
"94.00000","125.33605","2.65291"
"94.10000","125.46935","2.66238"
"94.20000","125.60262","2.65348"
"94.30000","125.73608","2.65611"
"94.40000","125.86935","2.66326"
"94.50000","126.00269","2.66351"
"94.60000","126.13602","2.66301"
"94.70000","126.26929","2.67216"
"94.80000","126.40269","2.66664"
"94.90000","126.53603","2.66664"
"95.00000","126.66942","2.67135"
"95.10000","126.80276","2.67166"
"95.20000","126.93605","2.67210"
"95.30000","127.06938","2.67323"
"95.40000","127.20266","2.67348"
"95.50000","127.33600","2.67567"
"95.60000","127.46933","2.68100"
"95.70000","127.60273","2.68151"
"95.80000","127.73600","2.68539"
"95.90000","127.86934","2.68878"
"96.00000","128.00273","2.67781"
"96.10000","128.13606","2.68345"
"96.20000","128.26941","2.69398"
"96.30000","128.40263","2.68941"
"96.40000","128.53590","2.69185"
"96.50000","128.66942","2.69875"
"96.60000","128.80270","2.69674"
"96.70000","128.93604","2.70496"
"96.80000","129.06943","2.69499"
"96.90000","129.20271","2.70044"
"97.00000","129.33598","2.70465"
"97.10000","129.46931","2.70853"
"97.20000","129.60266","2.71349"
"97.30000","129.73605","2.72070"
"97.40000","129.86938","2.71480"
"97.50000","130.00267","2.70797"
"97.60000","130.13602","2.71179"
"97.70000","130.26941","2.70985"
"97.80000","130.40268","2.71016"
"97.90000","130.53607","2.71850"
"98.00000","130.66936","2.72189"
"98.10000","130.80263","2.72145"
"98.20000","130.93614","2.72816"
"98.30000","131.06931","2.72296"
"98.40000","131.20270","2.72910"
"98.50000","131.33609","2.73268"
"98.60000","131.46933","2.72810"
"98.70000","131.60271","2.73117"
"98.80000","131.73599","2.73017"
"98.90000","131.86938","2.73368"
"99.00000","132.00267","2.73769"
"99.10000","132.13606","2.73876"
"99.20000","132.26933","2.73732"
"99.30000","132.40262","2.74076"
"99.40000","132.53601","2.73456"
"99.50000","132.66928","2.73694"
"99.60000","132.80273","2.74171"
"99.70000","132.93602","2.73669"
"99.80000","133.06931","2.74252"
"99.90000","133.20280","2.74465"
"100.00000","133.33604","2.74045"
"100.10000","133.46931","2.73775"
"100.20000","133.60271","2.74001"
"100.30000","133.73593","2.74490"
"100.40000","133.86945","2.75864"
"100.50000","134.00272","2.75287"
"100.60000","134.13599","2.75055"
"100.70000","134.26933","2.75594"
"100.80000","134.40266","2.75337"
"100.90000","134.53595","2.74729"
"101.00000","134.66939","2.76547"
"101.10000","134.80273","2.76898"
"101.20000","134.93608","2.76089"
"101.30000","135.06946","2.77801"
"101.40000","135.20270","2.78861"
"101.50000","135.33597","2.77193"
"101.60000","135.46942","2.75713"
"101.70000","135.60263","2.77093"
"101.80000","135.73604","2.76284"
"101.90000","135.86937","2.77275"
"102.00000","136.00264","2.77181"
"102.10000","136.13609","2.78366"
"102.20000","136.26938","2.77199"
"102.30000","136.40266","2.78083"
"102.40000","136.53606","2.77469"
"102.50000","136.66940","2.77243"
"102.60000","136.80273","2.77933"
"102.70000","136.93613","2.79124"
"102.80000","137.06940","2.77883"
"102.90000","137.20268","2.78002"
"103.00000","137.33607","2.79225"
"103.10000","137.46930","2.79507"
"103.20000","137.60252","2.78604"
"103.30000","137.73615","2.78315"
"103.40000","137.86937","2.80203"
"103.50000","138.00275","2.81332"
"103.60000","138.13605","2.78315"
"103.70000","138.26932","2.79501"
"103.80000","138.40265","2.80573"
"103.90000","138.53593","2.81495"
"104.00000","138.66927","2.81733"
"104.10000","138.80272","2.79620"
"104.20000","138.93611","2.80849"
"104.30000","139.06946","2.80868"
"104.40000","139.20273","2.82373"
"104.50000","139.33595","2.82116"
"104.60000","139.46930","2.80974"
"104.70000","139.60274","2.80586"
"104.80000","139.73608","2.82373"
"104.90000","139.86925","2.82304"
"105.00000","140.00281","2.83307"
"105.10000","140.13603","2.81927"
"105.20000","140.26936","2.81507"
"105.30000","140.40265","2.83138"
"105.40000","140.53598","2.82053"
"105.50000","140.66937","2.82366"
"105.60000","140.80270","2.83169"
"105.70000","140.93605","2.82768"
"105.80000","141.06938","2.83577"
"105.90000","141.20267","2.82956"
"106.00000","141.33601","2.82937"
"106.10000","141.46935","2.83458"
"106.20000","141.60274","2.84172"
"106.30000","141.73596","2.83784"
"106.40000","141.86948","2.83489"
"106.50000","142.00275","2.83771"
"106.60000","142.13596","2.84812"
"106.70000","142.26942","2.82529"
"106.80000","142.40259","2.83501"
"106.90000","142.53603","2.84172"
"107.00000","142.66927","2.86098"
"107.10000","142.80266","2.84047"
"107.20000","142.93610","2.84580"
"107.30000","143.06944","2.85176"
"107.40000","143.20267","2.85458"
"107.50000","143.33606","2.85238"
"107.60000","143.46939","2.84956"
"107.70000","143.60268","2.86016"
"107.80000","143.73601","2.86624"
"107.90000","143.86934","2.84693"
"108.00000","144.00262","2.85602"
"108.10000","144.13608","2.85803"
"108.20000","144.26936","2.86618"
"108.30000","144.40257","2.86963"
"108.40000","144.53613","2.86925"
"108.50000","144.66931","2.86530"
"108.60000","144.80276","2.86938"
"108.70000","144.93604","2.87414"
"108.80000","145.06932","2.86681"
"108.90000","145.20277","2.86787"
"109.00000","145.33598","2.87433"
"109.10000","145.46933","2.86825"
"109.20000","145.60272","2.87759"
"109.30000","145.73605","2.87408"
"109.40000","145.86938","2.88750"
"109.50000","146.00275","2.88374"
"109.60000","146.13608","2.88411"
"109.70000","146.26929","2.88336"
"109.80000","146.40268","2.89258"
"109.90000","146.53603","2.88706"
"110.00000","146.66925","2.89114"
"110.10000","146.80275","2.89007"
"110.20000","146.93604","2.89402"
"110.30000","147.06943","2.89628"
"110.40000","147.20270","2.88995"
"110.50000","147.33594","2.90324"
"110.60000","147.46939","2.87822"
"110.70000","147.60272","2.89239"
"110.80000","147.73605","2.90155"
"110.90000","147.86934","2.90167"
"111.00000","148.00273","2.91597"
"111.10000","148.13606","2.90707"
"111.20000","148.26929","2.91120"
"111.30000","148.40268","2.90374"
"111.40000","148.53596","2.91039"
"111.50000","148.66940","2.91277"
"111.60000","148.80269","2.91271"
"111.70000","148.93579","2.91566"
"111.80000","149.06941","2.91051"
"111.90000","149.20270","2.91998"
"112.00000","149.33604","2.92538"
"112.10000","149.46931","2.92563"
"112.20000","149.60265","2.91898"
"112.30000","149.73605","2.92161"
"112.40000","149.86938","2.92933"
"112.50000","150.00272","2.93027"
"112.60000","150.13611","2.92425"
"112.70000","150.26933","2.92594"
"112.80000","150.40268","2.93717"
"112.90000","150.53601","2.93804"
"113.00000","150.66942","2.93773"
"113.10000","150.80263","2.93510"
"113.20000","150.93602","2.93923"
"113.30000","151.06935","2.93378"
"113.40000","151.20264","2.93923"
"113.50000","151.33609","2.94895"
"113.60000","151.46930","2.93980"
"113.70000","151.60275","2.93691"
"113.80000","151.73604","2.93898"
"113.90000","151.86932","2.94494"
"114.00000","152.00276","2.94645"
"114.10000","152.13606","2.95102"
"114.20000","152.26933","2.94996"
"114.30000","152.40266","2.96193"
"114.40000","152.53607","2.96099"
"114.50000","152.66940","2.95008"
"114.60000","152.80273","2.95579"
"114.70000","152.93607","2.95729"
"114.80000","153.06929","2.95961"
"114.90000","153.20268","2.96444"
"115.00000","153.33601","2.96150"
"115.10000","153.46925","2.96858"
"115.20000","153.60271","2.97122"
"115.30000","153.73598","2.96871"
"115.40000","153.86937","2.97172"
"115.50000","154.00278","2.97090"
"115.60000","154.13605","2.97523"
"115.70000","154.26938","2.96858"
"115.80000","154.40273","2.97059"
"115.90000","154.53606","2.97573"
"116.00000","154.66939","2.97567"
"116.10000","154.80272","2.97360"
"116.20000","154.93607","2.97999"
"116.30000","155.06940","2.98175"
"116.40000","155.20268","2.97529"
"116.50000","155.33597","2.96896"
"116.60000","155.46942","2.95466"
"116.70000","155.60269","2.95253"
"116.80000","155.73592","2.93717"
"116.90000","155.86937","2.94325"
"117.00000","156.00276","2.92820"
"117.10000","156.13609","2.93798"
"117.20000","156.26932","2.94413"
"117.30000","156.40265","2.93961"
"117.40000","156.53610","2.94902"
"117.50000","156.66937","2.94927"
"117.60000","156.80278","2.95516"
"117.70000","156.93611","2.94275"
"117.80000","157.06940","2.94444"
"117.90000","157.20267","2.94845"
"118.00000","157.33601","2.95441"
"118.10000","157.46928","2.95052"
"118.20000","157.60257","2.94745"
"118.30000","157.73608","2.94795"
"118.40000","157.86934","2.96319"
"118.50000","158.00264","2.95773"
"118.60000","158.13612","2.95704"
"118.70000","158.26932","2.96156"
"118.80000","158.40271","2.94889"
"118.90000","158.53604","2.96250"
"119.00000","158.66927","2.96802"
"119.10000","158.80278","2.96262"
"119.20000","158.93599","2.96099"
"119.30000","159.06927","2.96187"
"119.40000","159.20267","2.95867"
"119.50000","159.33600","2.97090"
"119.60000","159.46933","2.97347"
"119.70000","159.60268","2.96432"
"119.80000","159.73607","2.96482"
"119.90000","159.86935","2.97122"
"120.00000","160.00279","2.97579"
"120.10000","160.13602","2.97441"
"120.20000","160.26930","2.96933"
"120.30000","160.40274","2.96871"
"120.40000","160.53596","2.98238"
"120.50000","160.66942","2.97165"
"120.60000","160.80269","2.97285"
"120.70000","160.93599","2.97134"
"120.80000","161.06943","2.97799"
"120.90000","161.20264","2.97686"
"121.00000","161.33600","2.97705"
"121.10000","161.46938","2.97567"
"121.20000","161.60272","2.98087"
"121.30000","161.73607","2.97999"
"121.40000","161.86938","2.98971"
"121.50000","162.00275","2.99028"
"121.60000","162.13596","2.98815"
"121.70000","162.26933","2.99323"
"121.80000","162.40269","2.98921"
"121.90000","162.53603","2.98520"
"122.00000","162.66942","2.99592"
"122.10000","162.80270","2.98777"
"122.20000","162.93602","2.99141"
"122.30000","163.06943","2.98808"
"122.40000","163.20265","2.99191"
"122.50000","163.33604","2.99467"
"122.60000","163.46939","2.99410"
"122.70000","163.60260","2.99711"
"122.80000","163.73599","2.99774"
"122.90000","163.86934","3.00106"
"123.00000","164.00261","2.99755"
"123.10000","164.13600","3.00050"
"123.20000","164.26935","3.00708"
"123.30000","164.40263","3.00351"
"123.40000","164.53607","3.00025"
"123.50000","164.66936","3.00696"
"123.60000","164.80269","3.00865"
"123.70000","164.93613","3.00219"
"123.80000","165.06931","3.00200"
"123.90000","165.20277","3.00991"
"124.00000","165.33598","3.01486"
"124.10000","165.46925","3.00978"
"124.20000","165.60277","3.02270"
"124.30000","165.73605","3.01342"
"124.40000","165.86938","3.01097"
"124.50000","166.00272","3.01542"
"124.60000","166.13602","3.02075"
"124.70000","166.26927","3.01862"
"124.80000","166.40268","3.02169"
"124.90000","166.53601","3.01956"
"125.00000","166.66928","3.02270"
"125.10000","166.80280","3.02358"
"125.20000","166.93608","3.02878"
"125.30000","167.06931","3.02333"
"125.40000","167.20274","3.02395"
"125.50000","167.33592","3.02715"
"125.60000","167.46931","3.01843"
"125.70000","167.60266","3.02966"
"125.80000","167.73587","3.01693"
"125.90000","167.86942","3.01668"
"126.00000","168.00276","3.02558"
"126.10000","168.13606","3.02057"
"126.20000","168.26933","3.02226"
"126.30000","168.40266","3.01712"
"126.40000","168.53601","3.02514"
"126.50000","168.66934","3.03116"
"126.60000","168.80267","3.02257"
"126.70000","168.93596","3.02107"
"126.80000","169.06941","3.03969"
"126.90000","169.20262","3.03480"
"127.00000","169.33598","3.02583"
"127.10000","169.46930","3.02703"
"127.20000","169.60265","3.03424"
"127.30000","169.73608","3.03637"
"127.40000","169.86938","3.03668"
"127.50000","170.00266","3.04214"
"127.60000","170.13603","3.02797"
"127.70000","170.26938","3.01618"
"127.80000","170.40266","3.02872"
"127.90000","170.53598","3.03336"
"128.00000","170.66933","3.03468"
"128.10000","170.80272","3.02715"
"128.20000","170.93607","3.02521"
"128.30000","171.06938","3.02314"
"128.40000","171.20264","3.03342"
"128.50000","171.33612","3.02546"
"128.60000","171.46936","3.03173"
"128.70000","171.60268","3.03004"
"128.80000","171.73604","3.03060"
"128.90000","171.86937","3.02797"
"129.00000","172.00276","3.03486"
"129.10000","172.13599","3.03518"
"129.20000","172.26927","3.02596"
"129.30000","172.40277","3.03461"
"129.40000","172.53604","3.04001"
"129.50000","172.66933","3.03436"
"129.60000","172.80273","3.03668"
"129.70000","172.93605","3.03355"
"129.80000","173.06932","3.03047"
"129.90000","173.20268","3.02866"
"130.00000","173.33600","3.02960"
"130.10000","173.46927","3.03148"
"130.20000","173.60278","3.04013"
"130.30000","173.73601","3.04013"
"130.40000","173.86935","3.03417"
"130.50000","174.00273","3.03192"
"130.60000","174.13599","3.03505"
"130.70000","174.26932","3.03925"
"130.80000","174.40265","3.03424"
"130.90000","174.53593","3.03700"
"131.00000","174.66939","3.03273"
"131.10000","174.80270","3.03442"
"131.20000","174.93605","3.03085"
"131.30000","175.06940","3.02721"
"131.40000","175.20273","3.03311"
"131.50000","175.33606","3.03461"
"131.60000","175.46939","3.02721"
"131.70000","175.60268","3.03091"
"131.80000","175.73589","3.04126"
"131.90000","175.86940","3.03254"
"132.00000","176.00276","3.03580"
"132.10000","176.13597","3.03505"
"132.20000","176.26935","3.04264"
"132.30000","176.40271","3.02997"
"132.40000","176.53609","3.03342"
"132.50000","176.66943","3.02853"
"132.60000","176.80264","3.03938"
"132.70000","176.93611","3.03932"
"132.80000","177.06938","3.03844"
"132.90000","177.20270","3.03706"
"133.00000","177.33601","3.04038"
"133.10000","177.46935","3.04145"
"133.20000","177.60268","3.03982"
"133.30000","177.73607","3.04446"
"133.40000","177.86942","3.05154"
"133.50000","178.00269","3.03624"
"133.60000","178.13608","3.03963"
"133.70000","178.26936","3.03643"
"133.80000","178.40268","3.03386"
"133.90000","178.53609","3.02903"
"134.00000","178.66931","3.03405"
"134.10000","178.80276","3.03881"
"134.20000","178.93605","3.03850"
"134.30000","179.06920","3.02997"
"134.40000","179.20276","3.04044"
"134.50000","179.33600","3.03875"
"134.60000","179.46938","3.04245"
"134.70000","179.60272","3.03831"
"134.80000","179.73601","3.03674"
"134.90000","179.86932","3.05073"
"135.00000","180.00273","3.04126"
"135.10000","180.13597","3.04289"
"135.20000","180.26930","3.05380"
"135.30000","180.40279","3.05186"
"135.40000","180.53607","3.04803"
"135.50000","180.66937","3.04239"
"135.60000","180.80276","3.05035"
"135.70000","180.93597","3.04935"
"135.80000","181.06937","3.05029"
"135.90000","181.20265","3.05869"
"136.00000","181.33588","3.05850"
"136.10000","181.46944","3.05462"
"136.20000","181.60271","3.05562"
"136.30000","181.73605","3.04935"
"136.40000","181.86938","3.05161"
"136.50000","182.00272","3.05744"
"136.60000","182.13602","3.05731"
"136.70000","182.26939","3.05292"
"136.80000","182.40262","3.05756"
"136.90000","182.53603","3.06202"
"137.00000","182.66940","3.05869"
"137.10000","182.80275","3.06126"
"137.20000","182.93597","3.06722"
"137.30000","183.06935","3.06879"
"137.40000","183.20264","3.06195"
"137.50000","183.33598","3.06678"
"137.60000","183.46938","3.06120"
"137.70000","183.60258","3.06383"
"137.80000","183.73605","3.06916"
"137.90000","183.86938","3.06684"
"138.00000","184.00267","3.06666"
"138.10000","184.13594","3.07424"
"138.20000","184.26933","3.06559"
"138.30000","184.40268","3.07387"
"138.40000","184.53607","3.07148"
"138.50000","184.66940","3.07700"
"138.60000","184.80264","3.06860"
"138.70000","184.93608","3.07424"
"138.80000","185.06941","3.07851"
"138.90000","185.20268","3.08584"
"139.00000","185.33604","3.08447"
"139.10000","185.46931","3.07487"
"139.20000","185.60277","3.08265"
"139.30000","185.73604","3.07562"
"139.40000","185.86932","3.08610"
"139.50000","186.00284","3.07870"
"139.60000","186.13605","3.07713"
"139.70000","186.26932","3.07895"
"139.80000","186.40266","3.08258"
"139.90000","186.53595","3.07995"
"140.00000","186.66939","3.08760"
"140.10000","186.80273","3.08817"
"140.20000","186.93596","3.08948"
"140.30000","187.06941","3.08898"
"140.40000","187.20270","3.08829"
"140.50000","187.33603","3.09143"
"140.60000","187.46928","3.08967"
"140.70000","187.60269","3.08008"
"140.80000","187.73598","3.09017"
"140.90000","187.86943","3.08647"
"141.00000","188.00270","3.09607"
"141.10000","188.13594","3.08804"
"141.20000","188.26944","3.09174"
"141.30000","188.40276","3.09745"
"141.40000","188.53604","3.09745"
"141.50000","188.66940","3.09005"
"141.60000","188.80266","3.08748"
"141.70000","188.93599","3.09450"
"141.80000","189.06940","3.10052"
"141.90000","189.20261","3.08810"
"142.00000","189.33594","3.09776"
"142.10000","189.46939","3.09218"
"142.20000","189.60275","3.09180"
"142.30000","189.73602","3.09030"
"142.40000","189.86940","3.09293"
"142.50000","190.00264","3.09287"
"142.60000","190.13608","3.08685"
"142.70000","190.26942","3.08835"
"142.80000","190.40259","3.09895"
"142.90000","190.53616","3.09356"
"143.00000","190.66937","3.10152"
"143.10000","190.80266","3.09174"
"143.20000","190.93605","3.09067"
"143.30000","191.06932","3.09525"
"143.40000","191.20267","3.09293"
"143.50000","191.33600","3.08616"
"143.60000","191.46935","3.09845"
"143.70000","191.60269","3.09487"
"143.80000","191.73613","3.08973"
"143.90000","191.86942","3.09406"
"144.00000","192.00269","3.09055"
"144.10000","192.13602","3.09017"
"144.20000","192.26932","3.09005"
"144.30000","192.40263","3.08804"
"144.40000","192.53604","3.08666"
"144.50000","192.66925","3.08227"
"144.60000","192.80283","3.08641"
"144.70000","192.93605","3.09418"
"144.80000","193.06934","3.08691"
"144.90000","193.20271","3.09186"
"145.00000","193.33601","3.08352"
"145.10000","193.46939","3.08008"
"145.20000","193.60274","3.08722"
"145.30000","193.73602","3.08089"
"145.40000","193.86929","3.07776"
"145.50000","194.00269","3.07876"
"145.60000","194.13597","3.07550"
"145.70000","194.26930","3.06841"
"145.80000","194.40269","3.06490"
"145.90000","194.53598","3.06603"
"146.00000","194.66948","3.05299"
"146.08600","194.78404","0.53132"
"146.18600","194.91734","0.22500"
"146.28600","195.05075","0.21283"
"146.38600","195.18402","0.22337"
"146.48600","195.31734","0.21521"
"146.58600","195.45070","0.22080"
"146.68600","195.58401","0.21666"
"146.78600","195.71736","0.21101"
"146.88600","195.85074","0.21164"
"146.98600","195.98402","0.21609"
"147.08600","196.11725","0.21170"
"147.18600","196.25069","0.22117"
"147.28600","196.38405","0.21220"
"147.38600","196.51743","0.21741"
"147.48600","196.65065","0.21553"
"147.58600","196.78400","0.21384"
"147.68600","196.91739","0.21647"
"147.78600","197.05080","0.21572"
"147.88600","197.18393","0.21471"
"147.98600","197.31734","0.21057"
"148.08600","197.45074","0.21108"
"148.18600","197.58401","0.22330"
"148.28600","197.71732","0.22525"
"148.38600","197.85069","0.22123"
"148.48600","197.98404","0.22450"
"148.58600","198.11736","0.22406"
"148.68600","198.25072","0.21866"
"148.78600","198.38399","0.22613"
"148.88600","198.51744","0.22192"
"148.98600","198.65071","0.22794"
"149.08600","198.78404","0.22450"
"149.18600","198.91731","0.22989"
"149.28600","199.05060","0.22293"
"149.38600","199.18405","0.22544"
"149.42400","199.23471","0.23296"