File: data/class3/Specimen_RawData_13.csv
Time,Extension,Load
(s),(mm),(N)
"0.00000","0.00000","-0.00344"
"0.10000","0.12926","-0.01003"
"0.20000","0.26871","0.00784"
"0.30000","0.40250","0.00765"
"0.40000","0.53601","0.02020"
"0.50000","0.66929","0.03462"
"0.60000","0.80263","0.04622"
"0.70000","0.93596","0.05218"
"0.80000","1.06930","0.06014"
"0.90000","1.20269","0.07318"
"1.00000","1.33597","0.08842"
"1.10000","1.46931","0.09476"
"1.20000","1.60265","0.09952"
"1.30000","1.73598","0.11777"
"1.40000","1.86926","0.12084"
"1.50000","2.00254","0.13388"
"1.60000","2.13605","0.14762"
"1.70000","2.26922","0.14398"
"1.80000","2.40267","0.16304"
"1.90000","2.53595","0.18066"
"2.00000","2.66928","0.18806"
"2.10000","2.80262","0.19145"
"2.20000","2.93596","0.20148"
"2.30000","3.06929","0.21045"
"2.40000","3.20269","0.22299"
"2.50000","3.33597","0.23560"
"2.60000","3.46936","0.24350"
"2.70000","3.60264","0.25315"
"2.80000","3.73592","0.25510"
"2.90000","3.86926","0.26839"
"3.00000","4.00265","0.27579"
"3.10000","4.13593","0.27912"
"3.20000","4.26915","0.29655"
"3.30000","4.40266","0.30865"
"3.40000","4.53594","0.31335"
"3.50000","4.66933","0.32251"
"3.60000","4.80261","0.33800"
"3.70000","4.93589","0.34464"
"3.80000","5.06934","0.35951"
"3.90000","5.20268","0.35775"
"4.00000","5.33596","0.36308"
"4.10000","5.46935","0.37217"
"4.20000","5.60263","0.39375"
"4.30000","5.73597","0.39795"
"4.40000","5.86925","0.39933"
"4.50000","6.00259","0.41318"
"4.60000","6.13598","0.42046"
"4.70000","6.26932","0.42058"
"4.80000","6.40265","0.44347"
"4.90000","6.53582","0.44385"
"5.00000","6.66938","0.45695"
"5.10000","6.80261","0.46084"
"5.20000","6.93600","0.47207"
"5.30000","7.06928","0.47846"
"5.40000","7.20262","0.48273"
"5.50000","7.33595","0.49401"
"5.60000","7.46929","0.50261"
"5.70000","7.60263","0.51182"
"5.80000","7.73596","0.51559"
"5.90000","7.86930","0.52694"
"6.00000","8.00264","0.53133"
"6.10000","8.13597","0.53722"
"6.20000","8.26937","0.54857"
"6.30000","8.40259","0.56036"
"6.40000","8.53604","0.56901"
"6.50000","8.66926","0.56600"
"6.60000","8.80249","0.58099"
"6.70000","8.93599","0.58024"
"6.80000","9.06922","0.58544"
"6.90000","9.20267","0.60601"
"7.00000","9.33595","0.60946"
"7.10000","9.46928","0.61535"
"7.20000","9.60262","0.61999"
"7.30000","9.73596","0.61981"
"7.40000","9.86929","0.63285"
"7.50000","10.00268","0.63774"
"7.60000","10.13602","0.65317"
"7.70000","10.26936","0.66395"
"7.80000","10.40258","0.67254"
"7.90000","10.53592","0.67537"
"8.00000","10.66920","0.68176"
"8.10000","10.80259","0.67612"
"8.20000","10.93593","0.69349"
"8.30000","11.06921","0.69474"
"8.40000","11.20277","0.70860"
"8.50000","11.33594","0.71976"
"8.60000","11.46933","0.72610"
"8.70000","11.60256","0.72547"
"8.80000","11.73589","0.73362"
"8.90000","11.86923","0.73632"
"9.00000","12.00262","0.74152"
"9.10000","12.13596","0.74842"
"9.20000","12.26935","0.76090"
"9.30000","12.40269","0.76084"
"9.40000","12.53591","0.76767"
"9.50000","12.66931","0.77407"
"9.60000","12.80258","0.78523"
"9.70000","12.93598","0.78755"
"9.80000","13.06932","0.80040"
"9.90000","13.20260","0.80147"
"10.00000","13.33582","0.81476"
"10.10000","13.46938","0.81113"
"10.20000","13.60255","0.81765"
"10.30000","13.73594","0.82078"
"10.40000","13.86928","0.83477"
"10.50000","14.00256","0.83746"
"10.60000","14.13601","0.84649"
"10.70000","14.26929","0.84806"
"10.80000","14.40268","0.85471"
"10.90000","14.53596","0.85628"
"11.00000","14.66930","0.86807"
"11.10000","14.80258","0.87848"
"11.20000","14.93592","0.88537"
"11.30000","15.06931","0.88888"
"11.40000","15.20265","0.89384"
"11.50000","15.33604","0.89653"
"11.60000","15.46932","0.89842"
"11.70000","15.60249","0.91441"
"11.80000","15.73605","0.91240"
"11.90000","15.86922","0.92469"
"12.00000","16.00266","0.92927"
"12.10000","16.13595","0.92507"
"12.20000","16.26928","0.93786"
"12.30000","16.40273","0.93573"
"12.40000","16.53596","0.95222"
"12.50000","16.66929","0.95153"
"12.60000","16.80268","0.95912"
"12.70000","16.93596","0.95899"
"12.80000","17.06930","0.97774"
"12.90000","17.20258","0.97787"
"13.00000","17.33598","0.97956"
"13.10000","17.46926","0.98796"
"13.20000","17.60259","0.98771"
"13.30000","17.73593","0.99436"
"13.40000","17.86921","1.00239"
"13.50000","18.00271","1.00527"
"13.60000","18.13599","1.01374"
"13.70000","18.26939","1.01863"
"13.80000","18.40261","1.01938"
"13.90000","18.53584","1.02157"
"14.00000","18.66928","1.03010"
"14.10000","18.80256","1.03487"
"14.20000","18.93590","1.04020"
"14.30000","19.06935","1.05130"
"14.40000","19.20263","1.05368"
"14.50000","19.33597","1.05299"
"14.60000","19.46936","1.06415"
"14.70000","19.60253","1.05788"
"14.80000","19.73592","1.07036"
"14.90000","19.86932","1.07400"
"15.00000","20.00254","1.07262"
"15.10000","20.13588","1.08547"
"15.20000","20.26938","1.08905"
"15.30000","20.40261","1.09595"
"15.40000","20.53600","1.10033"
"15.50000","20.66934","1.10667"
"15.60000","20.80256","1.10962"
"15.70000","20.93607","1.11043"
"15.80000","21.06929","1.11996"
"15.90000","21.20262","1.11727"
"16.00000","21.33596","1.11940"
"16.10000","21.46930","1.12529"
"16.20000","21.60258","1.13765"
"16.30000","21.73597","1.13476"
"16.40000","21.86931","1.13451"
"16.50000","22.00265","1.14273"
"16.60000","22.13604","1.15244"
"16.70000","22.26932","1.16693"
"16.80000","22.40260","1.16323"
"16.90000","22.53599","1.17239"
"17.00000","22.66921","1.17101"
"17.10000","22.80267","1.17678"
"17.20000","22.93594","1.18443"
"17.30000","23.06923","1.18831"
"17.40000","23.20267","1.19377"
"17.50000","23.33596","1.19302"
"17.60000","23.46924","1.19421"
"17.70000","23.60257","1.19828"
"17.80000","23.73597","1.19910"
"17.90000","23.86925","1.21258"
"18.00000","24.00264","1.21032"
"18.10000","24.13597","1.21177"
"18.20000","24.26920","1.22274"
"18.30000","24.40259","1.23152"
"18.40000","24.53593","1.23233"
"18.50000","24.66921","1.23403"
"18.60000","24.80266","1.23296"
"18.70000","24.93594","1.24318"
"18.80000","25.06939","1.24557"
"18.90000","25.20261","1.24249"
"19.00000","25.33595","1.24851"
"19.10000","25.46934","1.25955"
"19.20000","25.60251","1.26331"
"19.30000","25.73596","1.26381"
"19.40000","25.86930","1.25905"
"19.50000","26.00263","1.27403"
"19.60000","26.13597","1.27767"
"19.70000","26.26930","1.28463"
"19.80000","26.40264","1.28689"
"19.90000","26.53592","1.28582"
"20.00000","26.66926","1.29479"
"20.10000","26.80254","1.30232"
"20.20000","26.93593","1.30207"
"20.30000","27.06933","1.29655"
"20.40000","27.20261","1.30721"
"20.50000","27.33600","1.31511"
"20.60000","27.46934","1.31705"
"20.70000","27.60250","1.31486"
"20.80000","27.73606","1.31605"
"20.90000","27.86929","1.33398"
"21.00000","28.00274","1.32533"
"21.10000","28.13596","1.33380"
"21.20000","28.26924","1.33881"
"21.30000","28.40264","1.33668"
"21.40000","28.53597","1.34928"
"21.50000","28.66925","1.34803"
"21.60000","28.80259","1.34446"
"21.70000","28.93604","1.34822"
"21.80000","29.06932","1.35480"
"21.90000","29.20260","1.36289"
"22.00000","29.33599","1.36195"
"22.10000","29.46927","1.36371"
"22.20000","29.60261","1.36063"
"22.30000","29.73589","1.37224"
"22.40000","29.86923","1.38114"
"22.50000","30.00268","1.37963"
"22.60000","30.13601","1.38421"
"22.70000","30.26924","1.38459"
"22.80000","30.40263","1.38860"
"22.90000","30.53596","1.40139"
"23.00000","30.66930","1.39337"
"23.10000","30.80264","1.40177"
"23.20000","30.93592","1.40133"
"23.30000","31.06931","1.40516"
"23.40000","31.20271","1.42322"
"23.50000","31.33598","1.41651"
"23.60000","31.46926","1.41745"
"23.70000","31.60266","1.42591"
"23.80000","31.73594","1.42911"
"23.90000","31.86933","1.41814"
"24.00000","32.00261","1.42754"
"24.10000","32.13589","1.42610"
"24.20000","32.26934","1.44535"
"24.30000","32.40262","1.43469"
"24.40000","32.53595","1.44422"
"24.50000","32.66930","1.43262"
"24.60000","32.80257","1.44429"
"24.70000","32.93591","1.45212"
"24.80000","33.06936","1.44974"
"24.90000","33.20258","1.45902"
"25.00000","33.33598","1.45764"
"25.10000","33.46931","1.46473"
"25.20000","33.60260","1.46034"
"25.30000","33.73593","1.46786"
"25.40000","33.86932","1.46241"
"25.50000","34.00260","1.46492"
"25.60000","34.13600","1.47658"
"25.70000","34.26928","1.48084"
"25.80000","34.40250","1.49044"
"25.90000","34.53601","1.48962"
"26.00000","34.66923","1.48793"
"26.10000","34.80262","1.48222"
"26.20000","34.93596","1.49840"
"26.30000","35.06930","1.49464"
"26.40000","35.20263","1.50053"
"26.50000","35.33597","1.49426"
"26.60000","35.46931","1.50762"
"26.70000","35.60259","1.51333"
"26.80000","35.73603","1.50260"
"26.90000","35.86926","1.52581"
"27.00000","36.00260","1.51646"
"27.10000","36.13599","1.51803"
"27.20000","36.26927","1.52167"
"27.30000","36.40266","1.53095"
"27.40000","36.53600","1.53239"
"27.50000","36.66917","1.53295"
"27.60000","36.80268","1.53013"
"27.70000","36.93596","1.52719"
"27.80000","37.06929","1.54305"
"27.90000","37.20263","1.53490"
"28.00000","37.33591","1.53897"
"28.10000","37.46925","1.54725"
"28.20000","37.60264","1.54800"
"28.30000","37.73592","1.55007"
"28.40000","37.86926","1.54857"
"28.50000","38.00270","1.55848"
"28.60000","38.13598","1.55848"
"28.70000","38.26932","1.56080"
"28.80000","38.40260","1.56155"
"28.90000","38.53588","1.57603"
"29.00000","38.66933","1.57898"
"29.10000","38.80261","1.57597"
"29.20000","38.93589","1.57503"
"29.30000","39.06940","1.58807"
"29.40000","39.20261","1.59014"
"29.50000","39.33596","1.58375"
"29.60000","39.46923","1.58989"
"29.70000","39.60257","1.59447"
"29.80000","39.73590","1.59504"
"29.90000","39.86930","1.60682"
"30.00000","40.00264","1.59729"
"30.10000","40.13604","1.60187"
"30.20000","40.26931","1.61404"
"30.30000","40.40265","1.60921"
"30.40000","40.53599","1.60639"
"30.50000","40.66926","1.61422"
"30.60000","40.80255","1.61529"
"30.70000","40.93594","1.62476"
"30.80000","41.06927","1.62313"
"30.90000","41.20250","1.62344"
"31.00000","41.33606","1.61761"
"31.10000","41.46923","1.63642"
"31.20000","41.60262","1.63435"
"31.30000","41.73590","1.63297"
"31.40000","41.86924","1.62965"
"31.50000","42.00263","1.63272"
"31.60000","42.13603","1.64119"
"31.70000","42.26931","1.64326"
"31.80000","42.40259","1.64376"
"31.90000","42.53598","1.64815"
"32.00000","42.66926","1.65693"
"32.10000","42.80265","1.65273"
"32.20000","42.93593","1.65517"
"32.30000","43.06927","1.65511"
"32.40000","43.20272","1.65505"
"32.50000","43.33600","1.66132"
"32.60000","43.46911","1.66608"
"32.70000","43.60268","1.67605"
"32.80000","43.73590","1.67624"
"32.90000","43.86924","1.66947"
"33.00000","44.00263","1.67474"
"33.10000","44.13597","1.67662"
"33.20000","44.26936","1.67724"
"33.30000","44.40263","1.67637"
"33.40000","44.53592","1.68295"
"33.50000","44.66925","1.68101"
"33.60000","44.80270","1.68314"
"33.70000","44.93598","1.68872"
"33.80000","45.06927","1.69675"
"33.90000","45.20266","1.69104"
"34.00000","45.33599","1.69838"
"34.10000","45.46928","1.69581"
"34.20000","45.60261","1.70233"
"34.30000","45.73584","1.70114"
"34.40000","45.86940","1.70659"
"34.50000","46.00268","1.70515"
"34.60000","46.13601","1.71656"
"34.70000","46.26929","1.71412"
"34.80000","46.40257","1.71481"
"34.90000","46.53591","1.71838"
"35.00000","46.66925","1.72641"
"35.10000","46.80258","1.71775"
"35.20000","46.93592","1.72503"
"35.30000","47.06931","1.72534"
"35.40000","47.20265","1.72854"
"35.50000","47.33604","1.72935"
"35.60000","47.46927","1.73688"
"35.70000","47.60255","1.73682"
"35.80000","47.73600","1.73782"
"35.90000","47.86928","1.73425"
"36.00000","48.00249","1.73763"
"36.10000","48.13612","1.74848"
"36.20000","48.26929","1.74741"
"36.30000","48.40262","1.74384"
"36.40000","48.53590","1.75494"
"36.50000","48.66924","1.76008"
"36.60000","48.80264","1.75864"
"36.70000","48.93597","1.76378"
"36.80000","49.06925","1.77143"
"36.90000","49.20264","1.76573"
"37.00000","49.33598","1.77739"
"37.10000","49.46921","1.77306"
"37.20000","49.60265","1.77030"
"37.30000","49.73599","1.77764"
"37.40000","49.86927","1.79144"
"37.50000","50.00266","1.77927"
"37.60000","50.13600","1.78397"
"37.70000","50.26922","1.78284"
"37.80000","50.40268","1.77632"
"37.90000","50.53595","1.78617"
"38.00000","50.66924","1.79683"
"38.10000","50.80263","1.79175"
"38.20000","50.93585","1.79608"
"38.30000","51.06936","1.79294"
"38.40000","51.20269","1.79438"
"38.50000","51.33603","1.80316"
"38.60000","51.46920","1.80322"
"38.70000","51.60265","1.80975"
"38.80000","51.73593","1.80260"
"38.90000","51.86927","1.80962"
"39.00000","52.00260","1.82091"
"39.10000","52.13588","1.81740"
"39.20000","52.26933","1.81332"
"39.30000","52.40261","1.82185"
"39.40000","52.53583","1.81633"
"39.50000","52.66940","1.82066"
"39.60000","52.80262","1.82429"
"39.70000","52.93601","1.83314"
"39.80000","53.06929","1.82693"
"39.90000","53.20258","1.83746"
"40.00000","53.33603","1.82524"
"40.10000","53.46930","1.83809"
"40.20000","53.60258","1.84116"
"40.30000","53.73592","1.83627"
"40.40000","53.86937","1.83922"
"40.50000","54.00259","1.84555"
"40.60000","54.13593","1.84605"
"40.70000","54.26932","1.85615"
"40.80000","54.40255","1.84863"
"40.90000","54.53594","1.85232"
"41.00000","54.66928","1.86123"
"41.10000","54.80244","1.85703"
"41.20000","54.93607","1.86173"
"41.30000","55.06929","1.85885"
"41.40000","55.20268","1.86763"
"41.50000","55.33602","1.86142"
"41.60000","55.46924","1.86775"
"41.70000","55.60263","1.86543"
"41.80000","55.73602","1.87346"
"41.90000","55.86930","1.87189"
"42.00000","56.00264","1.87477"
"42.10000","56.13598","1.87327"
"42.20000","56.26926","1.87854"
"42.30000","56.40265","1.88537"
"42.40000","56.53594","1.87979"
"42.50000","56.66921","1.87760"
"42.60000","56.80267","1.88330"
"42.70000","56.93600","1.89114"
"42.80000","57.06917","1.89584"
"42.90000","57.20273","1.89302"
"43.00000","57.33590","1.89058"
"43.10000","57.46929","1.90826"
"43.20000","57.60257","1.91089"
"43.30000","57.73597","1.90337"
"43.40000","57.86930","1.91334"
"43.50000","58.00270","1.90099"
"43.60000","58.13603","1.90813"
"43.70000","58.26931","1.91911"
"43.80000","58.40265","1.91196"
"43.90000","58.53587","1.91930"
"44.00000","58.66926","1.90669"
"44.10000","58.80266","1.91748"
"44.20000","58.93588","1.92851"
"44.30000","59.06927","1.92005"
"44.40000","59.20267","1.92989"
"44.50000","59.33589","1.92419"
"44.60000","59.46934","1.92776"
"44.70000","59.60262","1.93767"
"44.80000","59.73602","1.93328"
"44.90000","59.86929","1.94281"
"45.00000","60.00257","1.93297"
"45.10000","60.13602","1.94030"
"45.20000","60.26925","1.95115"
"45.30000","60.40258","1.94777"
"45.40000","60.53592","1.95585"
"45.50000","60.66932","1.95310"
"45.60000","60.80265","1.95604"
"45.70000","60.93599","1.95535"
"45.80000","61.06932","1.94952"
"45.90000","61.20255","1.95654"
"46.00000","61.33605","1.95786"
"46.10000","61.46922","1.96438"
"46.20000","61.60250","1.96432"
"46.30000","61.73601","1.96764"
"46.40000","61.86929","1.96946"
"46.50000","62.00268","1.96702"
"46.60000","62.13591","1.97561"
"46.70000","62.26924","1.97943"
"46.80000","62.40269","1.97580"
"46.90000","62.53596","1.97454"
"47.00000","62.66925","1.98664"
"47.10000","62.80258","1.98225"
"47.20000","62.93603","1.98414"
"47.30000","63.06931","1.98940"
"47.40000","63.20265","1.98238"
"47.50000","63.33593","1.99436"
"47.60000","63.46921","1.99141"
"47.70000","63.60271","1.99480"
"47.80000","63.73594","1.99323"
"47.90000","63.86922","1.99643"
"48.00000","64.00273","2.00126"
"48.10000","64.13596","2.00477"
"48.20000","64.26929","2.00627"
"48.30000","64.40263","2.00339"
"48.40000","64.53590","2.01925"
"48.50000","64.66930","2.01198"
"48.60000","64.80264","2.01254"
"48.70000","64.93603","2.01888"
"48.80000","65.06931","2.01932"
"48.90000","65.20270","2.02019"
"49.00000","65.33598","2.01856"
"49.10000","65.46926","2.02822"
"49.20000","65.60265","2.02364"
"49.30000","65.73588","2.02941"
"49.40000","65.86932","2.02753"
"49.50000","66.00261","2.02734"
"49.60000","66.13589","2.02878"
"49.70000","66.26934","2.03355"
"49.80000","66.40261","2.02797"
"49.90000","66.53590","2.04064"
"50.00000","66.66930","2.04038"
"50.10000","66.80257","2.04032"
"50.20000","66.93597","2.04371"
"50.30000","67.06930","2.04446"
"50.40000","67.20264","2.03669"
"50.50000","67.33592","2.04753"
"50.60000","67.46925","2.05330"
"50.70000","67.60259","2.04841"
"50.80000","67.73592","2.05851"
"50.90000","67.86926","2.05199"
"51.00000","68.00254","2.05600"
"51.10000","68.13599","2.06114"
"51.20000","68.26933","2.06484"
"51.30000","68.40261","2.06214"
"51.40000","68.53595","2.06478"
"51.50000","68.66923","2.07092"
"51.60000","68.80262","2.06904"
"51.70000","68.93596","2.07161"
"51.80000","69.06918","2.07663"
"51.90000","69.20269","2.08334"
"52.00000","69.33597","2.07381"
"52.10000","69.46925","2.08472"
"52.20000","69.60252","2.08334"
"52.30000","69.73598","2.09024"
"52.40000","69.86932","2.08723"
"52.50000","70.00266","2.09143"
"52.60000","70.13599","2.09645"
"52.70000","70.26921","2.09030"
"52.80000","70.40272","2.09300"
"52.90000","70.53600","2.09174"
"53.00000","70.66928","2.10008"
"53.10000","70.80267","2.09657"
"53.20000","70.93595","2.09864"
"53.30000","71.06928","2.10303"
"53.40000","71.20268","2.09895"
"53.50000","71.33585","2.10422"
"53.60000","71.46935","2.10491"
"53.70000","71.60264","2.10617"
"53.80000","71.73597","2.11507"
"53.90000","71.86926","2.11256"
"54.00000","72.00270","2.12122"
"54.10000","72.13593","2.11563"
"54.20000","72.26932","2.12429"
"54.30000","72.40260","2.11883"
"54.40000","72.53588","2.12122"
"54.50000","72.66933","2.12316"
"54.60000","72.80255","2.12774"
"54.70000","72.93589","2.12278"
"54.80000","73.06934","2.12805"
"54.90000","73.20267","2.12636"
"55.00000","73.33590","2.12943"
"55.10000","73.46924","2.12705"
"55.20000","73.60252","2.13570"
"55.30000","73.73602","2.13821"
"55.40000","73.86930","2.14417"
"55.50000","74.00264","2.13808"
"55.60000","74.13593","2.13244"
"55.70000","74.26931","2.13996"
"55.80000","74.40260","2.14222"
"55.90000","74.53593","2.13990"
"56.00000","74.66933","2.14975"
"56.10000","74.80255","2.15382"
"56.20000","74.93600","2.16292"
"56.30000","75.06933","2.15821"
"56.40000","75.20267","2.16066"
"56.50000","75.33595","2.16436"
"56.60000","75.46928","2.16185"
"56.70000","75.60262","2.16442"
"56.80000","75.73595","2.16185"
"56.90000","75.86918","2.16304"
"57.00000","76.00275","2.16141"
"57.10000","76.13602","2.17715"
"57.20000","76.26931","2.17439"
"57.30000","76.40258","2.16292"
"57.40000","76.53593","2.18022"
"57.50000","76.66926","2.17746"
"57.60000","76.80260","2.17057"
"57.70000","76.93593","2.17401"
"57.80000","77.06921","2.18424"
"57.90000","77.20266","2.18154"
"58.00000","77.33594","2.18631"
"58.10000","77.46922","2.19258"
"58.20000","77.60262","2.19001"
"58.30000","77.73595","2.19841"
"58.40000","77.86935","2.19646"
"58.50000","78.00262","2.19195"
"58.60000","78.13591","2.18424"
"58.70000","78.26936","2.20079"
"58.80000","78.40264","2.19941"
"58.90000","78.53587","2.19678"
"59.00000","78.66925","2.21245"
"59.10000","78.80258","2.21101"
"59.20000","78.93598","2.20850"
"59.30000","79.06931","2.21139"
"59.40000","79.20265","2.21797"
"59.50000","79.33588","2.21145"
"59.60000","79.46932","2.21409"
"59.70000","79.60261","2.21308"
"59.80000","79.73593","2.21496"
"59.90000","79.86934","2.21597"
"60.00000","80.00266","2.22675"
"60.10000","80.13596","2.22468"
"60.20000","80.26929","2.23265"
"60.30000","80.40251","2.22932"
"60.40000","80.53602","2.22042"
"60.50000","80.66930","2.22217"
"60.60000","80.80264","2.23001"
"60.70000","80.93592","2.23139"
"60.80000","81.06931","2.22976"
"60.90000","81.20265","2.23183"
"61.00000","81.33593","2.24381"
"61.10000","81.46927","2.23465"
"61.20000","81.60260","2.24186"
"61.30000","81.73600","2.24462"
"61.40000","81.86928","2.23804"
"61.50000","82.00261","2.25340"
"61.60000","82.13595","2.25077"
"61.70000","82.26923","2.24456"
"61.80000","82.40262","2.25823"
"61.90000","82.53590","2.24939"
"62.00000","82.66918","2.25221"
"62.10000","82.80263","2.25604"
"62.20000","82.93603","2.25817"
"62.30000","83.06936","2.25967"
"62.40000","83.20264","2.26043"
"62.50000","83.33587","2.25917"
"62.60000","83.46925","2.26093"
"62.70000","83.60265","2.26494"
"62.80000","83.73598","2.27046"
"62.90000","83.86921","2.26375"
"63.00000","84.00266","2.27428"
"63.10000","84.13594","2.27052"
"63.20000","84.26928","2.27146"
"63.30000","84.40267","2.27052"
"63.40000","84.53590","2.27466"
"63.50000","84.66929","2.28068"
"63.60000","84.80267","2.28081"
"63.70000","84.93584","2.27974"
"63.80000","85.06936","2.27422"
"63.90000","85.20264","2.28200"
"64.00000","85.33591","2.28513"
"64.10000","85.46925","2.28927"
"64.20000","85.60264","2.29498"
"64.30000","85.73598","2.29241"
"64.40000","85.86932","2.29278"
"64.50000","86.00266","2.29874"
"64.60000","86.13587","2.29209"
"64.70000","86.26939","2.29680"
"64.80000","86.40260","2.29623"
"64.90000","86.53589","2.30068"
"65.00000","86.66928","2.30363"
"65.10000","86.80256","2.31122"
"65.20000","86.93601","2.30438"
"65.30000","87.06935","2.31235"
"65.40000","87.20252","2.31022"
"65.50000","87.33597","2.31818"
"65.60000","87.46936","2.31354"
"65.70000","87.60263","2.31329"
"65.80000","87.73592","2.30551"
"65.90000","87.86932","2.32351"
"66.00000","88.00266","2.31705"
"66.10000","88.13598","2.32370"
"66.20000","88.26933","2.31918"
"66.30000","88.40255","2.33436"
"66.40000","88.53606","2.31925"
"66.50000","88.66922","2.31837"
"66.60000","88.80261","2.32602"
"66.70000","88.93595","2.32288"
"66.80000","89.06923","2.32677"
"66.90000","89.20261","2.33047"
"67.00000","89.33596","2.33066"
"67.10000","89.46912","2.33887"
"67.20000","89.60268","2.33963"
"67.30000","89.73597","2.34282"
"67.40000","89.86931","2.33862"
"67.50000","90.00264","2.34276"
"67.60000","90.13598","2.33699"
"67.70000","90.26931","2.33944"
"67.80000","90.40260","2.34395"
"67.90000","90.53593","2.34978"
"68.00000","90.66921","2.35047"
"68.10000","90.80266","2.34634"
"68.20000","90.93594","2.34615"
"68.30000","91.06927","2.34822"
"68.40000","91.20267","2.35618"
"68.50000","91.33589","2.35549"
"68.60000","91.46935","2.36408"
"68.70000","91.60268","2.36847"
"68.80000","91.73591","2.37217"
"68.90000","91.86935","2.36515"
"69.00000","92.00264","2.36634"
"69.10000","92.13591","2.36653"
"69.20000","92.26930","2.37825"
"69.30000","92.40253","2.36816"
"69.40000","92.53592","2.37368"
"69.50000","92.66936","2.38082"
"69.60000","92.80265","2.37524"
"69.70000","92.93594","2.37512"
"69.80000","93.06938","2.38283"
"69.90000","93.20261","2.37418"
"70.00000","93.33589","2.38239"
"70.10000","93.46922","2.38910"
"70.20000","93.60255","2.38220"
"70.30000","93.73602","2.38923"
"70.40000","93.86935","2.38521"
"70.50000","94.00246","2.38183"
"70.60000","94.13602","2.38396"
"70.70000","94.26936","2.39832"
"70.80000","94.40258","2.39656"
"70.90000","94.53591","2.39243"
"71.00000","94.66920","2.39192"
"71.10000","94.80264","2.39462"
"71.20000","94.93597","2.40070"
"71.30000","95.06933","2.41230"
"71.40000","95.20255","2.40233"
"71.50000","95.33605","2.40748"
"71.60000","95.46928","2.40716"
"71.70000","95.60261","2.39757"
"71.80000","95.73595","2.40516"
"71.90000","95.86922","2.41350"
"72.00000","96.00268","2.41055"
"72.10000","96.13596","2.41155"
"72.20000","96.26917","2.41481"
"72.30000","96.40263","2.40340"
"72.40000","96.53597","2.41412"
"72.50000","96.66931","2.41820"
"72.60000","96.80264","2.41820"
"72.70000","96.93592","2.42497"
"72.80000","97.06931","2.43268"
"72.90000","97.20265","2.42108"
"73.00000","97.33594","2.42829"
"73.10000","97.46920","2.42610"
"73.20000","97.60267","2.42516"
"73.30000","97.73593","2.44159"
"73.40000","97.86927","2.43870"
"73.50000","98.00266","2.43977"
"73.60000","98.13589","2.43601"
"73.70000","98.26934","2.43645"
"73.80000","98.40262","2.44234"
"73.90000","98.53585","2.44410"
"74.00000","98.66930","2.44497"
"74.10000","98.80264","2.43732"
"74.20000","98.93592","2.45212"
"74.30000","99.06925","2.45081"
"74.40000","99.20258","2.44949"
"74.50000","99.33591","2.44886"
"74.60000","99.46931","2.45451"
"74.70000","99.60265","2.45156"
"74.80000","99.73587","2.45808"
"74.90000","99.86933","2.45727"
"75.00000","100.00266","2.45570"
"75.10000","100.13599","2.45802"
"75.20000","100.26933","2.45789"
"75.30000","100.40250","2.46429"
"75.40000","100.53596","2.46416"
"75.50000","100.66930","2.46435"
"75.60000","100.80252","2.46554"
"75.70000","100.93603","2.46680"
"75.80000","101.06929","2.47714"
"75.90000","101.20258","2.46416"
"76.00000","101.33591","2.47213"
"76.10000","101.46920","2.48028"
"76.20000","101.60259","2.47451"
"76.30000","101.73598","2.47777"
"76.40000","101.86932","2.47119"
"76.50000","102.00261","2.47489"
"76.60000","102.13599","2.49113"
"76.70000","102.26928","2.48235"
"76.80000","102.40260","2.48599"
"76.90000","102.53594","2.49182"
"77.00000","102.66923","2.48730"
"77.10000","102.80263","2.48197"
"77.20000","102.93584","2.49270"
"77.30000","103.06929","2.49596"
"77.40000","103.20263","2.49809"
"77.50000","103.33597","2.49903"
"77.60000","103.46925","2.49257"
"77.70000","103.60264","2.49320"
"77.80000","103.73598","2.49665"
"77.90000","103.86932","2.50856"
"78.00000","104.00259","2.50003"
"78.10000","104.13599","2.50166"
"78.20000","104.26927","2.49871"
"78.30000","104.40266","2.50336"
"78.40000","104.53600","2.50392"
"78.50000","104.66927","2.50988"
"78.60000","104.80261","2.51458"
"78.70000","104.93590","2.51652"
"78.80000","105.06934","2.51445"
"78.90000","105.20263","2.51728"
"79.00000","105.33590","2.51803"
"79.10000","105.46936","2.51696"
"79.20000","105.60263","2.52123"
"79.30000","105.73596","2.51740"
"79.40000","105.86925","2.52612"
"79.50000","106.00265","2.52744"
"79.60000","106.13598","2.52813"
"79.70000","106.26926","2.52963"
"79.80000","106.40260","2.52994"
"79.90000","106.53588","2.53182"
"80.00000","106.66938","2.54600"
"80.10000","106.80261","2.53264"
"80.20000","106.93595","2.53922"
"80.30000","107.06934","2.53314"
"80.40000","107.20250","2.54255"
"80.50000","107.33595","2.54211"
"80.60000","107.46930","2.54393"
"80.70000","107.60257","2.54205"
"80.80000","107.73596","2.54437"
"80.90000","107.86930","2.54311"
"81.00000","108.00264","2.55039"
"81.10000","108.13598","2.54481"
"81.20000","108.26926","2.55208"
"81.30000","108.40266","2.54637"
"81.40000","108.53593","2.54788"
"81.50000","108.66933","2.55327"
"81.60000","108.80254","2.54750"
"81.70000","108.93599","2.56224"
"81.80000","109.06934","2.55434"
"81.90000","109.20255","2.55735"
"82.00000","109.33595","2.56048"
"82.10000","109.46922","2.56619"
"82.20000","109.60268","2.55841"
"82.30000","109.73602","2.55659"
"82.40000","109.86924","2.56287"
"82.50000","110.00257","2.56562"
"82.60000","110.13590","2.56807"
"82.70000","110.26925","2.57258"
"82.80000","110.40253","2.56725"
"82.90000","110.53592","2.56744"
"83.00000","110.66931","2.56544"
"83.10000","110.80259","2.56851"
"83.20000","110.93604","2.57045"
"83.30000","111.06921","2.58055"
"83.40000","111.20260","2.57033"
"83.50000","111.33595","2.57478"
"83.60000","111.46928","2.57296"
"83.70000","111.60273","2.57610"
"83.80000","111.73589","2.58118"
"83.90000","111.86929","2.57892"
"84.00000","112.00268","2.57503"
"84.10000","112.13590","2.58230"
"84.20000","112.26929","2.58864"
"84.30000","112.40258","2.58469"
"84.40000","112.53596","2.58331"
"84.50000","112.66924","2.58506"
"84.60000","112.80260","2.58676"
"84.70000","112.93597","2.58814"
"84.80000","113.06931","2.59121"
"84.90000","113.20255","2.58926"
"85.00000","113.33593","2.58569"
"85.10000","113.46932","2.58757"
"85.20000","113.60255","2.59616"
"85.30000","113.73595","2.60049"
"85.40000","113.86939","2.59466"
"85.50000","114.00256","2.60388"
"85.60000","114.13601","2.59798"
"85.70000","114.26929","2.60783"
"85.80000","114.40251","2.60124"
"85.90000","114.53591","2.60732"
"86.00000","114.66931","2.60206"
"86.10000","114.80269","2.60827"
"86.20000","114.93597","2.61008"
"86.30000","115.06931","2.61284"
"86.40000","115.20259","2.61422"
"86.50000","115.33598","2.60651"
"86.60000","115.46932","2.61159"
"86.70000","115.60261","2.60789"
"86.80000","115.73599","2.60726"
"86.90000","115.86927","2.61347"
"87.00000","116.00256","2.61184"
"87.10000","116.13596","2.61516"
"87.20000","116.26923","2.61899"
"87.30000","116.40262","2.61535"
"87.40000","116.53602","2.61911"
"87.50000","116.66935","2.60789"
"87.60000","116.80264","2.61171"
"87.70000","116.93597","2.61723"
"87.80000","117.06931","2.61786"
"87.90000","117.20259","2.62093"
"88.00000","117.33591","2.62031"
"88.10000","117.46931","2.61974"
"88.20000","117.60265","2.61723"
"88.30000","117.73598","2.62300"
"88.40000","117.86926","2.62031"
"88.50000","118.00267","2.62150"
"88.60000","118.13599","2.62595"
"88.70000","118.26928","2.63234"
"88.80000","118.40256","2.61849"
"88.90000","118.53584","2.61874"
"89.00000","118.66929","2.62081"
"89.10000","118.80263","2.61867"
"89.20000","118.93597","2.61861"
"89.30000","119.06929","2.61673"
"89.40000","119.20263","2.61686"
"89.50000","119.33597","2.61441"
"89.60000","119.46931","2.61755"
"89.70000","119.60259","2.62062"
"89.80000","119.73598","2.61817"
"89.90000","119.86926","2.61861"
"90.00000","120.00266","2.62225"
"90.10000","120.13588","2.61485"
"90.20000","120.26933","2.62363"
"90.30000","120.40261","2.62143"
"90.40000","120.53594","2.61541"
"90.50000","120.66934","2.62043"
"90.60000","120.80261","2.62125"
"90.70000","120.93600","2.61842"
"90.80000","121.06924","2.62670"
"90.90000","121.20258","2.61560"
"91.00000","121.33597","2.61548"
"91.10000","121.46931","2.62319"
"91.20000","121.60264","2.61165"
"91.30000","121.73598","2.61240"
"91.40000","121.86919","2.61378"
"91.50000","122.00266","2.60833"
"91.60000","122.13599","2.60801"
"91.70000","122.26926","2.61278"
"91.80000","122.40254","2.61253"
"91.90000","122.53599","2.61134"
"92.00000","122.66934","2.60714"
"92.10000","122.80261","2.60557"
"92.20000","122.93600","2.60770"
"92.30000","123.06923","2.60068"
"92.40000","123.20262","2.60325"
"92.50000","123.33601","2.60036"
"92.60000","123.46930","2.60463"
"92.70000","123.60264","2.60400"
"92.80000","123.73596","2.59729"
"92.90000","123.86930","2.59221"
"93.00000","124.00263","2.60024"
"93.10000","124.13592","2.59811"
"93.20000","124.26926","2.59453"
"93.30000","124.40260","2.59422"
"93.40000","124.53604","2.59403"
"93.50000","124.66927","2.59303"
"93.60000","124.80267","2.58933"
"93.70000","124.93594","2.57879"
"93.80000","125.06927","2.58682"
"93.90000","125.20261","2.57409"
"94.00000","125.33583","2.56305"
"94.10000","125.46935","2.56751"
"94.20000","125.60262","2.56644"
"94.30000","125.73595","2.56725"
"94.40000","125.86919","2.55785"
"94.50000","126.00262","2.55452"
"94.60000","126.13596","2.55371"
"94.70000","126.26929","2.55452"
"94.80000","126.40259","2.55785"
"94.90000","126.53598","2.54863"
"95.00000","126.66932","2.54844"
"95.10000","126.80265","2.54474"
"95.20000","126.93593","2.54211"
"95.30000","127.06927","2.54111"
"95.40000","127.20266","2.52443"
"95.50000","127.33594","2.51928"
"95.60000","127.46927","2.52668"
"95.70000","127.60250","2.51941"
"95.80000","127.73600","2.52298"
"95.90000","127.86934","2.51082"
"96.00000","128.00262","2.50731"
"96.10000","128.13597","2.49527"
"96.20000","128.26930","2.49182"
"96.30000","128.40263","2.49006"
"96.40000","128.53590","2.48128"
"96.50000","128.66925","2.47877"
"96.60000","128.80264","2.48536"
"96.70000","128.93597","2.47639"
"96.80000","129.06926","2.47269"
"96.90000","129.20259","2.46567"
"97.00000","129.33592","2.47175"
"97.10000","129.46927","2.46793"
"97.20000","129.60266","2.45689"
"97.30000","129.73599","2.44259"
"97.40000","129.86916","2.44617"
"97.50000","130.00267","2.43582"
"97.60000","130.13602","2.43344"
"97.70000","130.26917","2.42190"
"97.75800","130.34659","-0.09161"
"97.85800","130.47992","-0.02533"
"97.95800","130.61325","-0.02552"
"98.05800","130.74658","-0.03110"
"98.15800","130.87999","-0.02314"
"98.25800","131.01321","-0.02063"
"98.35800","131.14665","-0.02721"
"98.45800","131.27998","-0.02916"
"98.55800","131.41328","-0.02978"
"98.65800","131.54666","-0.02941"
"98.75800","131.67995","-0.02132"
"98.85800","131.81329","-0.01316"
"98.95800","131.94656","-0.02514"
"99.05800","132.07983","-0.02157"
"99.15800","132.21335","-0.02583"
"99.25800","132.34663","-0.02414"
"99.35800","132.47990","-0.02194"
"99.45800","132.61324","-0.02389"
"99.55800","132.74660","-0.01342"
"99.65800","132.87997","-0.02401"
"99.75800","133.01331","-0.02263"
"99.85800","133.14665","-0.02451"
"99.95800","133.27988","-0.02796"
"100.05800","133.41327","-0.01737"
"100.15800","133.54660","-0.01987"
"100.25800","133.67995","-0.02232"
"100.35800","133.81334","-0.01392"
"100.45800","133.94655","-0.01981"
"100.55800","134.07994","-0.02408"
"100.65800","134.21324","-0.02025"
"100.75800","134.34651","-0.02282"
"100.85800","134.47995","-0.01229"
"100.95800","134.61331","-0.00746"
"101.05800","134.74664","-0.02464"
"101.15800","134.87997","-0.02050"
"101.25800","135.01326","-0.01975"
"101.35800","135.14665","-0.02050"
"101.45800","135.27998","-0.01398"
"101.55800","135.41331","-0.00997"
"101.65800","135.54654","-0.01248"
"101.75800","135.68005","-0.02589"
"101.85800","135.81332","-0.02383"
"101.95800","135.94656","-0.02188"
"102.05800","136.08000","-0.01718"
"102.07600","136.10397","-0.02270"